Workbook

Sheet Leia-me
A1: Comparação: calculadora × planilhas convencionais (FRX-DE, raízes de cana)
A3: O que é | B3: Razão Calculadora / Planilha convencional para concentração (C), incerteza (Erro) e limite de detecção (LD). O esperado é 1.
A4: Abas | B4: 'Razão AgV/AuV/RhV' = comparação (fórmulas). 'Calc_*' e 'Manual_*' = valores copiados das planilhas originais (texto azul).
A5: Textos nas razões | B5: 'só calc' / 'só manual' = só uma das planilhas tem número; 'sem valor' = nenhuma tem (ex.: <LD ou erro #VALUE!).
A6: Tolerância (editável) | B6: 0.01 | C6: ← faixa considerada '≈ 1' na cor verde (ex.: 1% = razão entre 0,99 e 1,01). Valor escolhido pelo Claude; ajuste à vontade.
A7: Linha Pd | B7: É o padrão (Folha de Tomate): C é o valor certificado nas duas planilhas, então a razão de C é 1 por construção.
A9: Elementos por alvo
A10: AgV | B10: Comparados: P, S, Cl, K, Ca, Cr, Mn, Fe, Ni, Cu, Zn, Br | Só na calculadora (fora da comparação): Se, Sr, Ag, Ag (22.103 keV, mg/kg)
B11: Padrão: 250226ab (b) Tomato Leaves - 1573a)
A12: AuV | B12: Comparados: S, Cl, K, Ca, Cr, Mn, Fe, Ni, Cu, Zn, Se | Só na calculadora (fora da comparação): Br, Sr
B13: Padrão: 250326ab (b) Tomato Leaves - 1573a)
A14: RhV | B14: Comparados: P, S, Cl, K, Ca, Cr, Mn, Fe, Ni, Cu, Zn | Só na calculadora (fora da comparação): Br, Sr
B15: Padrão: 110326ab (b) Tomato Leaves - 1573a)
A17: Observações
A18: RhV — C e Erro ≠ 1 | B18: Na planilha convencional do RhV o fator de normalização (célula 'Norm:', col. E das abas de elemento) foi digitado como 1 para todas as amostras, em vez da fórmula Ar(padrão)/Ar(amostra) usada no AgV e no AuV. A razão de cada amostra é exatamente esse fator (0,57–0,81), ou seja, a calculadora normalizou e a planilha não.
A19: AgV — LD de P, Ni e Zn | B19: O LD da planilha convencional usa o Bg digitado à mão (célula X7). Para P, Ni e Zn esse Bg difere do usado pela calculadora (razões 0,88; 0,97; 0,95). Nos demais elementos o LD bate.
A20: AuV — LD | B20: Na planilha convencional do AuV o Bg (X7) ficou como 'Insira Bg' em todos os elementos exceto Cr, por isso o LD só pode ser comparado para Cr.
A21: Células 'sem valor' | B21: AgV Br/R3 e RhV Cu/R3–R5: a calculadora marcou '<LD' e a planilha convencional deu erro #VALUE!.

Sheet Razão AgV
A1: Alvo AgV — razão Calculadora / Planilha convencional
A2: Valor esperado = 1. Verde: |razão − 1| ≤ tolerância; vermelho: fora da tolerância (definida no Leia-me).
C3: P | E3: S | G3: Cl | I3: K | K3: Ca | M3: Cr | O3: Mn | Q3: Fe | S3: Ni | U3: Cu | W3: Zn | Y3: Br
A4: Medida | B4: Amostra | C4: C | D4: Erro | E4: C | F4: Erro | G4: C | H4: Erro | I4: C | J4: Erro | K4: C | L4: Erro | M4: C | N4: Erro | O4: C | P4: Erro | Q4: C | R4: Erro | S4: C | T4: Erro | U4: C | V4: Erro | W4: C | X4: Erro | Y4: C | Z4: Erro
A5: LD | C5: =IF(AND(ISNUMBER(Calc_AgV!C5),ISNUMBER(Manual_AgV!C5)),Calc_AgV!C5/Manual_AgV!C5,IF(AND(ISNUMBER(Calc_AgV!C5),NOT(ISNUMBER(Manual_AgV!C5))),"só calc",IF(AND(ISNUMBER(Manual_AgV!C5),NOT(ISNUMBER(Calc_AgV!C5))),"só manual","sem valor"))) -> 0.88268365 | E5: =IF(AND(ISNUMBER(Calc_AgV!E5),ISNUMBER(Manual_AgV!E5)),Calc_AgV!E5/Manual_AgV!E5,IF(AND(ISNUMBER(Calc_AgV!E5),NOT(ISNUMBER(Manual_AgV!E5))),"só calc",IF(AND(ISNUMBER(Manual_AgV!E5),NOT(ISNUMBER(Calc_AgV!E5))),"só manual","sem valor"))) -> 1 | G5: =IF(AND(ISNUMBER(Calc_AgV!G5),ISNUMBER(Manual_AgV!G5)),Calc_AgV!G5/Manual_AgV!G5,IF(AND(ISNUMBER(Calc_AgV!G5),NOT(ISNUMBER(Manual_AgV!G5))),"só calc",IF(AND(ISNUMBER(Manual_AgV!G5),NOT(ISNUMBER(Calc_AgV!G5))),"só manual","sem valor"))) -> 1 | I5: =IF(AND(ISNUMBER(Calc_AgV!I5),ISNUMBER(Manual_AgV!I5)),Calc_AgV!I5/Manual_AgV!I5,IF(AND(ISNUMBER(Calc_AgV!I5),NOT(ISNUMBER(Manual_AgV!I5))),"só calc",IF(AND(ISNUMBER(Manual_AgV!I5),NOT(ISNUMBER(Calc_AgV!I5))),"só manual","sem valor"))) -> 1 | K5: =IF(AND(ISNUMBER(Calc_AgV!K5),ISNUMBER(Manual_AgV!K5)),Calc_AgV!K5/Manual_AgV!K5,IF(AND(ISNUMBER(Calc_AgV!K5),NOT(ISNUMBER(Manual_AgV!K5))),"só calc",IF(AND(ISNUMBER(Manual_AgV!K5),NOT(ISNUMBER(Calc_AgV!K5))),"só manual","sem valor"))) -> 1 | M5: =IF(AND(ISNUMBER(Calc_AgV!M5),ISNUMBER(Manual_AgV!M5)),Calc_AgV!M5/Manual_AgV!M5,IF(AND(ISNUMBER(Calc_AgV!M5),NOT(ISNUMBER(Manual_AgV!M5))),"só calc",IF(AND(ISNUMBER(Manual_AgV!M5),NOT(ISNUMBER(Calc_AgV!M5))),"só manual","sem valor"))) -> 1 | O5: =IF(AND(ISNUMBER(Calc_AgV!O5),ISNUMBER(Manual_AgV!O5)),Calc_AgV!O5/Manual_AgV!O5,IF(AND(ISNUMBER(Calc_AgV!O5),NOT(ISNUMBER(Manual_AgV!O5))),"só calc",IF(AND(ISNUMBER(Manual_AgV!O5),NOT(ISNUMBER(Calc_AgV!O5))),"só manual","sem valor"))) -> 1 | Q5: =IF(AND(ISNUMBER(Calc_AgV!Q5),ISNUMBER(Manual_AgV!Q5)),Calc_AgV!Q5/Manual_AgV!Q5,IF(AND(ISNUMBER(Calc_AgV!Q5),NOT(ISNUMBER(Manual_AgV!Q5))),"só calc",IF(AND(ISNUMBER(Manual_AgV!Q5),NOT(ISNUMBER(Calc_AgV!Q5))),"só manual","sem valor"))) -> 1 | S5: =IF(AND(ISNUMBER(Calc_AgV!S5),ISNUMBER(Manual_AgV!S5)),Calc_AgV!S5/Manual_AgV!S5,IF(AND(ISNUMBER(Calc_AgV!S5),NOT(ISNUMBER(Manual_AgV!S5))),"só calc",IF(AND(ISNUMBER(Manual_AgV!S5),NOT(ISNUMBER(Calc_AgV!S5))),"só manual","sem valor"))) -> 0.9706187 | U5: =IF(AND(ISNUMBER(Calc_AgV!U5),ISNUMBER(Manual_AgV!U5)),Calc_AgV!U5/Manual_AgV!U5,IF(AND(ISNUMBER(Calc_AgV!U5),NOT(ISNUMBER(Manual_AgV!U5))),"só calc",IF(AND(ISNUMBER(Manual_AgV!U5),NOT(ISNUMBER(Calc_AgV!U5))),"só manual","sem valor"))) -> 1 | W5: =IF(AND(ISNUMBER(Calc_AgV!W5),ISNUMBER(Manual_AgV!W5)),Calc_AgV!W5/Manual_AgV!W5,IF(AND(ISNUMBER(Calc_AgV!W5),NOT(ISNUMBER(Manual_AgV!W5))),"só calc",IF(AND(ISNUMBER(Manual_AgV!W5),NOT(ISNUMBER(Calc_AgV!W5))),"só manual","sem valor"))) -> 0.95349267 | Y5: =IF(AND(ISNUMBER(Calc_AgV!Y5),ISNUMBER(Manual_AgV!Y5)),Calc_AgV!Y5/Manual_AgV!Y5,IF(AND(ISNUMBER(Calc_AgV!Y5),NOT(ISNUMBER(Manual_AgV!Y5))),"só calc",IF(AND(ISNUMBER(Manual_AgV!Y5),NOT(ISNUMBER(Calc_AgV!Y5))),"só manual","sem valor"))) -> 1
A6: ab | B6: =Calc_AgV!B6 -> Pd Folha tomate 3 | C6: =IF(AND(ISNUMBER(Calc_AgV!C6),ISNUMBER(Manual_AgV!C6)),Calc_AgV!C6/Manual_AgV!C6,IF(AND(ISNUMBER(Calc_AgV!C6),NOT(ISNUMBER(Manual_AgV!C6))),"só calc",IF(AND(ISNUMBER(Manual_AgV!C6),NOT(ISNUMBER(Calc_AgV!C6))),"só manual","sem valor"))) -> 1 | D6: =IF(AND(ISNUMBER(Calc_AgV!D6),ISNUMBER(Manual_AgV!D6)),Calc_AgV!D6/Manual_AgV!D6,IF(AND(ISNUMBER(Calc_AgV!D6),NOT(ISNUMBER(Manual_AgV!D6))),"só calc",IF(AND(ISNUMBER(Manual_AgV!D6),NOT(ISNUMBER(Calc_AgV!D6))),"só manual","sem valor"))) -> 1.008337 | E6: =IF(AND(ISNUMBER(Calc_AgV!E6),ISNUMBER(Manual_AgV!E6)),Calc_AgV!E6/Manual_AgV!E6,IF(AND(ISNUMBER(Calc_AgV!E6),NOT(ISNUMBER(Manual_AgV!E6))),"só calc",IF(AND(ISNUMBER(Manual_AgV!E6),NOT(ISNUMBER(Calc_AgV!E6))),"só manual","sem valor"))) -> 1 | F6: =IF(AND(ISNUMBER(Calc_AgV!F6),ISNUMBER(Manual_AgV!F6)),Calc_AgV!F6/Manual_AgV!F6,IF(AND(ISNUMBER(Calc_AgV!F6),NOT(ISNUMBER(Manual_AgV!F6))),"só calc",IF(AND(ISNUMBER(Manual_AgV!F6),NOT(ISNUMBER(Calc_AgV!F6))),"só manual","sem valor"))) -> 1 | G6: =IF(AND(ISNUMBER(Calc_AgV!G6),ISNUMBER(Manual_AgV!G6)),Calc_AgV!G6/Manual_AgV!G6,IF(AND(ISNUMBER(Calc_AgV!G6),NOT(ISNUMBER(Manual_AgV!G6))),"só calc",IF(AND(ISNUMBER(Manual_AgV!G6),NOT(ISNUMBER(Calc_AgV!G6))),"só manual","sem valor"))) -> 1 | H6: =IF(AND(ISNUMBER(Calc_AgV!H6),ISNUMBER(Manual_AgV!H6)),Calc_AgV!H6/Manual_AgV!H6,IF(AND(ISNUMBER(Calc_AgV!H6),NOT(ISNUMBER(Manual_AgV!H6))),"só calc",IF(AND(ISNUMBER(Manual_AgV!H6),NOT(ISNUMBER(Calc_AgV!H6))),"só manual","sem valor"))) -> 1 | I6: =IF(AND(ISNUMBER(Calc_AgV!I6),ISNUMBER(Manual_AgV!I6)),Calc_AgV!I6/Manual_AgV!I6,IF(AND(ISNUMBER(Calc_AgV!I6),NOT(ISNUMBER(Manual_AgV!I6))),"só calc",IF(AND(ISNUMBER(Manual_AgV!I6),NOT(ISNUMBER(Calc_AgV!I6))),"só manual","sem valor"))) -> 1 | J6: =IF(AND(ISNUMBER(Calc_AgV!J6),ISNUMBER(Manual_AgV!J6)),Calc_AgV!J6/Manual_AgV!J6,IF(AND(ISNUMBER(Calc_AgV!J6),NOT(ISNUMBER(Manual_AgV!J6))),"só calc",IF(AND(ISNUMBER(Manual_AgV!J6),NOT(ISNUMBER(Calc_AgV!J6))),"só manual","sem valor"))) -> 1 | ... Z6: =IF(AND(ISNUMBER(Calc_AgV!Z6),ISNUMBER(Manual_AgV!Z6)),Calc_AgV!Z6/Manual_AgV!Z6,IF(AND(ISNUMBER(Calc_AgV!Z6),NOT(ISNUMBER(Manual_AgV!Z6))),"só calc",IF(AND(ISNUMBER(Manual_AgV!Z6),NOT(ISNUMBER(Calc_AgV!Z6))),"só manual","sem valor"))) -> 1
A7: ac | B7: =Calc_AgV!B7 -> R2 | C7: =IF(AND(ISNUMBER(Calc_AgV!C7),ISNUMBER(Manual_AgV!C7)),Calc_AgV!C7/Manual_AgV!C7,IF(AND(ISNUMBER(Calc_AgV!C7),NOT(ISNUMBER(Manual_AgV!C7))),"só calc",IF(AND(ISNUMBER(Manual_AgV!C7),NOT(ISNUMBER(Calc_AgV!C7))),"só manual","sem valor"))) -> 1 | D7: =IF(AND(ISNUMBER(Calc_AgV!D7),ISNUMBER(Manual_AgV!D7)),Calc_AgV!D7/Manual_AgV!D7,IF(AND(ISNUMBER(Calc_AgV!D7),NOT(ISNUMBER(Manual_AgV!D7))),"só calc",IF(AND(ISNUMBER(Manual_AgV!D7),NOT(ISNUMBER(Calc_AgV!D7))),"só manual","sem valor"))) -> 1.0056397 | E7: =IF(AND(ISNUMBER(Calc_AgV!E7),ISNUMBER(Manual_AgV!E7)),Calc_AgV!E7/Manual_AgV!E7,IF(AND(ISNUMBER(Calc_AgV!E7),NOT(ISNUMBER(Manual_AgV!E7))),"só calc",IF(AND(ISNUMBER(Manual_AgV!E7),NOT(ISNUMBER(Calc_AgV!E7))),"só manual","sem valor"))) -> 1 | F7: =IF(AND(ISNUMBER(Calc_AgV!F7),ISNUMBER(Manual_AgV!F7)),Calc_AgV!F7/Manual_AgV!F7,IF(AND(ISNUMBER(Calc_AgV!F7),NOT(ISNUMBER(Manual_AgV!F7))),"só calc",IF(AND(ISNUMBER(Manual_AgV!F7),NOT(ISNUMBER(Calc_AgV!F7))),"só manual","sem valor"))) -> 1.0019864 | G7: =IF(AND(ISNUMBER(Calc_AgV!G7),ISNUMBER(Manual_AgV!G7)),Calc_AgV!G7/Manual_AgV!G7,IF(AND(ISNUMBER(Calc_AgV!G7),NOT(ISNUMBER(Manual_AgV!G7))),"só calc",IF(AND(ISNUMBER(Manual_AgV!G7),NOT(ISNUMBER(Calc_AgV!G7))),"só manual","sem valor"))) -> 1 | H7: =IF(AND(ISNUMBER(Calc_AgV!H7),ISNUMBER(Manual_AgV!H7)),Calc_AgV!H7/Manual_AgV!H7,IF(AND(ISNUMBER(Calc_AgV!H7),NOT(ISNUMBER(Manual_AgV!H7))),"só calc",IF(AND(ISNUMBER(Manual_AgV!H7),NOT(ISNUMBER(Calc_AgV!H7))),"só manual","sem valor"))) -> 0.99761914 | I7: =IF(AND(ISNUMBER(Calc_AgV!I7),ISNUMBER(Manual_AgV!I7)),Calc_AgV!I7/Manual_AgV!I7,IF(AND(ISNUMBER(Calc_AgV!I7),NOT(ISNUMBER(Manual_AgV!I7))),"só calc",IF(AND(ISNUMBER(Manual_AgV!I7),NOT(ISNUMBER(Calc_AgV!I7))),"só manual","sem valor"))) -> 1 | J7: =IF(AND(ISNUMBER(Calc_AgV!J7),ISNUMBER(Manual_AgV!J7)),Calc_AgV!J7/Manual_AgV!J7,IF(AND(ISNUMBER(Calc_AgV!J7),NOT(ISNUMBER(Manual_AgV!J7))),"só calc",IF(AND(ISNUMBER(Manual_AgV!J7),NOT(ISNUMBER(Calc_AgV!J7))),"só manual","sem valor"))) -> 0.99992546 | ... Z7: =IF(AND(ISNUMBER(Calc_AgV!Z7),ISNUMBER(Manual_AgV!Z7)),Calc_AgV!Z7/Manual_AgV!Z7,IF(AND(ISNUMBER(Calc_AgV!Z7),NOT(ISNUMBER(Manual_AgV!Z7))),"só calc",IF(AND(ISNUMBER(Manual_AgV!Z7),NOT(ISNUMBER(Calc_AgV!Z7))),"só manual","sem valor"))) -> 1.0028827
A8: ad | B8: =Calc_AgV!B8 -> R3 | C8: =IF(AND(ISNUMBER(Calc_AgV!C8),ISNUMBER(Manual_AgV!C8)),Calc_AgV!C8/Manual_AgV!C8,IF(AND(ISNUMBER(Calc_AgV!C8),NOT(ISNUMBER(Manual_AgV!C8))),"só calc",IF(AND(ISNUMBER(Manual_AgV!C8),NOT(ISNUMBER(Calc_AgV!C8))),"só manual","sem valor"))) -> 1 | D8: =IF(AND(ISNUMBER(Calc_AgV!D8),ISNUMBER(Manual_AgV!D8)),Calc_AgV!D8/Manual_AgV!D8,IF(AND(ISNUMBER(Calc_AgV!D8),NOT(ISNUMBER(Manual_AgV!D8))),"só calc",IF(AND(ISNUMBER(Manual_AgV!D8),NOT(ISNUMBER(Calc_AgV!D8))),"só manual","sem valor"))) -> 1.0077668 | E8: =IF(AND(ISNUMBER(Calc_AgV!E8),ISNUMBER(Manual_AgV!E8)),Calc_AgV!E8/Manual_AgV!E8,IF(AND(ISNUMBER(Calc_AgV!E8),NOT(ISNUMBER(Manual_AgV!E8))),"só calc",IF(AND(ISNUMBER(Manual_AgV!E8),NOT(ISNUMBER(Calc_AgV!E8))),"só manual","sem valor"))) -> 1 | F8: =IF(AND(ISNUMBER(Calc_AgV!F8),ISNUMBER(Manual_AgV!F8)),Calc_AgV!F8/Manual_AgV!F8,IF(AND(ISNUMBER(Calc_AgV!F8),NOT(ISNUMBER(Manual_AgV!F8))),"só calc",IF(AND(ISNUMBER(Manual_AgV!F8),NOT(ISNUMBER(Calc_AgV!F8))),"só manual","sem valor"))) -> 1.0060988 | G8: =IF(AND(ISNUMBER(Calc_AgV!G8),ISNUMBER(Manual_AgV!G8)),Calc_AgV!G8/Manual_AgV!G8,IF(AND(ISNUMBER(Calc_AgV!G8),NOT(ISNUMBER(Manual_AgV!G8))),"só calc",IF(AND(ISNUMBER(Manual_AgV!G8),NOT(ISNUMBER(Calc_AgV!G8))),"só manual","sem valor"))) -> 1 | H8: =IF(AND(ISNUMBER(Calc_AgV!H8),ISNUMBER(Manual_AgV!H8)),Calc_AgV!H8/Manual_AgV!H8,IF(AND(ISNUMBER(Calc_AgV!H8),NOT(ISNUMBER(Manual_AgV!H8))),"só calc",IF(AND(ISNUMBER(Manual_AgV!H8),NOT(ISNUMBER(Calc_AgV!H8))),"só manual","sem valor"))) -> 0.99998769 | I8: =IF(AND(ISNUMBER(Calc_AgV!I8),ISNUMBER(Manual_AgV!I8)),Calc_AgV!I8/Manual_AgV!I8,IF(AND(ISNUMBER(Calc_AgV!I8),NOT(ISNUMBER(Manual_AgV!I8))),"só calc",IF(AND(ISNUMBER(Manual_AgV!I8),NOT(ISNUMBER(Calc_AgV!I8))),"só manual","sem valor"))) -> 1 | J8: =IF(AND(ISNUMBER(Calc_AgV!J8),ISNUMBER(Manual_AgV!J8)),Calc_AgV!J8/Manual_AgV!J8,IF(AND(ISNUMBER(Calc_AgV!J8),NOT(ISNUMBER(Manual_AgV!J8))),"só calc",IF(AND(ISNUMBER(Manual_AgV!J8),NOT(ISNUMBER(Calc_AgV!J8))),"só manual","sem valor"))) -> 0.99945637 | ... Z8: =IF(AND(ISNUMBER(Calc_AgV!Z8),ISNUMBER(Manual_AgV!Z8)),Calc_AgV!Z8/Manual_AgV!Z8,IF(AND(ISNUMBER(Calc_AgV!Z8),NOT(ISNUMBER(Manual_AgV!Z8))),"só calc",IF(AND(ISNUMBER(Manual_AgV!Z8),NOT(ISNUMBER(Calc_AgV!Z8))),"só manual","sem valor"))) -> sem valor
A9: ae | B9: =Calc_AgV!B9 -> R4 | C9: =IF(AND(ISNUMBER(Calc_AgV!C9),ISNUMBER(Manual_AgV!C9)),Calc_AgV!C9/Manual_AgV!C9,IF(AND(ISNUMBER(Calc_AgV!C9),NOT(ISNUMBER(Manual_AgV!C9))),"só calc",IF(AND(ISNUMBER(Manual_AgV!C9),NOT(ISNUMBER(Calc_AgV!C9))),"só manual","sem valor"))) -> 1 | D9: =IF(AND(ISNUMBER(Calc_AgV!D9),ISNUMBER(Manual_AgV!D9)),Calc_AgV!D9/Manual_AgV!D9,IF(AND(ISNUMBER(Calc_AgV!D9),NOT(ISNUMBER(Manual_AgV!D9))),"só calc",IF(AND(ISNUMBER(Manual_AgV!D9),NOT(ISNUMBER(Calc_AgV!D9))),"só manual","sem valor"))) -> 1.0083438 | E9: =IF(AND(ISNUMBER(Calc_AgV!E9),ISNUMBER(Manual_AgV!E9)),Calc_AgV!E9/Manual_AgV!E9,IF(AND(ISNUMBER(Calc_AgV!E9),NOT(ISNUMBER(Manual_AgV!E9))),"só calc",IF(AND(ISNUMBER(Manual_AgV!E9),NOT(ISNUMBER(Calc_AgV!E9))),"só manual","sem valor"))) -> 1 | F9: =IF(AND(ISNUMBER(Calc_AgV!F9),ISNUMBER(Manual_AgV!F9)),Calc_AgV!F9/Manual_AgV!F9,IF(AND(ISNUMBER(Calc_AgV!F9),NOT(ISNUMBER(Manual_AgV!F9))),"só calc",IF(AND(ISNUMBER(Manual_AgV!F9),NOT(ISNUMBER(Calc_AgV!F9))),"só manual","sem valor"))) -> 0.99690542 | G9: =IF(AND(ISNUMBER(Calc_AgV!G9),ISNUMBER(Manual_AgV!G9)),Calc_AgV!G9/Manual_AgV!G9,IF(AND(ISNUMBER(Calc_AgV!G9),NOT(ISNUMBER(Manual_AgV!G9))),"só calc",IF(AND(ISNUMBER(Manual_AgV!G9),NOT(ISNUMBER(Calc_AgV!G9))),"só manual","sem valor"))) -> 1 | H9: =IF(AND(ISNUMBER(Calc_AgV!H9),ISNUMBER(Manual_AgV!H9)),Calc_AgV!H9/Manual_AgV!H9,IF(AND(ISNUMBER(Calc_AgV!H9),NOT(ISNUMBER(Manual_AgV!H9))),"só calc",IF(AND(ISNUMBER(Manual_AgV!H9),NOT(ISNUMBER(Calc_AgV!H9))),"só manual","sem valor"))) -> 1.0054284 | I9: =IF(AND(ISNUMBER(Calc_AgV!I9),ISNUMBER(Manual_AgV!I9)),Calc_AgV!I9/Manual_AgV!I9,IF(AND(ISNUMBER(Calc_AgV!I9),NOT(ISNUMBER(Manual_AgV!I9))),"só calc",IF(AND(ISNUMBER(Manual_AgV!I9),NOT(ISNUMBER(Calc_AgV!I9))),"só manual","sem valor"))) -> 1 | J9: =IF(AND(ISNUMBER(Calc_AgV!J9),ISNUMBER(Manual_AgV!J9)),Calc_AgV!J9/Manual_AgV!J9,IF(AND(ISNUMBER(Calc_AgV!J9),NOT(ISNUMBER(Manual_AgV!J9))),"só calc",IF(AND(ISNUMBER(Manual_AgV!J9),NOT(ISNUMBER(Calc_AgV!J9))),"só manual","sem valor"))) -> 1.0000482 | ... Z9: =IF(AND(ISNUMBER(Calc_AgV!Z9),ISNUMBER(Manual_AgV!Z9)),Calc_AgV!Z9/Manual_AgV!Z9,IF(AND(ISNUMBER(Calc_AgV!Z9),NOT(ISNUMBER(Manual_AgV!Z9))),"só calc",IF(AND(ISNUMBER(Manual_AgV!Z9),NOT(ISNUMBER(Calc_AgV!Z9))),"só manual","sem valor"))) -> 0.99905915
A10: af | B10: =Calc_AgV!B10 -> R5 | C10: =IF(AND(ISNUMBER(Calc_AgV!C10),ISNUMBER(Manual_AgV!C10)),Calc_AgV!C10/Manual_AgV!C10,IF(AND(ISNUMBER(Calc_AgV!C10),NOT(ISNUMBER(Manual_AgV!C10))),"só calc",IF(AND(ISNUMBER(Manual_AgV!C10),NOT(ISNUMBER(Calc_AgV!C10))),"só manual","sem valor"))) -> 1 | D10: =IF(AND(ISNUMBER(Calc_AgV!D10),ISNUMBER(Manual_AgV!D10)),Calc_AgV!D10/Manual_AgV!D10,IF(AND(ISNUMBER(Calc_AgV!D10),NOT(ISNUMBER(Manual_AgV!D10))),"só calc",IF(AND(ISNUMBER(Manual_AgV!D10),NOT(ISNUMBER(Calc_AgV!D10))),"só manual","sem valor"))) -> 1.005171 | E10: =IF(AND(ISNUMBER(Calc_AgV!E10),ISNUMBER(Manual_AgV!E10)),Calc_AgV!E10/Manual_AgV!E10,IF(AND(ISNUMBER(Calc_AgV!E10),NOT(ISNUMBER(Manual_AgV!E10))),"só calc",IF(AND(ISNUMBER(Manual_AgV!E10),NOT(ISNUMBER(Calc_AgV!E10))),"só manual","sem valor"))) -> 1 | F10: =IF(AND(ISNUMBER(Calc_AgV!F10),ISNUMBER(Manual_AgV!F10)),Calc_AgV!F10/Manual_AgV!F10,IF(AND(ISNUMBER(Calc_AgV!F10),NOT(ISNUMBER(Manual_AgV!F10))),"só calc",IF(AND(ISNUMBER(Manual_AgV!F10),NOT(ISNUMBER(Calc_AgV!F10))),"só manual","sem valor"))) -> 1.0012271 | G10: =IF(AND(ISNUMBER(Calc_AgV!G10),ISNUMBER(Manual_AgV!G10)),Calc_AgV!G10/Manual_AgV!G10,IF(AND(ISNUMBER(Calc_AgV!G10),NOT(ISNUMBER(Manual_AgV!G10))),"só calc",IF(AND(ISNUMBER(Manual_AgV!G10),NOT(ISNUMBER(Calc_AgV!G10))),"só manual","sem valor"))) -> 1 | H10: =IF(AND(ISNUMBER(Calc_AgV!H10),ISNUMBER(Manual_AgV!H10)),Calc_AgV!H10/Manual_AgV!H10,IF(AND(ISNUMBER(Calc_AgV!H10),NOT(ISNUMBER(Manual_AgV!H10))),"só calc",IF(AND(ISNUMBER(Manual_AgV!H10),NOT(ISNUMBER(Calc_AgV!H10))),"só manual","sem valor"))) -> 0.99943529 | I10: =IF(AND(ISNUMBER(Calc_AgV!I10),ISNUMBER(Manual_AgV!I10)),Calc_AgV!I10/Manual_AgV!I10,IF(AND(ISNUMBER(Calc_AgV!I10),NOT(ISNUMBER(Manual_AgV!I10))),"só calc",IF(AND(ISNUMBER(Manual_AgV!I10),NOT(ISNUMBER(Calc_AgV!I10))),"só manual","sem valor"))) -> 1 | J10: =IF(AND(ISNUMBER(Calc_AgV!J10),ISNUMBER(Manual_AgV!J10)),Calc_AgV!J10/Manual_AgV!J10,IF(AND(ISNUMBER(Calc_AgV!J10),NOT(ISNUMBER(Manual_AgV!J10))),"só calc",IF(AND(ISNUMBER(Manual_AgV!J10),NOT(ISNUMBER(Calc_AgV!J10))),"só manual","sem valor"))) -> 1.00026 | ... Z10: =IF(AND(ISNUMBER(Calc_AgV!Z10),ISNUMBER(Manual_AgV!Z10)),Calc_AgV!Z10/Manual_AgV!Z10,IF(AND(ISNUMBER(Calc_AgV!Z10),NOT(ISNUMBER(Manual_AgV!Z10))),"só calc",IF(AND(ISNUMBER(Manual_AgV!Z10),NOT(ISNUMBER(Calc_AgV!Z10))),"só manual","sem valor"))) -> 0.99840368
A11: ag | B11: =Calc_AgV!B11 -> R6 | C11: =IF(AND(ISNUMBER(Calc_AgV!C11),ISNUMBER(Manual_AgV!C11)),Calc_AgV!C11/Manual_AgV!C11,IF(AND(ISNUMBER(Calc_AgV!C11),NOT(ISNUMBER(Manual_AgV!C11))),"só calc",IF(AND(ISNUMBER(Manual_AgV!C11),NOT(ISNUMBER(Calc_AgV!C11))),"só manual","sem valor"))) -> 1 | D11: =IF(AND(ISNUMBER(Calc_AgV!D11),ISNUMBER(Manual_AgV!D11)),Calc_AgV!D11/Manual_AgV!D11,IF(AND(ISNUMBER(Calc_AgV!D11),NOT(ISNUMBER(Manual_AgV!D11))),"só calc",IF(AND(ISNUMBER(Manual_AgV!D11),NOT(ISNUMBER(Calc_AgV!D11))),"só manual","sem valor"))) -> 1.0091627 | E11: =IF(AND(ISNUMBER(Calc_AgV!E11),ISNUMBER(Manual_AgV!E11)),Calc_AgV!E11/Manual_AgV!E11,IF(AND(ISNUMBER(Calc_AgV!E11),NOT(ISNUMBER(Manual_AgV!E11))),"só calc",IF(AND(ISNUMBER(Manual_AgV!E11),NOT(ISNUMBER(Calc_AgV!E11))),"só manual","sem valor"))) -> 1 | F11: =IF(AND(ISNUMBER(Calc_AgV!F11),ISNUMBER(Manual_AgV!F11)),Calc_AgV!F11/Manual_AgV!F11,IF(AND(ISNUMBER(Calc_AgV!F11),NOT(ISNUMBER(Manual_AgV!F11))),"só calc",IF(AND(ISNUMBER(Manual_AgV!F11),NOT(ISNUMBER(Calc_AgV!F11))),"só manual","sem valor"))) -> 0.99618967 | G11: =IF(AND(ISNUMBER(Calc_AgV!G11),ISNUMBER(Manual_AgV!G11)),Calc_AgV!G11/Manual_AgV!G11,IF(AND(ISNUMBER(Calc_AgV!G11),NOT(ISNUMBER(Manual_AgV!G11))),"só calc",IF(AND(ISNUMBER(Manual_AgV!G11),NOT(ISNUMBER(Calc_AgV!G11))),"só manual","sem valor"))) -> 1 | H11: =IF(AND(ISNUMBER(Calc_AgV!H11),ISNUMBER(Manual_AgV!H11)),Calc_AgV!H11/Manual_AgV!H11,IF(AND(ISNUMBER(Calc_AgV!H11),NOT(ISNUMBER(Manual_AgV!H11))),"só calc",IF(AND(ISNUMBER(Manual_AgV!H11),NOT(ISNUMBER(Calc_AgV!H11))),"só manual","sem valor"))) -> 1.0025102 | I11: =IF(AND(ISNUMBER(Calc_AgV!I11),ISNUMBER(Manual_AgV!I11)),Calc_AgV!I11/Manual_AgV!I11,IF(AND(ISNUMBER(Calc_AgV!I11),NOT(ISNUMBER(Manual_AgV!I11))),"só calc",IF(AND(ISNUMBER(Manual_AgV!I11),NOT(ISNUMBER(Calc_AgV!I11))),"só manual","sem valor"))) -> 1 | J11: =IF(AND(ISNUMBER(Calc_AgV!J11),ISNUMBER(Manual_AgV!J11)),Calc_AgV!J11/Manual_AgV!J11,IF(AND(ISNUMBER(Calc_AgV!J11),NOT(ISNUMBER(Manual_AgV!J11))),"só calc",IF(AND(ISNUMBER(Manual_AgV!J11),NOT(ISNUMBER(Calc_AgV!J11))),"só manual","sem valor"))) -> 0.99977047 | ... Z11: =IF(AND(ISNUMBER(Calc_AgV!Z11),ISNUMBER(Manual_AgV!Z11)),Calc_AgV!Z11/Manual_AgV!Z11,IF(AND(ISNUMBER(Calc_AgV!Z11),NOT(ISNUMBER(Manual_AgV!Z11))),"só calc",IF(AND(ISNUMBER(Manual_AgV!Z11),NOT(ISNUMBER(Calc_AgV!Z11))),"só manual","sem valor"))) -> 0.9997935
A12: ah | B12: =Calc_AgV!B12 -> R7 | C12: =IF(AND(ISNUMBER(Calc_AgV!C12),ISNUMBER(Manual_AgV!C12)),Calc_AgV!C12/Manual_AgV!C12,IF(AND(ISNUMBER(Calc_AgV!C12),NOT(ISNUMBER(Manual_AgV!C12))),"só calc",IF(AND(ISNUMBER(Manual_AgV!C12),NOT(ISNUMBER(Calc_AgV!C12))),"só manual","sem valor"))) -> 1 | D12: =IF(AND(ISNUMBER(Calc_AgV!D12),ISNUMBER(Manual_AgV!D12)),Calc_AgV!D12/Manual_AgV!D12,IF(AND(ISNUMBER(Calc_AgV!D12),NOT(ISNUMBER(Manual_AgV!D12))),"só calc",IF(AND(ISNUMBER(Manual_AgV!D12),NOT(ISNUMBER(Calc_AgV!D12))),"só manual","sem valor"))) -> 1.0069738 | E12: =IF(AND(ISNUMBER(Calc_AgV!E12),ISNUMBER(Manual_AgV!E12)),Calc_AgV!E12/Manual_AgV!E12,IF(AND(ISNUMBER(Calc_AgV!E12),NOT(ISNUMBER(Manual_AgV!E12))),"só calc",IF(AND(ISNUMBER(Manual_AgV!E12),NOT(ISNUMBER(Calc_AgV!E12))),"só manual","sem valor"))) -> 1 | F12: =IF(AND(ISNUMBER(Calc_AgV!F12),ISNUMBER(Manual_AgV!F12)),Calc_AgV!F12/Manual_AgV!F12,IF(AND(ISNUMBER(Calc_AgV!F12),NOT(ISNUMBER(Manual_AgV!F12))),"só calc",IF(AND(ISNUMBER(Manual_AgV!F12),NOT(ISNUMBER(Calc_AgV!F12))),"só manual","sem valor"))) -> 1.0022506 | G12: =IF(AND(ISNUMBER(Calc_AgV!G12),ISNUMBER(Manual_AgV!G12)),Calc_AgV!G12/Manual_AgV!G12,IF(AND(ISNUMBER(Calc_AgV!G12),NOT(ISNUMBER(Manual_AgV!G12))),"só calc",IF(AND(ISNUMBER(Manual_AgV!G12),NOT(ISNUMBER(Calc_AgV!G12))),"só manual","sem valor"))) -> 1 | H12: =IF(AND(ISNUMBER(Calc_AgV!H12),ISNUMBER(Manual_AgV!H12)),Calc_AgV!H12/Manual_AgV!H12,IF(AND(ISNUMBER(Calc_AgV!H12),NOT(ISNUMBER(Manual_AgV!H12))),"só calc",IF(AND(ISNUMBER(Manual_AgV!H12),NOT(ISNUMBER(Calc_AgV!H12))),"só manual","sem valor"))) -> 1.0046841 | I12: =IF(AND(ISNUMBER(Calc_AgV!I12),ISNUMBER(Manual_AgV!I12)),Calc_AgV!I12/Manual_AgV!I12,IF(AND(ISNUMBER(Calc_AgV!I12),NOT(ISNUMBER(Manual_AgV!I12))),"só calc",IF(AND(ISNUMBER(Manual_AgV!I12),NOT(ISNUMBER(Calc_AgV!I12))),"só manual","sem valor"))) -> 1 | J12: =IF(AND(ISNUMBER(Calc_AgV!J12),ISNUMBER(Manual_AgV!J12)),Calc_AgV!J12/Manual_AgV!J12,IF(AND(ISNUMBER(Calc_AgV!J12),NOT(ISNUMBER(Manual_AgV!J12))),"só calc",IF(AND(ISNUMBER(Manual_AgV!J12),NOT(ISNUMBER(Calc_AgV!J12))),"só manual","sem valor"))) -> 0.99972554 | ... Z12: =IF(AND(ISNUMBER(Calc_AgV!Z12),ISNUMBER(Manual_AgV!Z12)),Calc_AgV!Z12/Manual_AgV!Z12,IF(AND(ISNUMBER(Calc_AgV!Z12),NOT(ISNUMBER(Manual_AgV!Z12))),"só calc",IF(AND(ISNUMBER(Manual_AgV!Z12),NOT(ISNUMBER(Calc_AgV!Z12))),"só manual","sem valor"))) -> 0.99668947
A13: ai | B13: =Calc_AgV!B13 -> R8 | C13: =IF(AND(ISNUMBER(Calc_AgV!C13),ISNUMBER(Manual_AgV!C13)),Calc_AgV!C13/Manual_AgV!C13,IF(AND(ISNUMBER(Calc_AgV!C13),NOT(ISNUMBER(Manual_AgV!C13))),"só calc",IF(AND(ISNUMBER(Manual_AgV!C13),NOT(ISNUMBER(Calc_AgV!C13))),"só manual","sem valor"))) -> 1 | D13: =IF(AND(ISNUMBER(Calc_AgV!D13),ISNUMBER(Manual_AgV!D13)),Calc_AgV!D13/Manual_AgV!D13,IF(AND(ISNUMBER(Calc_AgV!D13),NOT(ISNUMBER(Manual_AgV!D13))),"só calc",IF(AND(ISNUMBER(Manual_AgV!D13),NOT(ISNUMBER(Calc_AgV!D13))),"só manual","sem valor"))) -> 0.99954817 | E13: =IF(AND(ISNUMBER(Calc_AgV!E13),ISNUMBER(Manual_AgV!E13)),Calc_AgV!E13/Manual_AgV!E13,IF(AND(ISNUMBER(Calc_AgV!E13),NOT(ISNUMBER(Manual_AgV!E13))),"só calc",IF(AND(ISNUMBER(Manual_AgV!E13),NOT(ISNUMBER(Calc_AgV!E13))),"só manual","sem valor"))) -> 1 | F13: =IF(AND(ISNUMBER(Calc_AgV!F13),ISNUMBER(Manual_AgV!F13)),Calc_AgV!F13/Manual_AgV!F13,IF(AND(ISNUMBER(Calc_AgV!F13),NOT(ISNUMBER(Manual_AgV!F13))),"só calc",IF(AND(ISNUMBER(Manual_AgV!F13),NOT(ISNUMBER(Calc_AgV!F13))),"só manual","sem valor"))) -> 0.99809999 | G13: =IF(AND(ISNUMBER(Calc_AgV!G13),ISNUMBER(Manual_AgV!G13)),Calc_AgV!G13/Manual_AgV!G13,IF(AND(ISNUMBER(Calc_AgV!G13),NOT(ISNUMBER(Manual_AgV!G13))),"só calc",IF(AND(ISNUMBER(Manual_AgV!G13),NOT(ISNUMBER(Calc_AgV!G13))),"só manual","sem valor"))) -> 1 | H13: =IF(AND(ISNUMBER(Calc_AgV!H13),ISNUMBER(Manual_AgV!H13)),Calc_AgV!H13/Manual_AgV!H13,IF(AND(ISNUMBER(Calc_AgV!H13),NOT(ISNUMBER(Manual_AgV!H13))),"só calc",IF(AND(ISNUMBER(Manual_AgV!H13),NOT(ISNUMBER(Calc_AgV!H13))),"só manual","sem valor"))) -> 1.0024497 | I13: =IF(AND(ISNUMBER(Calc_AgV!I13),ISNUMBER(Manual_AgV!I13)),Calc_AgV!I13/Manual_AgV!I13,IF(AND(ISNUMBER(Calc_AgV!I13),NOT(ISNUMBER(Manual_AgV!I13))),"só calc",IF(AND(ISNUMBER(Manual_AgV!I13),NOT(ISNUMBER(Calc_AgV!I13))),"só manual","sem valor"))) -> 1 | J13: =IF(AND(ISNUMBER(Calc_AgV!J13),ISNUMBER(Manual_AgV!J13)),Calc_AgV!J13/Manual_AgV!J13,IF(AND(ISNUMBER(Calc_AgV!J13),NOT(ISNUMBER(Manual_AgV!J13))),"só calc",IF(AND(ISNUMBER(Manual_AgV!J13),NOT(ISNUMBER(Calc_AgV!J13))),"só manual","sem valor"))) -> 1.0002065 | ... Z13: =IF(AND(ISNUMBER(Calc_AgV!Z13),ISNUMBER(Manual_AgV!Z13)),Calc_AgV!Z13/Manual_AgV!Z13,IF(AND(ISNUMBER(Calc_AgV!Z13),NOT(ISNUMBER(Manual_AgV!Z13))),"só calc",IF(AND(ISNUMBER(Manual_AgV!Z13),NOT(ISNUMBER(Calc_AgV!Z13))),"só manual","sem valor"))) -> 1.0035642
A14: aj | B14: =Calc_AgV!B14 -> R9 | C14: =IF(AND(ISNUMBER(Calc_AgV!C14),ISNUMBER(Manual_AgV!C14)),Calc_AgV!C14/Manual_AgV!C14,IF(AND(ISNUMBER(Calc_AgV!C14),NOT(ISNUMBER(Manual_AgV!C14))),"só calc",IF(AND(ISNUMBER(Manual_AgV!C14),NOT(ISNUMBER(Calc_AgV!C14))),"só manual","sem valor"))) -> 1 | D14: =IF(AND(ISNUMBER(Calc_AgV!D14),ISNUMBER(Manual_AgV!D14)),Calc_AgV!D14/Manual_AgV!D14,IF(AND(ISNUMBER(Calc_AgV!D14),NOT(ISNUMBER(Manual_AgV!D14))),"só calc",IF(AND(ISNUMBER(Manual_AgV!D14),NOT(ISNUMBER(Calc_AgV!D14))),"só manual","sem valor"))) -> 1.0065543 | E14: =IF(AND(ISNUMBER(Calc_AgV!E14),ISNUMBER(Manual_AgV!E14)),Calc_AgV!E14/Manual_AgV!E14,IF(AND(ISNUMBER(Calc_AgV!E14),NOT(ISNUMBER(Manual_AgV!E14))),"só calc",IF(AND(ISNUMBER(Manual_AgV!E14),NOT(ISNUMBER(Calc_AgV!E14))),"só manual","sem valor"))) -> 1 | F14: =IF(AND(ISNUMBER(Calc_AgV!F14),ISNUMBER(Manual_AgV!F14)),Calc_AgV!F14/Manual_AgV!F14,IF(AND(ISNUMBER(Calc_AgV!F14),NOT(ISNUMBER(Manual_AgV!F14))),"só calc",IF(AND(ISNUMBER(Manual_AgV!F14),NOT(ISNUMBER(Calc_AgV!F14))),"só manual","sem valor"))) -> 1.0053203 | G14: =IF(AND(ISNUMBER(Calc_AgV!G14),ISNUMBER(Manual_AgV!G14)),Calc_AgV!G14/Manual_AgV!G14,IF(AND(ISNUMBER(Calc_AgV!G14),NOT(ISNUMBER(Manual_AgV!G14))),"só calc",IF(AND(ISNUMBER(Manual_AgV!G14),NOT(ISNUMBER(Calc_AgV!G14))),"só manual","sem valor"))) -> 1 | H14: =IF(AND(ISNUMBER(Calc_AgV!H14),ISNUMBER(Manual_AgV!H14)),Calc_AgV!H14/Manual_AgV!H14,IF(AND(ISNUMBER(Calc_AgV!H14),NOT(ISNUMBER(Manual_AgV!H14))),"só calc",IF(AND(ISNUMBER(Manual_AgV!H14),NOT(ISNUMBER(Calc_AgV!H14))),"só manual","sem valor"))) -> 0.99731677 | I14: =IF(AND(ISNUMBER(Calc_AgV!I14),ISNUMBER(Manual_AgV!I14)),Calc_AgV!I14/Manual_AgV!I14,IF(AND(ISNUMBER(Calc_AgV!I14),NOT(ISNUMBER(Manual_AgV!I14))),"só calc",IF(AND(ISNUMBER(Manual_AgV!I14),NOT(ISNUMBER(Calc_AgV!I14))),"só manual","sem valor"))) -> 1 | J14: =IF(AND(ISNUMBER(Calc_AgV!J14),ISNUMBER(Manual_AgV!J14)),Calc_AgV!J14/Manual_AgV!J14,IF(AND(ISNUMBER(Calc_AgV!J14),NOT(ISNUMBER(Manual_AgV!J14))),"só calc",IF(AND(ISNUMBER(Manual_AgV!J14),NOT(ISNUMBER(Calc_AgV!J14))),"só manual","sem valor"))) -> 0.99991533 | ... Z14: =IF(AND(ISNUMBER(Calc_AgV!Z14),ISNUMBER(Manual_AgV!Z14)),Calc_AgV!Z14/Manual_AgV!Z14,IF(AND(ISNUMBER(Calc_AgV!Z14),NOT(ISNUMBER(Manual_AgV!Z14))),"só calc",IF(AND(ISNUMBER(Manual_AgV!Z14),NOT(ISNUMBER(Calc_AgV!Z14))),"só manual","sem valor"))) -> 0.99891615
A15: ak | B15: =Calc_AgV!B15 -> R10 | C15: =IF(AND(ISNUMBER(Calc_AgV!C15),ISNUMBER(Manual_AgV!C15)),Calc_AgV!C15/Manual_AgV!C15,IF(AND(ISNUMBER(Calc_AgV!C15),NOT(ISNUMBER(Manual_AgV!C15))),"só calc",IF(AND(ISNUMBER(Manual_AgV!C15),NOT(ISNUMBER(Calc_AgV!C15))),"só manual","sem valor"))) -> 1 | D15: =IF(AND(ISNUMBER(Calc_AgV!D15),ISNUMBER(Manual_AgV!D15)),Calc_AgV!D15/Manual_AgV!D15,IF(AND(ISNUMBER(Calc_AgV!D15),NOT(ISNUMBER(Manual_AgV!D15))),"só calc",IF(AND(ISNUMBER(Manual_AgV!D15),NOT(ISNUMBER(Calc_AgV!D15))),"só manual","sem valor"))) -> 1.0132006 | E15: =IF(AND(ISNUMBER(Calc_AgV!E15),ISNUMBER(Manual_AgV!E15)),Calc_AgV!E15/Manual_AgV!E15,IF(AND(ISNUMBER(Calc_AgV!E15),NOT(ISNUMBER(Manual_AgV!E15))),"só calc",IF(AND(ISNUMBER(Manual_AgV!E15),NOT(ISNUMBER(Calc_AgV!E15))),"só manual","sem valor"))) -> 1 | F15: =IF(AND(ISNUMBER(Calc_AgV!F15),ISNUMBER(Manual_AgV!F15)),Calc_AgV!F15/Manual_AgV!F15,IF(AND(ISNUMBER(Calc_AgV!F15),NOT(ISNUMBER(Manual_AgV!F15))),"só calc",IF(AND(ISNUMBER(Manual_AgV!F15),NOT(ISNUMBER(Calc_AgV!F15))),"só manual","sem valor"))) -> 0.99743944 | G15: =IF(AND(ISNUMBER(Calc_AgV!G15),ISNUMBER(Manual_AgV!G15)),Calc_AgV!G15/Manual_AgV!G15,IF(AND(ISNUMBER(Calc_AgV!G15),NOT(ISNUMBER(Manual_AgV!G15))),"só calc",IF(AND(ISNUMBER(Manual_AgV!G15),NOT(ISNUMBER(Calc_AgV!G15))),"só manual","sem valor"))) -> 1 | H15: =IF(AND(ISNUMBER(Calc_AgV!H15),ISNUMBER(Manual_AgV!H15)),Calc_AgV!H15/Manual_AgV!H15,IF(AND(ISNUMBER(Calc_AgV!H15),NOT(ISNUMBER(Manual_AgV!H15))),"só calc",IF(AND(ISNUMBER(Manual_AgV!H15),NOT(ISNUMBER(Calc_AgV!H15))),"só manual","sem valor"))) -> 1.004122 | I15: =IF(AND(ISNUMBER(Calc_AgV!I15),ISNUMBER(Manual_AgV!I15)),Calc_AgV!I15/Manual_AgV!I15,IF(AND(ISNUMBER(Calc_AgV!I15),NOT(ISNUMBER(Manual_AgV!I15))),"só calc",IF(AND(ISNUMBER(Manual_AgV!I15),NOT(ISNUMBER(Calc_AgV!I15))),"só manual","sem valor"))) -> 1 | J15: =IF(AND(ISNUMBER(Calc_AgV!J15),ISNUMBER(Manual_AgV!J15)),Calc_AgV!J15/Manual_AgV!J15,IF(AND(ISNUMBER(Calc_AgV!J15),NOT(ISNUMBER(Manual_AgV!J15))),"só calc",IF(AND(ISNUMBER(Manual_AgV!J15),NOT(ISNUMBER(Calc_AgV!J15))),"só manual","sem valor"))) -> 1.0002778 | ... Z15: =IF(AND(ISNUMBER(Calc_AgV!Z15),ISNUMBER(Manual_AgV!Z15)),Calc_AgV!Z15/Manual_AgV!Z15,IF(AND(ISNUMBER(Calc_AgV!Z15),NOT(ISNUMBER(Manual_AgV!Z15))),"só calc",IF(AND(ISNUMBER(Manual_AgV!Z15),NOT(ISNUMBER(Calc_AgV!Z15))),"só manual","sem valor"))) -> 0.99769019
A16: al | B16: =Calc_AgV!B16 -> R11 | C16: =IF(AND(ISNUMBER(Calc_AgV!C16),ISNUMBER(Manual_AgV!C16)),Calc_AgV!C16/Manual_AgV!C16,IF(AND(ISNUMBER(Calc_AgV!C16),NOT(ISNUMBER(Manual_AgV!C16))),"só calc",IF(AND(ISNUMBER(Manual_AgV!C16),NOT(ISNUMBER(Calc_AgV!C16))),"só manual","sem valor"))) -> 1 | D16: =IF(AND(ISNUMBER(Calc_AgV!D16),ISNUMBER(Manual_AgV!D16)),Calc_AgV!D16/Manual_AgV!D16,IF(AND(ISNUMBER(Calc_AgV!D16),NOT(ISNUMBER(Manual_AgV!D16))),"só calc",IF(AND(ISNUMBER(Manual_AgV!D16),NOT(ISNUMBER(Calc_AgV!D16))),"só manual","sem valor"))) -> 1.0093832 | E16: =IF(AND(ISNUMBER(Calc_AgV!E16),ISNUMBER(Manual_AgV!E16)),Calc_AgV!E16/Manual_AgV!E16,IF(AND(ISNUMBER(Calc_AgV!E16),NOT(ISNUMBER(Manual_AgV!E16))),"só calc",IF(AND(ISNUMBER(Manual_AgV!E16),NOT(ISNUMBER(Calc_AgV!E16))),"só manual","sem valor"))) -> 1 | F16: =IF(AND(ISNUMBER(Calc_AgV!F16),ISNUMBER(Manual_AgV!F16)),Calc_AgV!F16/Manual_AgV!F16,IF(AND(ISNUMBER(Calc_AgV!F16),NOT(ISNUMBER(Manual_AgV!F16))),"só calc",IF(AND(ISNUMBER(Manual_AgV!F16),NOT(ISNUMBER(Calc_AgV!F16))),"só manual","sem valor"))) -> 0.99261361 | G16: =IF(AND(ISNUMBER(Calc_AgV!G16),ISNUMBER(Manual_AgV!G16)),Calc_AgV!G16/Manual_AgV!G16,IF(AND(ISNUMBER(Calc_AgV!G16),NOT(ISNUMBER(Manual_AgV!G16))),"só calc",IF(AND(ISNUMBER(Manual_AgV!G16),NOT(ISNUMBER(Calc_AgV!G16))),"só manual","sem valor"))) -> 1 | H16: =IF(AND(ISNUMBER(Calc_AgV!H16),ISNUMBER(Manual_AgV!H16)),Calc_AgV!H16/Manual_AgV!H16,IF(AND(ISNUMBER(Calc_AgV!H16),NOT(ISNUMBER(Manual_AgV!H16))),"só calc",IF(AND(ISNUMBER(Manual_AgV!H16),NOT(ISNUMBER(Calc_AgV!H16))),"só manual","sem valor"))) -> 0.99978103 | I16: =IF(AND(ISNUMBER(Calc_AgV!I16),ISNUMBER(Manual_AgV!I16)),Calc_AgV!I16/Manual_AgV!I16,IF(AND(ISNUMBER(Calc_AgV!I16),NOT(ISNUMBER(Manual_AgV!I16))),"só calc",IF(AND(ISNUMBER(Manual_AgV!I16),NOT(ISNUMBER(Calc_AgV!I16))),"só manual","sem valor"))) -> 1 | J16: =IF(AND(ISNUMBER(Calc_AgV!J16),ISNUMBER(Manual_AgV!J16)),Calc_AgV!J16/Manual_AgV!J16,IF(AND(ISNUMBER(Calc_AgV!J16),NOT(ISNUMBER(Manual_AgV!J16))),"só calc",IF(AND(ISNUMBER(Manual_AgV!J16),NOT(ISNUMBER(Calc_AgV!J16))),"só manual","sem valor"))) -> 0.99996159 | ... Z16: =IF(AND(ISNUMBER(Calc_AgV!Z16),ISNUMBER(Manual_AgV!Z16)),Calc_AgV!Z16/Manual_AgV!Z16,IF(AND(ISNUMBER(Calc_AgV!Z16),NOT(ISNUMBER(Manual_AgV!Z16))),"só calc",IF(AND(ISNUMBER(Manual_AgV!Z16),NOT(ISNUMBER(Calc_AgV!Z16))),"só manual","sem valor"))) -> 1.0022868
A18: Média (R2–R11) | C18: =IF(COUNT(C7:C16)>=2,AVERAGE(C7:C16),"—") -> 1 | D18: =IF(COUNT(D7:D16)>=2,AVERAGE(D7:D16),"—") -> 1.0071744 | E18: =IF(COUNT(E7:E16)>=2,AVERAGE(E7:E16),"—") -> 1 | F18: =IF(COUNT(F7:F16)>=2,AVERAGE(F7:F16),"—") -> 0.99981313 | G18: =IF(COUNT(G7:G16)>=2,AVERAGE(G7:G16),"—") -> 1 | H18: =IF(COUNT(H7:H16)>=2,AVERAGE(H7:H16),"—") -> 1.0013334 | I18: =IF(COUNT(I7:I16)>=2,AVERAGE(I7:I16),"—") -> 1 | J18: =IF(COUNT(J7:J16)>=2,AVERAGE(J7:J16),"—") -> 0.99995473 | ... Z18: =IF(COUNT(Z7:Z16)>=2,AVERAGE(Z7:Z16),"—") -> 0.99992065
A19: Desvio padrão | C19: =IF(COUNT(C7:C16)>=2,STDEV(C7:C16),"—") -> 0 | D19: =IF(COUNT(D7:D16)>=2,STDEV(D7:D16),"—") -> 0.0035248066 | E19: =IF(COUNT(E7:E16)>=2,STDEV(E7:E16),"—") -> 0 | F19: =IF(COUNT(F7:F16)>=2,STDEV(F7:F16),"—") -> 0.0042751011 | G19: =IF(COUNT(G7:G16)>=2,STDEV(G7:G16),"—") -> 0 | H19: =IF(COUNT(H7:H16)>=2,STDEV(H7:H16),"—") -> 0.0029089133 | I19: =IF(COUNT(I7:I16)>=2,STDEV(I7:I16),"—") -> 0 | J19: =IF(COUNT(J7:J16)>=2,STDEV(J7:J16),"—") -> 0.00025970042 | ... Z19: =IF(COUNT(Z7:Z16)>=2,STDEV(Z7:Z16),"—") -> 0.0024272445
A20: Mín. | C20: =IF(COUNT(C7:C16)>=2,MIN(C7:C16),"—") -> 1 | D20: =IF(COUNT(D7:D16)>=2,MIN(D7:D16),"—") -> 0.99954817 | E20: =IF(COUNT(E7:E16)>=2,MIN(E7:E16),"—") -> 1 | F20: =IF(COUNT(F7:F16)>=2,MIN(F7:F16),"—") -> 0.99261361 | G20: =IF(COUNT(G7:G16)>=2,MIN(G7:G16),"—") -> 1 | H20: =IF(COUNT(H7:H16)>=2,MIN(H7:H16),"—") -> 0.99731677 | I20: =IF(COUNT(I7:I16)>=2,MIN(I7:I16),"—") -> 1 | J20: =IF(COUNT(J7:J16)>=2,MIN(J7:J16),"—") -> 0.99945637 | ... Z20: =IF(COUNT(Z7:Z16)>=2,MIN(Z7:Z16),"—") -> 0.99668947
A21: Máx. | C21: =IF(COUNT(C7:C16)>=2,MAX(C7:C16),"—") -> 1 | D21: =IF(COUNT(D7:D16)>=2,MAX(D7:D16),"—") -> 1.0132006 | E21: =IF(COUNT(E7:E16)>=2,MAX(E7:E16),"—") -> 1 | F21: =IF(COUNT(F7:F16)>=2,MAX(F7:F16),"—") -> 1.0060988 | G21: =IF(COUNT(G7:G16)>=2,MAX(G7:G16),"—") -> 1 | H21: =IF(COUNT(H7:H16)>=2,MAX(H7:H16),"—") -> 1.0054284 | I21: =IF(COUNT(I7:I16)>=2,MAX(I7:I16),"—") -> 1 | J21: =IF(COUNT(J7:J16)>=2,MAX(J7:J16),"—") -> 1.0002778 | ... Z21: =IF(COUNT(Z7:Z16)>=2,MAX(Z7:Z16),"—") -> 1.0035642

Sheet Razão AuV
A1: Alvo AuV — razão Calculadora / Planilha convencional
A2: Valor esperado = 1. Verde: |razão − 1| ≤ tolerância; vermelho: fora da tolerância (definida no Leia-me).
C3: S | E3: Cl | G3: K | I3: Ca | K3: Cr | M3: Mn | O3: Fe | Q3: Ni | S3: Cu | U3: Zn | W3: Se
A4: Medida | B4: Amostra | C4: C | D4: Erro | E4: C | F4: Erro | G4: C | H4: Erro | I4: C | J4: Erro | K4: C | L4: Erro | M4: C | N4: Erro | O4: C | P4: Erro | Q4: C | R4: Erro | S4: C | T4: Erro | U4: C | V4: Erro | W4: C | X4: Erro
A5: LD | C5: =IF(AND(ISNUMBER(Calc_AuV!C5),ISNUMBER(Manual_AuV!C5)),Calc_AuV!C5/Manual_AuV!C5,IF(AND(ISNUMBER(Calc_AuV!C5),NOT(ISNUMBER(Manual_AuV!C5))),"só calc",IF(AND(ISNUMBER(Manual_AuV!C5),NOT(ISNUMBER(Calc_AuV!C5))),"só manual","sem valor"))) -> só calc | E5: =IF(AND(ISNUMBER(Calc_AuV!E5),ISNUMBER(Manual_AuV!E5)),Calc_AuV!E5/Manual_AuV!E5,IF(AND(ISNUMBER(Calc_AuV!E5),NOT(ISNUMBER(Manual_AuV!E5))),"só calc",IF(AND(ISNUMBER(Manual_AuV!E5),NOT(ISNUMBER(Calc_AuV!E5))),"só manual","sem valor"))) -> só calc | G5: =IF(AND(ISNUMBER(Calc_AuV!G5),ISNUMBER(Manual_AuV!G5)),Calc_AuV!G5/Manual_AuV!G5,IF(AND(ISNUMBER(Calc_AuV!G5),NOT(ISNUMBER(Manual_AuV!G5))),"só calc",IF(AND(ISNUMBER(Manual_AuV!G5),NOT(ISNUMBER(Calc_AuV!G5))),"só manual","sem valor"))) -> só calc | I5: =IF(AND(ISNUMBER(Calc_AuV!I5),ISNUMBER(Manual_AuV!I5)),Calc_AuV!I5/Manual_AuV!I5,IF(AND(ISNUMBER(Calc_AuV!I5),NOT(ISNUMBER(Manual_AuV!I5))),"só calc",IF(AND(ISNUMBER(Manual_AuV!I5),NOT(ISNUMBER(Calc_AuV!I5))),"só manual","sem valor"))) -> só calc | K5: =IF(AND(ISNUMBER(Calc_AuV!K5),ISNUMBER(Manual_AuV!K5)),Calc_AuV!K5/Manual_AuV!K5,IF(AND(ISNUMBER(Calc_AuV!K5),NOT(ISNUMBER(Manual_AuV!K5))),"só calc",IF(AND(ISNUMBER(Manual_AuV!K5),NOT(ISNUMBER(Calc_AuV!K5))),"só manual","sem valor"))) -> 1 | M5: =IF(AND(ISNUMBER(Calc_AuV!M5),ISNUMBER(Manual_AuV!M5)),Calc_AuV!M5/Manual_AuV!M5,IF(AND(ISNUMBER(Calc_AuV!M5),NOT(ISNUMBER(Manual_AuV!M5))),"só calc",IF(AND(ISNUMBER(Manual_AuV!M5),NOT(ISNUMBER(Calc_AuV!M5))),"só manual","sem valor"))) -> só calc | O5: =IF(AND(ISNUMBER(Calc_AuV!O5),ISNUMBER(Manual_AuV!O5)),Calc_AuV!O5/Manual_AuV!O5,IF(AND(ISNUMBER(Calc_AuV!O5),NOT(ISNUMBER(Manual_AuV!O5))),"só calc",IF(AND(ISNUMBER(Manual_AuV!O5),NOT(ISNUMBER(Calc_AuV!O5))),"só manual","sem valor"))) -> só calc | Q5: =IF(AND(ISNUMBER(Calc_AuV!Q5),ISNUMBER(Manual_AuV!Q5)),Calc_AuV!Q5/Manual_AuV!Q5,IF(AND(ISNUMBER(Calc_AuV!Q5),NOT(ISNUMBER(Manual_AuV!Q5))),"só calc",IF(AND(ISNUMBER(Manual_AuV!Q5),NOT(ISNUMBER(Calc_AuV!Q5))),"só manual","sem valor"))) -> só calc | S5: =IF(AND(ISNUMBER(Calc_AuV!S5),ISNUMBER(Manual_AuV!S5)),Calc_AuV!S5/Manual_AuV!S5,IF(AND(ISNUMBER(Calc_AuV!S5),NOT(ISNUMBER(Manual_AuV!S5))),"só calc",IF(AND(ISNUMBER(Manual_AuV!S5),NOT(ISNUMBER(Calc_AuV!S5))),"só manual","sem valor"))) -> só calc | U5: =IF(AND(ISNUMBER(Calc_AuV!U5),ISNUMBER(Manual_AuV!U5)),Calc_AuV!U5/Manual_AuV!U5,IF(AND(ISNUMBER(Calc_AuV!U5),NOT(ISNUMBER(Manual_AuV!U5))),"só calc",IF(AND(ISNUMBER(Manual_AuV!U5),NOT(ISNUMBER(Calc_AuV!U5))),"só manual","sem valor"))) -> só calc | W5: =IF(AND(ISNUMBER(Calc_AuV!W5),ISNUMBER(Manual_AuV!W5)),Calc_AuV!W5/Manual_AuV!W5,IF(AND(ISNUMBER(Calc_AuV!W5),NOT(ISNUMBER(Manual_AuV!W5))),"só calc",IF(AND(ISNUMBER(Manual_AuV!W5),NOT(ISNUMBER(Calc_AuV!W5))),"só manual","sem valor"))) -> só calc
A6: ab | B6: =Calc_AuV!B6 -> Pd Folha tomate 3 | C6: =IF(AND(ISNUMBER(Calc_AuV!C6),ISNUMBER(Manual_AuV!C6)),Calc_AuV!C6/Manual_AuV!C6,IF(AND(ISNUMBER(Calc_AuV!C6),NOT(ISNUMBER(Manual_AuV!C6))),"só calc",IF(AND(ISNUMBER(Manual_AuV!C6),NOT(ISNUMBER(Calc_AuV!C6))),"só manual","sem valor"))) -> 1 | D6: =IF(AND(ISNUMBER(Calc_AuV!D6),ISNUMBER(Manual_AuV!D6)),Calc_AuV!D6/Manual_AuV!D6,IF(AND(ISNUMBER(Calc_AuV!D6),NOT(ISNUMBER(Manual_AuV!D6))),"só calc",IF(AND(ISNUMBER(Manual_AuV!D6),NOT(ISNUMBER(Calc_AuV!D6))),"só manual","sem valor"))) -> 1 | E6: =IF(AND(ISNUMBER(Calc_AuV!E6),ISNUMBER(Manual_AuV!E6)),Calc_AuV!E6/Manual_AuV!E6,IF(AND(ISNUMBER(Calc_AuV!E6),NOT(ISNUMBER(Manual_AuV!E6))),"só calc",IF(AND(ISNUMBER(Manual_AuV!E6),NOT(ISNUMBER(Calc_AuV!E6))),"só manual","sem valor"))) -> 1 | F6: =IF(AND(ISNUMBER(Calc_AuV!F6),ISNUMBER(Manual_AuV!F6)),Calc_AuV!F6/Manual_AuV!F6,IF(AND(ISNUMBER(Calc_AuV!F6),NOT(ISNUMBER(Manual_AuV!F6))),"só calc",IF(AND(ISNUMBER(Manual_AuV!F6),NOT(ISNUMBER(Calc_AuV!F6))),"só manual","sem valor"))) -> 1 | G6: =IF(AND(ISNUMBER(Calc_AuV!G6),ISNUMBER(Manual_AuV!G6)),Calc_AuV!G6/Manual_AuV!G6,IF(AND(ISNUMBER(Calc_AuV!G6),NOT(ISNUMBER(Manual_AuV!G6))),"só calc",IF(AND(ISNUMBER(Manual_AuV!G6),NOT(ISNUMBER(Calc_AuV!G6))),"só manual","sem valor"))) -> 1 | H6: =IF(AND(ISNUMBER(Calc_AuV!H6),ISNUMBER(Manual_AuV!H6)),Calc_AuV!H6/Manual_AuV!H6,IF(AND(ISNUMBER(Calc_AuV!H6),NOT(ISNUMBER(Manual_AuV!H6))),"só calc",IF(AND(ISNUMBER(Manual_AuV!H6),NOT(ISNUMBER(Calc_AuV!H6))),"só manual","sem valor"))) -> 1 | I6: =IF(AND(ISNUMBER(Calc_AuV!I6),ISNUMBER(Manual_AuV!I6)),Calc_AuV!I6/Manual_AuV!I6,IF(AND(ISNUMBER(Calc_AuV!I6),NOT(ISNUMBER(Manual_AuV!I6))),"só calc",IF(AND(ISNUMBER(Manual_AuV!I6),NOT(ISNUMBER(Calc_AuV!I6))),"só manual","sem valor"))) -> 1 | J6: =IF(AND(ISNUMBER(Calc_AuV!J6),ISNUMBER(Manual_AuV!J6)),Calc_AuV!J6/Manual_AuV!J6,IF(AND(ISNUMBER(Calc_AuV!J6),NOT(ISNUMBER(Manual_AuV!J6))),"só calc",IF(AND(ISNUMBER(Manual_AuV!J6),NOT(ISNUMBER(Calc_AuV!J6))),"só manual","sem valor"))) -> 1 | ... X6: =IF(AND(ISNUMBER(Calc_AuV!X6),ISNUMBER(Manual_AuV!X6)),Calc_AuV!X6/Manual_AuV!X6,IF(AND(ISNUMBER(Calc_AuV!X6),NOT(ISNUMBER(Manual_AuV!X6))),"só calc",IF(AND(ISNUMBER(Manual_AuV!X6),NOT(ISNUMBER(Calc_AuV!X6))),"só manual","sem valor"))) -> 1
A7: ac | B7: =Calc_AuV!B7 -> R2 | C7: =IF(AND(ISNUMBER(Calc_AuV!C7),ISNUMBER(Manual_AuV!C7)),Calc_AuV!C7/Manual_AuV!C7,IF(AND(ISNUMBER(Calc_AuV!C7),NOT(ISNUMBER(Manual_AuV!C7))),"só calc",IF(AND(ISNUMBER(Manual_AuV!C7),NOT(ISNUMBER(Calc_AuV!C7))),"só manual","sem valor"))) -> 1 | D7: =IF(AND(ISNUMBER(Calc_AuV!D7),ISNUMBER(Manual_AuV!D7)),Calc_AuV!D7/Manual_AuV!D7,IF(AND(ISNUMBER(Calc_AuV!D7),NOT(ISNUMBER(Manual_AuV!D7))),"só calc",IF(AND(ISNUMBER(Manual_AuV!D7),NOT(ISNUMBER(Calc_AuV!D7))),"só manual","sem valor"))) -> 0.99812239 | E7: =IF(AND(ISNUMBER(Calc_AuV!E7),ISNUMBER(Manual_AuV!E7)),Calc_AuV!E7/Manual_AuV!E7,IF(AND(ISNUMBER(Calc_AuV!E7),NOT(ISNUMBER(Manual_AuV!E7))),"só calc",IF(AND(ISNUMBER(Manual_AuV!E7),NOT(ISNUMBER(Calc_AuV!E7))),"só manual","sem valor"))) -> 1 | F7: =IF(AND(ISNUMBER(Calc_AuV!F7),ISNUMBER(Manual_AuV!F7)),Calc_AuV!F7/Manual_AuV!F7,IF(AND(ISNUMBER(Calc_AuV!F7),NOT(ISNUMBER(Manual_AuV!F7))),"só calc",IF(AND(ISNUMBER(Manual_AuV!F7),NOT(ISNUMBER(Calc_AuV!F7))),"só manual","sem valor"))) -> 1.0014211 | G7: =IF(AND(ISNUMBER(Calc_AuV!G7),ISNUMBER(Manual_AuV!G7)),Calc_AuV!G7/Manual_AuV!G7,IF(AND(ISNUMBER(Calc_AuV!G7),NOT(ISNUMBER(Manual_AuV!G7))),"só calc",IF(AND(ISNUMBER(Manual_AuV!G7),NOT(ISNUMBER(Calc_AuV!G7))),"só manual","sem valor"))) -> 1 | H7: =IF(AND(ISNUMBER(Calc_AuV!H7),ISNUMBER(Manual_AuV!H7)),Calc_AuV!H7/Manual_AuV!H7,IF(AND(ISNUMBER(Calc_AuV!H7),NOT(ISNUMBER(Manual_AuV!H7))),"só calc",IF(AND(ISNUMBER(Manual_AuV!H7),NOT(ISNUMBER(Calc_AuV!H7))),"só manual","sem valor"))) -> 0.99987828 | I7: =IF(AND(ISNUMBER(Calc_AuV!I7),ISNUMBER(Manual_AuV!I7)),Calc_AuV!I7/Manual_AuV!I7,IF(AND(ISNUMBER(Calc_AuV!I7),NOT(ISNUMBER(Manual_AuV!I7))),"só calc",IF(AND(ISNUMBER(Manual_AuV!I7),NOT(ISNUMBER(Calc_AuV!I7))),"só manual","sem valor"))) -> 1 | J7: =IF(AND(ISNUMBER(Calc_AuV!J7),ISNUMBER(Manual_AuV!J7)),Calc_AuV!J7/Manual_AuV!J7,IF(AND(ISNUMBER(Calc_AuV!J7),NOT(ISNUMBER(Manual_AuV!J7))),"só calc",IF(AND(ISNUMBER(Manual_AuV!J7),NOT(ISNUMBER(Calc_AuV!J7))),"só manual","sem valor"))) -> 0.99950985 | ... X7: =IF(AND(ISNUMBER(Calc_AuV!X7),ISNUMBER(Manual_AuV!X7)),Calc_AuV!X7/Manual_AuV!X7,IF(AND(ISNUMBER(Calc_AuV!X7),NOT(ISNUMBER(Manual_AuV!X7))),"só calc",IF(AND(ISNUMBER(Manual_AuV!X7),NOT(ISNUMBER(Calc_AuV!X7))),"só manual","sem valor"))) -> 1.0005959
A8: ad | B8: =Calc_AuV!B8 -> R3 | C8: =IF(AND(ISNUMBER(Calc_AuV!C8),ISNUMBER(Manual_AuV!C8)),Calc_AuV!C8/Manual_AuV!C8,IF(AND(ISNUMBER(Calc_AuV!C8),NOT(ISNUMBER(Manual_AuV!C8))),"só calc",IF(AND(ISNUMBER(Manual_AuV!C8),NOT(ISNUMBER(Calc_AuV!C8))),"só manual","sem valor"))) -> 1 | D8: =IF(AND(ISNUMBER(Calc_AuV!D8),ISNUMBER(Manual_AuV!D8)),Calc_AuV!D8/Manual_AuV!D8,IF(AND(ISNUMBER(Calc_AuV!D8),NOT(ISNUMBER(Manual_AuV!D8))),"só calc",IF(AND(ISNUMBER(Manual_AuV!D8),NOT(ISNUMBER(Calc_AuV!D8))),"só manual","sem valor"))) -> 0.99913203 | E8: =IF(AND(ISNUMBER(Calc_AuV!E8),ISNUMBER(Manual_AuV!E8)),Calc_AuV!E8/Manual_AuV!E8,IF(AND(ISNUMBER(Calc_AuV!E8),NOT(ISNUMBER(Manual_AuV!E8))),"só calc",IF(AND(ISNUMBER(Manual_AuV!E8),NOT(ISNUMBER(Calc_AuV!E8))),"só manual","sem valor"))) -> 1 | F8: =IF(AND(ISNUMBER(Calc_AuV!F8),ISNUMBER(Manual_AuV!F8)),Calc_AuV!F8/Manual_AuV!F8,IF(AND(ISNUMBER(Calc_AuV!F8),NOT(ISNUMBER(Manual_AuV!F8))),"só calc",IF(AND(ISNUMBER(Manual_AuV!F8),NOT(ISNUMBER(Calc_AuV!F8))),"só manual","sem valor"))) -> 1.0009807 | G8: =IF(AND(ISNUMBER(Calc_AuV!G8),ISNUMBER(Manual_AuV!G8)),Calc_AuV!G8/Manual_AuV!G8,IF(AND(ISNUMBER(Calc_AuV!G8),NOT(ISNUMBER(Manual_AuV!G8))),"só calc",IF(AND(ISNUMBER(Manual_AuV!G8),NOT(ISNUMBER(Calc_AuV!G8))),"só manual","sem valor"))) -> 1 | H8: =IF(AND(ISNUMBER(Calc_AuV!H8),ISNUMBER(Manual_AuV!H8)),Calc_AuV!H8/Manual_AuV!H8,IF(AND(ISNUMBER(Calc_AuV!H8),NOT(ISNUMBER(Manual_AuV!H8))),"só calc",IF(AND(ISNUMBER(Manual_AuV!H8),NOT(ISNUMBER(Calc_AuV!H8))),"só manual","sem valor"))) -> 1.0002679 | I8: =IF(AND(ISNUMBER(Calc_AuV!I8),ISNUMBER(Manual_AuV!I8)),Calc_AuV!I8/Manual_AuV!I8,IF(AND(ISNUMBER(Calc_AuV!I8),NOT(ISNUMBER(Manual_AuV!I8))),"só calc",IF(AND(ISNUMBER(Manual_AuV!I8),NOT(ISNUMBER(Calc_AuV!I8))),"só manual","sem valor"))) -> 1 | J8: =IF(AND(ISNUMBER(Calc_AuV!J8),ISNUMBER(Manual_AuV!J8)),Calc_AuV!J8/Manual_AuV!J8,IF(AND(ISNUMBER(Calc_AuV!J8),NOT(ISNUMBER(Manual_AuV!J8))),"só calc",IF(AND(ISNUMBER(Manual_AuV!J8),NOT(ISNUMBER(Calc_AuV!J8))),"só manual","sem valor"))) -> 1.0008916 | ... X8: =IF(AND(ISNUMBER(Calc_AuV!X8),ISNUMBER(Manual_AuV!X8)),Calc_AuV!X8/Manual_AuV!X8,IF(AND(ISNUMBER(Calc_AuV!X8),NOT(ISNUMBER(Manual_AuV!X8))),"só calc",IF(AND(ISNUMBER(Manual_AuV!X8),NOT(ISNUMBER(Calc_AuV!X8))),"só manual","sem valor"))) -> 0.99991441
A9: ae | B9: =Calc_AuV!B9 -> R4 | C9: =IF(AND(ISNUMBER(Calc_AuV!C9),ISNUMBER(Manual_AuV!C9)),Calc_AuV!C9/Manual_AuV!C9,IF(AND(ISNUMBER(Calc_AuV!C9),NOT(ISNUMBER(Manual_AuV!C9))),"só calc",IF(AND(ISNUMBER(Manual_AuV!C9),NOT(ISNUMBER(Calc_AuV!C9))),"só manual","sem valor"))) -> 1 | D9: =IF(AND(ISNUMBER(Calc_AuV!D9),ISNUMBER(Manual_AuV!D9)),Calc_AuV!D9/Manual_AuV!D9,IF(AND(ISNUMBER(Calc_AuV!D9),NOT(ISNUMBER(Manual_AuV!D9))),"só calc",IF(AND(ISNUMBER(Manual_AuV!D9),NOT(ISNUMBER(Calc_AuV!D9))),"só manual","sem valor"))) -> 0.99909697 | E9: =IF(AND(ISNUMBER(Calc_AuV!E9),ISNUMBER(Manual_AuV!E9)),Calc_AuV!E9/Manual_AuV!E9,IF(AND(ISNUMBER(Calc_AuV!E9),NOT(ISNUMBER(Manual_AuV!E9))),"só calc",IF(AND(ISNUMBER(Manual_AuV!E9),NOT(ISNUMBER(Calc_AuV!E9))),"só manual","sem valor"))) -> 1 | F9: =IF(AND(ISNUMBER(Calc_AuV!F9),ISNUMBER(Manual_AuV!F9)),Calc_AuV!F9/Manual_AuV!F9,IF(AND(ISNUMBER(Calc_AuV!F9),NOT(ISNUMBER(Manual_AuV!F9))),"só calc",IF(AND(ISNUMBER(Manual_AuV!F9),NOT(ISNUMBER(Calc_AuV!F9))),"só manual","sem valor"))) -> 0.99683778 | G9: =IF(AND(ISNUMBER(Calc_AuV!G9),ISNUMBER(Manual_AuV!G9)),Calc_AuV!G9/Manual_AuV!G9,IF(AND(ISNUMBER(Calc_AuV!G9),NOT(ISNUMBER(Manual_AuV!G9))),"só calc",IF(AND(ISNUMBER(Manual_AuV!G9),NOT(ISNUMBER(Calc_AuV!G9))),"só manual","sem valor"))) -> 1 | H9: =IF(AND(ISNUMBER(Calc_AuV!H9),ISNUMBER(Manual_AuV!H9)),Calc_AuV!H9/Manual_AuV!H9,IF(AND(ISNUMBER(Calc_AuV!H9),NOT(ISNUMBER(Manual_AuV!H9))),"só calc",IF(AND(ISNUMBER(Manual_AuV!H9),NOT(ISNUMBER(Calc_AuV!H9))),"só manual","sem valor"))) -> 0.99993581 | I9: =IF(AND(ISNUMBER(Calc_AuV!I9),ISNUMBER(Manual_AuV!I9)),Calc_AuV!I9/Manual_AuV!I9,IF(AND(ISNUMBER(Calc_AuV!I9),NOT(ISNUMBER(Manual_AuV!I9))),"só calc",IF(AND(ISNUMBER(Manual_AuV!I9),NOT(ISNUMBER(Calc_AuV!I9))),"só manual","sem valor"))) -> 1 | J9: =IF(AND(ISNUMBER(Calc_AuV!J9),ISNUMBER(Manual_AuV!J9)),Calc_AuV!J9/Manual_AuV!J9,IF(AND(ISNUMBER(Calc_AuV!J9),NOT(ISNUMBER(Manual_AuV!J9))),"só calc",IF(AND(ISNUMBER(Manual_AuV!J9),NOT(ISNUMBER(Calc_AuV!J9))),"só manual","sem valor"))) -> 1.0009575 | ... X9: =IF(AND(ISNUMBER(Calc_AuV!X9),ISNUMBER(Manual_AuV!X9)),Calc_AuV!X9/Manual_AuV!X9,IF(AND(ISNUMBER(Calc_AuV!X9),NOT(ISNUMBER(Manual_AuV!X9))),"só calc",IF(AND(ISNUMBER(Manual_AuV!X9),NOT(ISNUMBER(Calc_AuV!X9))),"só manual","sem valor"))) -> 0.99958826
A10: af | B10: =Calc_AuV!B10 -> R5 | C10: =IF(AND(ISNUMBER(Calc_AuV!C10),ISNUMBER(Manual_AuV!C10)),Calc_AuV!C10/Manual_AuV!C10,IF(AND(ISNUMBER(Calc_AuV!C10),NOT(ISNUMBER(Manual_AuV!C10))),"só calc",IF(AND(ISNUMBER(Manual_AuV!C10),NOT(ISNUMBER(Calc_AuV!C10))),"só manual","sem valor"))) -> 1 | D10: =IF(AND(ISNUMBER(Calc_AuV!D10),ISNUMBER(Manual_AuV!D10)),Calc_AuV!D10/Manual_AuV!D10,IF(AND(ISNUMBER(Calc_AuV!D10),NOT(ISNUMBER(Manual_AuV!D10))),"só calc",IF(AND(ISNUMBER(Manual_AuV!D10),NOT(ISNUMBER(Calc_AuV!D10))),"só manual","sem valor"))) -> 0.9917613 | E10: =IF(AND(ISNUMBER(Calc_AuV!E10),ISNUMBER(Manual_AuV!E10)),Calc_AuV!E10/Manual_AuV!E10,IF(AND(ISNUMBER(Calc_AuV!E10),NOT(ISNUMBER(Manual_AuV!E10))),"só calc",IF(AND(ISNUMBER(Manual_AuV!E10),NOT(ISNUMBER(Calc_AuV!E10))),"só manual","sem valor"))) -> 1 | F10: =IF(AND(ISNUMBER(Calc_AuV!F10),ISNUMBER(Manual_AuV!F10)),Calc_AuV!F10/Manual_AuV!F10,IF(AND(ISNUMBER(Calc_AuV!F10),NOT(ISNUMBER(Manual_AuV!F10))),"só calc",IF(AND(ISNUMBER(Manual_AuV!F10),NOT(ISNUMBER(Calc_AuV!F10))),"só manual","sem valor"))) -> 0.99854201 | G10: =IF(AND(ISNUMBER(Calc_AuV!G10),ISNUMBER(Manual_AuV!G10)),Calc_AuV!G10/Manual_AuV!G10,IF(AND(ISNUMBER(Calc_AuV!G10),NOT(ISNUMBER(Manual_AuV!G10))),"só calc",IF(AND(ISNUMBER(Manual_AuV!G10),NOT(ISNUMBER(Calc_AuV!G10))),"só manual","sem valor"))) -> 1 | H10: =IF(AND(ISNUMBER(Calc_AuV!H10),ISNUMBER(Manual_AuV!H10)),Calc_AuV!H10/Manual_AuV!H10,IF(AND(ISNUMBER(Calc_AuV!H10),NOT(ISNUMBER(Manual_AuV!H10))),"só calc",IF(AND(ISNUMBER(Manual_AuV!H10),NOT(ISNUMBER(Calc_AuV!H10))),"só manual","sem valor"))) -> 0.99997712 | I10: =IF(AND(ISNUMBER(Calc_AuV!I10),ISNUMBER(Manual_AuV!I10)),Calc_AuV!I10/Manual_AuV!I10,IF(AND(ISNUMBER(Calc_AuV!I10),NOT(ISNUMBER(Manual_AuV!I10))),"só calc",IF(AND(ISNUMBER(Manual_AuV!I10),NOT(ISNUMBER(Calc_AuV!I10))),"só manual","sem valor"))) -> 1 | J10: =IF(AND(ISNUMBER(Calc_AuV!J10),ISNUMBER(Manual_AuV!J10)),Calc_AuV!J10/Manual_AuV!J10,IF(AND(ISNUMBER(Calc_AuV!J10),NOT(ISNUMBER(Manual_AuV!J10))),"só calc",IF(AND(ISNUMBER(Manual_AuV!J10),NOT(ISNUMBER(Calc_AuV!J10))),"só manual","sem valor"))) -> 0.99953964 | ... X10: =IF(AND(ISNUMBER(Calc_AuV!X10),ISNUMBER(Manual_AuV!X10)),Calc_AuV!X10/Manual_AuV!X10,IF(AND(ISNUMBER(Calc_AuV!X10),NOT(ISNUMBER(Manual_AuV!X10))),"só calc",IF(AND(ISNUMBER(Manual_AuV!X10),NOT(ISNUMBER(Calc_AuV!X10))),"só manual","sem valor"))) -> 1.0003173
A11: ag | B11: =Calc_AuV!B11 -> R6 | C11: =IF(AND(ISNUMBER(Calc_AuV!C11),ISNUMBER(Manual_AuV!C11)),Calc_AuV!C11/Manual_AuV!C11,IF(AND(ISNUMBER(Calc_AuV!C11),NOT(ISNUMBER(Manual_AuV!C11))),"só calc",IF(AND(ISNUMBER(Manual_AuV!C11),NOT(ISNUMBER(Calc_AuV!C11))),"só manual","sem valor"))) -> 1 | D11: =IF(AND(ISNUMBER(Calc_AuV!D11),ISNUMBER(Manual_AuV!D11)),Calc_AuV!D11/Manual_AuV!D11,IF(AND(ISNUMBER(Calc_AuV!D11),NOT(ISNUMBER(Manual_AuV!D11))),"só calc",IF(AND(ISNUMBER(Manual_AuV!D11),NOT(ISNUMBER(Calc_AuV!D11))),"só manual","sem valor"))) -> 0.992452 | E11: =IF(AND(ISNUMBER(Calc_AuV!E11),ISNUMBER(Manual_AuV!E11)),Calc_AuV!E11/Manual_AuV!E11,IF(AND(ISNUMBER(Calc_AuV!E11),NOT(ISNUMBER(Manual_AuV!E11))),"só calc",IF(AND(ISNUMBER(Manual_AuV!E11),NOT(ISNUMBER(Calc_AuV!E11))),"só manual","sem valor"))) -> 1 | F11: =IF(AND(ISNUMBER(Calc_AuV!F11),ISNUMBER(Manual_AuV!F11)),Calc_AuV!F11/Manual_AuV!F11,IF(AND(ISNUMBER(Calc_AuV!F11),NOT(ISNUMBER(Manual_AuV!F11))),"só calc",IF(AND(ISNUMBER(Manual_AuV!F11),NOT(ISNUMBER(Calc_AuV!F11))),"só manual","sem valor"))) -> 0.99473317 | G11: =IF(AND(ISNUMBER(Calc_AuV!G11),ISNUMBER(Manual_AuV!G11)),Calc_AuV!G11/Manual_AuV!G11,IF(AND(ISNUMBER(Calc_AuV!G11),NOT(ISNUMBER(Manual_AuV!G11))),"só calc",IF(AND(ISNUMBER(Manual_AuV!G11),NOT(ISNUMBER(Calc_AuV!G11))),"só manual","sem valor"))) -> 1 | H11: =IF(AND(ISNUMBER(Calc_AuV!H11),ISNUMBER(Manual_AuV!H11)),Calc_AuV!H11/Manual_AuV!H11,IF(AND(ISNUMBER(Calc_AuV!H11),NOT(ISNUMBER(Manual_AuV!H11))),"só calc",IF(AND(ISNUMBER(Manual_AuV!H11),NOT(ISNUMBER(Calc_AuV!H11))),"só manual","sem valor"))) -> 1.0000639 | I11: =IF(AND(ISNUMBER(Calc_AuV!I11),ISNUMBER(Manual_AuV!I11)),Calc_AuV!I11/Manual_AuV!I11,IF(AND(ISNUMBER(Calc_AuV!I11),NOT(ISNUMBER(Manual_AuV!I11))),"só calc",IF(AND(ISNUMBER(Manual_AuV!I11),NOT(ISNUMBER(Calc_AuV!I11))),"só manual","sem valor"))) -> 1 | J11: =IF(AND(ISNUMBER(Calc_AuV!J11),ISNUMBER(Manual_AuV!J11)),Calc_AuV!J11/Manual_AuV!J11,IF(AND(ISNUMBER(Calc_AuV!J11),NOT(ISNUMBER(Manual_AuV!J11))),"só calc",IF(AND(ISNUMBER(Manual_AuV!J11),NOT(ISNUMBER(Calc_AuV!J11))),"só manual","sem valor"))) -> 1.0004463 | ... X11: =IF(AND(ISNUMBER(Calc_AuV!X11),ISNUMBER(Manual_AuV!X11)),Calc_AuV!X11/Manual_AuV!X11,IF(AND(ISNUMBER(Calc_AuV!X11),NOT(ISNUMBER(Manual_AuV!X11))),"só calc",IF(AND(ISNUMBER(Manual_AuV!X11),NOT(ISNUMBER(Calc_AuV!X11))),"só manual","sem valor"))) -> 1.0000384
A12: ah | B12: =Calc_AuV!B12 -> R7 | C12: =IF(AND(ISNUMBER(Calc_AuV!C12),ISNUMBER(Manual_AuV!C12)),Calc_AuV!C12/Manual_AuV!C12,IF(AND(ISNUMBER(Calc_AuV!C12),NOT(ISNUMBER(Manual_AuV!C12))),"só calc",IF(AND(ISNUMBER(Manual_AuV!C12),NOT(ISNUMBER(Calc_AuV!C12))),"só manual","sem valor"))) -> 1 | D12: =IF(AND(ISNUMBER(Calc_AuV!D12),ISNUMBER(Manual_AuV!D12)),Calc_AuV!D12/Manual_AuV!D12,IF(AND(ISNUMBER(Calc_AuV!D12),NOT(ISNUMBER(Manual_AuV!D12))),"só calc",IF(AND(ISNUMBER(Manual_AuV!D12),NOT(ISNUMBER(Calc_AuV!D12))),"só manual","sem valor"))) -> 1.0076998 | E12: =IF(AND(ISNUMBER(Calc_AuV!E12),ISNUMBER(Manual_AuV!E12)),Calc_AuV!E12/Manual_AuV!E12,IF(AND(ISNUMBER(Calc_AuV!E12),NOT(ISNUMBER(Manual_AuV!E12))),"só calc",IF(AND(ISNUMBER(Manual_AuV!E12),NOT(ISNUMBER(Calc_AuV!E12))),"só manual","sem valor"))) -> 1 | F12: =IF(AND(ISNUMBER(Calc_AuV!F12),ISNUMBER(Manual_AuV!F12)),Calc_AuV!F12/Manual_AuV!F12,IF(AND(ISNUMBER(Calc_AuV!F12),NOT(ISNUMBER(Manual_AuV!F12))),"só calc",IF(AND(ISNUMBER(Manual_AuV!F12),NOT(ISNUMBER(Calc_AuV!F12))),"só manual","sem valor"))) -> 1.0000877 | G12: =IF(AND(ISNUMBER(Calc_AuV!G12),ISNUMBER(Manual_AuV!G12)),Calc_AuV!G12/Manual_AuV!G12,IF(AND(ISNUMBER(Calc_AuV!G12),NOT(ISNUMBER(Manual_AuV!G12))),"só calc",IF(AND(ISNUMBER(Manual_AuV!G12),NOT(ISNUMBER(Calc_AuV!G12))),"só manual","sem valor"))) -> 1 | H12: =IF(AND(ISNUMBER(Calc_AuV!H12),ISNUMBER(Manual_AuV!H12)),Calc_AuV!H12/Manual_AuV!H12,IF(AND(ISNUMBER(Calc_AuV!H12),NOT(ISNUMBER(Manual_AuV!H12))),"só calc",IF(AND(ISNUMBER(Manual_AuV!H12),NOT(ISNUMBER(Calc_AuV!H12))),"só manual","sem valor"))) -> 1.0002031 | I12: =IF(AND(ISNUMBER(Calc_AuV!I12),ISNUMBER(Manual_AuV!I12)),Calc_AuV!I12/Manual_AuV!I12,IF(AND(ISNUMBER(Calc_AuV!I12),NOT(ISNUMBER(Manual_AuV!I12))),"só calc",IF(AND(ISNUMBER(Manual_AuV!I12),NOT(ISNUMBER(Calc_AuV!I12))),"só manual","sem valor"))) -> 1 | J12: =IF(AND(ISNUMBER(Calc_AuV!J12),ISNUMBER(Manual_AuV!J12)),Calc_AuV!J12/Manual_AuV!J12,IF(AND(ISNUMBER(Calc_AuV!J12),NOT(ISNUMBER(Manual_AuV!J12))),"só calc",IF(AND(ISNUMBER(Manual_AuV!J12),NOT(ISNUMBER(Calc_AuV!J12))),"só manual","sem valor"))) -> 0.99966455 | ... X12: =IF(AND(ISNUMBER(Calc_AuV!X12),ISNUMBER(Manual_AuV!X12)),Calc_AuV!X12/Manual_AuV!X12,IF(AND(ISNUMBER(Calc_AuV!X12),NOT(ISNUMBER(Manual_AuV!X12))),"só calc",IF(AND(ISNUMBER(Manual_AuV!X12),NOT(ISNUMBER(Calc_AuV!X12))),"só manual","sem valor"))) -> 0.99975177
A13: ai | B13: =Calc_AuV!B13 -> R8 | C13: =IF(AND(ISNUMBER(Calc_AuV!C13),ISNUMBER(Manual_AuV!C13)),Calc_AuV!C13/Manual_AuV!C13,IF(AND(ISNUMBER(Calc_AuV!C13),NOT(ISNUMBER(Manual_AuV!C13))),"só calc",IF(AND(ISNUMBER(Manual_AuV!C13),NOT(ISNUMBER(Calc_AuV!C13))),"só manual","sem valor"))) -> 1 | D13: =IF(AND(ISNUMBER(Calc_AuV!D13),ISNUMBER(Manual_AuV!D13)),Calc_AuV!D13/Manual_AuV!D13,IF(AND(ISNUMBER(Calc_AuV!D13),NOT(ISNUMBER(Manual_AuV!D13))),"só calc",IF(AND(ISNUMBER(Manual_AuV!D13),NOT(ISNUMBER(Calc_AuV!D13))),"só manual","sem valor"))) -> 1.0054685 | E13: =IF(AND(ISNUMBER(Calc_AuV!E13),ISNUMBER(Manual_AuV!E13)),Calc_AuV!E13/Manual_AuV!E13,IF(AND(ISNUMBER(Calc_AuV!E13),NOT(ISNUMBER(Manual_AuV!E13))),"só calc",IF(AND(ISNUMBER(Manual_AuV!E13),NOT(ISNUMBER(Calc_AuV!E13))),"só manual","sem valor"))) -> 1 | F13: =IF(AND(ISNUMBER(Calc_AuV!F13),ISNUMBER(Manual_AuV!F13)),Calc_AuV!F13/Manual_AuV!F13,IF(AND(ISNUMBER(Calc_AuV!F13),NOT(ISNUMBER(Manual_AuV!F13))),"só calc",IF(AND(ISNUMBER(Manual_AuV!F13),NOT(ISNUMBER(Calc_AuV!F13))),"só manual","sem valor"))) -> 0.99990678 | G13: =IF(AND(ISNUMBER(Calc_AuV!G13),ISNUMBER(Manual_AuV!G13)),Calc_AuV!G13/Manual_AuV!G13,IF(AND(ISNUMBER(Calc_AuV!G13),NOT(ISNUMBER(Manual_AuV!G13))),"só calc",IF(AND(ISNUMBER(Manual_AuV!G13),NOT(ISNUMBER(Calc_AuV!G13))),"só manual","sem valor"))) -> 1 | H13: =IF(AND(ISNUMBER(Calc_AuV!H13),ISNUMBER(Manual_AuV!H13)),Calc_AuV!H13/Manual_AuV!H13,IF(AND(ISNUMBER(Calc_AuV!H13),NOT(ISNUMBER(Manual_AuV!H13))),"só calc",IF(AND(ISNUMBER(Manual_AuV!H13),NOT(ISNUMBER(Calc_AuV!H13))),"só manual","sem valor"))) -> 0.99982488 | I13: =IF(AND(ISNUMBER(Calc_AuV!I13),ISNUMBER(Manual_AuV!I13)),Calc_AuV!I13/Manual_AuV!I13,IF(AND(ISNUMBER(Calc_AuV!I13),NOT(ISNUMBER(Manual_AuV!I13))),"só calc",IF(AND(ISNUMBER(Manual_AuV!I13),NOT(ISNUMBER(Calc_AuV!I13))),"só manual","sem valor"))) -> 1 | J13: =IF(AND(ISNUMBER(Calc_AuV!J13),ISNUMBER(Manual_AuV!J13)),Calc_AuV!J13/Manual_AuV!J13,IF(AND(ISNUMBER(Calc_AuV!J13),NOT(ISNUMBER(Manual_AuV!J13))),"só calc",IF(AND(ISNUMBER(Manual_AuV!J13),NOT(ISNUMBER(Calc_AuV!J13))),"só manual","sem valor"))) -> 1.0006748 | ... X13: =IF(AND(ISNUMBER(Calc_AuV!X13),ISNUMBER(Manual_AuV!X13)),Calc_AuV!X13/Manual_AuV!X13,IF(AND(ISNUMBER(Calc_AuV!X13),NOT(ISNUMBER(Manual_AuV!X13))),"só calc",IF(AND(ISNUMBER(Manual_AuV!X13),NOT(ISNUMBER(Calc_AuV!X13))),"só manual","sem valor"))) -> 0.9999249
A14: aj | B14: =Calc_AuV!B14 -> R9 | C14: =IF(AND(ISNUMBER(Calc_AuV!C14),ISNUMBER(Manual_AuV!C14)),Calc_AuV!C14/Manual_AuV!C14,IF(AND(ISNUMBER(Calc_AuV!C14),NOT(ISNUMBER(Manual_AuV!C14))),"só calc",IF(AND(ISNUMBER(Manual_AuV!C14),NOT(ISNUMBER(Calc_AuV!C14))),"só manual","sem valor"))) -> 1 | D14: =IF(AND(ISNUMBER(Calc_AuV!D14),ISNUMBER(Manual_AuV!D14)),Calc_AuV!D14/Manual_AuV!D14,IF(AND(ISNUMBER(Calc_AuV!D14),NOT(ISNUMBER(Manual_AuV!D14))),"só calc",IF(AND(ISNUMBER(Manual_AuV!D14),NOT(ISNUMBER(Calc_AuV!D14))),"só manual","sem valor"))) -> 0.99916788 | E14: =IF(AND(ISNUMBER(Calc_AuV!E14),ISNUMBER(Manual_AuV!E14)),Calc_AuV!E14/Manual_AuV!E14,IF(AND(ISNUMBER(Calc_AuV!E14),NOT(ISNUMBER(Manual_AuV!E14))),"só calc",IF(AND(ISNUMBER(Manual_AuV!E14),NOT(ISNUMBER(Calc_AuV!E14))),"só manual","sem valor"))) -> 1 | F14: =IF(AND(ISNUMBER(Calc_AuV!F14),ISNUMBER(Manual_AuV!F14)),Calc_AuV!F14/Manual_AuV!F14,IF(AND(ISNUMBER(Calc_AuV!F14),NOT(ISNUMBER(Manual_AuV!F14))),"só calc",IF(AND(ISNUMBER(Manual_AuV!F14),NOT(ISNUMBER(Calc_AuV!F14))),"só manual","sem valor"))) -> 1.0030665 | G14: =IF(AND(ISNUMBER(Calc_AuV!G14),ISNUMBER(Manual_AuV!G14)),Calc_AuV!G14/Manual_AuV!G14,IF(AND(ISNUMBER(Calc_AuV!G14),NOT(ISNUMBER(Manual_AuV!G14))),"só calc",IF(AND(ISNUMBER(Manual_AuV!G14),NOT(ISNUMBER(Calc_AuV!G14))),"só manual","sem valor"))) -> 1 | H14: =IF(AND(ISNUMBER(Calc_AuV!H14),ISNUMBER(Manual_AuV!H14)),Calc_AuV!H14/Manual_AuV!H14,IF(AND(ISNUMBER(Calc_AuV!H14),NOT(ISNUMBER(Manual_AuV!H14))),"só calc",IF(AND(ISNUMBER(Manual_AuV!H14),NOT(ISNUMBER(Calc_AuV!H14))),"só manual","sem valor"))) -> 0.99994556 | I14: =IF(AND(ISNUMBER(Calc_AuV!I14),ISNUMBER(Manual_AuV!I14)),Calc_AuV!I14/Manual_AuV!I14,IF(AND(ISNUMBER(Calc_AuV!I14),NOT(ISNUMBER(Manual_AuV!I14))),"só calc",IF(AND(ISNUMBER(Manual_AuV!I14),NOT(ISNUMBER(Calc_AuV!I14))),"só manual","sem valor"))) -> 1 | J14: =IF(AND(ISNUMBER(Calc_AuV!J14),ISNUMBER(Manual_AuV!J14)),Calc_AuV!J14/Manual_AuV!J14,IF(AND(ISNUMBER(Calc_AuV!J14),NOT(ISNUMBER(Manual_AuV!J14))),"só calc",IF(AND(ISNUMBER(Manual_AuV!J14),NOT(ISNUMBER(Calc_AuV!J14))),"só manual","sem valor"))) -> 0.99952488 | ... X14: =IF(AND(ISNUMBER(Calc_AuV!X14),ISNUMBER(Manual_AuV!X14)),Calc_AuV!X14/Manual_AuV!X14,IF(AND(ISNUMBER(Calc_AuV!X14),NOT(ISNUMBER(Manual_AuV!X14))),"só calc",IF(AND(ISNUMBER(Manual_AuV!X14),NOT(ISNUMBER(Calc_AuV!X14))),"só manual","sem valor"))) -> 0.9994054
