Workbook

Sheet Notas
A1: Comparação ferramenta computacional × planilhas eletrônicas convencionais (FRX-DE)
A3: Abas | B3: 'Tabela *' = tabelas resumidas para o artigo. 'Razões *' = razão por amostra. 'Calc_*' / 'Conv_*' = valores de entrada (texto azul).
A4: Ferramenta | B4: Resultados recalculados com a versão corrigida da ferramenta (commit 89a96ea: incerteza da área normalizada sem arredondamento), a partir dos arquivos .txt originais e do FullReport do padrão.
A5: Planilhas | B5: Cópias das planilhas convencionais com os parâmetros de entrada corrigidos e recalculadas no Excel; os arquivos originais não foram alterados. Correções abaixo.
A6: n.d. | B6: Não determinado: elemento ausente/abaixo do LD em uma das planilhas.
A8: Correções nas planilhas convencionais
A9: AgV | B9: 250226_Raiz_PdTomate_AgV_corrigida.xlsx
B10: P: Bg (X7) 2300.0 -> 1792
B11: P: incerteza do padrão (L10) 0.0 digitado -> fórmula da aba Padrões
B12: S: incerteza do padrão (L10) 0.0 digitado -> fórmula da aba Padrões
B13: Cl: incerteza do padrão (L10) 0.0 digitado -> fórmula da aba Padrões
B14: Ni: Bg (X7) 6874.0 -> 6476
B15: Zn: Bg (X7) 7925.0 -> 7205
B16: Br: incerteza do padrão (L10) 0.0 digitado -> fórmula da aba Padrões
A17: AuV | B17: 250326_Lucas_Raiz_AuV_corrigida.xlsx
B18: S: Bg (X7) Insira Bg -> 1417
B19: Cl: Bg (X7) Insira Bg -> 1863
B20: K: Bg (X7) Insira Bg -> 2730
B21: Ca: Bg (X7) Insira Bg -> 2821
B22: Mn: Bg (X7) Insira Bg -> 5469
B23: Fe: Bg (X7) Insira Bg -> 6417
B24: Ni: Bg (X7) Insira Bg -> 8966
B25: Cu: Bg (X7) Insira Bg -> 9767
B26: Zn: Bg (X7) Insira Bg -> 11316
B27: Se: Bg (X7) Insira Bg -> 11683
A28: RhV | B28: 110326_Raiz_FolhaTomate_RhV_corrigida.xlsx
B29: Cr: Bg (X7) 6647.0 -> 6674
B30: Fator de normalização (Norm) digitado como 1 em 110 células -> restaurada a fórmula Ar(padrão)/Ar(amostra)

Sheet Tabela AgV
A1: Tabela — Razão entre os resultados da ferramenta computacional e da planilha eletrônica convencional (alvo Ag), amostras de raiz de cana-de-açúcar (n = 10).
A3: Elemento | B3: n | C3: Concentração média | D3: Concentração DP | E3: Incerteza média | F3: Incerteza DP | G3: LD
A4: P | B4: =COUNT('Razões AgV'!C7:C16) -> 10 | C4: =IF(COUNT('Razões AgV'!C7:C16)>0,AVERAGE('Razões AgV'!C7:C16),"n.d.") -> 1 | D4: =IF(COUNT('Razões AgV'!C7:C16)>1,STDEV('Razões AgV'!C7:C16),"n.d.") -> 0 | E4: =IF(COUNT('Razões AgV'!D7:D16)>0,AVERAGE('Razões AgV'!D7:D16),"n.d.") -> 1 | F4: =IF(COUNT('Razões AgV'!D7:D16)>1,STDEV('Razões AgV'!D7:D16),"n.d.") -> 0 | G4: ='Razões AgV'!C5 -> 1
A5: S | B5: =COUNT('Razões AgV'!E7:E16) -> 10 | C5: =IF(COUNT('Razões AgV'!E7:E16)>0,AVERAGE('Razões AgV'!E7:E16),"n.d.") -> 1 | D5: =IF(COUNT('Razões AgV'!E7:E16)>1,STDEV('Razões AgV'!E7:E16),"n.d.") -> 0 | E5: =IF(COUNT('Razões AgV'!F7:F16)>0,AVERAGE('Razões AgV'!F7:F16),"n.d.") -> 1 | F5: =IF(COUNT('Razões AgV'!F7:F16)>1,STDEV('Razões AgV'!F7:F16),"n.d.") -> 0 | G5: ='Razões AgV'!E5 -> 1
A6: Cl | B6: =COUNT('Razões AgV'!G7:G16) -> 10 | C6: =IF(COUNT('Razões AgV'!G7:G16)>0,AVERAGE('Razões AgV'!G7:G16),"n.d.") -> 1 | D6: =IF(COUNT('Razões AgV'!G7:G16)>1,STDEV('Razões AgV'!G7:G16),"n.d.") -> 0 | E6: =IF(COUNT('Razões AgV'!H7:H16)>0,AVERAGE('Razões AgV'!H7:H16),"n.d.") -> 1 | F6: =IF(COUNT('Razões AgV'!H7:H16)>1,STDEV('Razões AgV'!H7:H16),"n.d.") -> 0 | G6: ='Razões AgV'!G5 -> 1
A7: K | B7: =COUNT('Razões AgV'!I7:I16) -> 10 | C7: =IF(COUNT('Razões AgV'!I7:I16)>0,AVERAGE('Razões AgV'!I7:I16),"n.d.") -> 1 | D7: =IF(COUNT('Razões AgV'!I7:I16)>1,STDEV('Razões AgV'!I7:I16),"n.d.") -> 0 | E7: =IF(COUNT('Razões AgV'!J7:J16)>0,AVERAGE('Razões AgV'!J7:J16),"n.d.") -> 1 | F7: =IF(COUNT('Razões AgV'!J7:J16)>1,STDEV('Razões AgV'!J7:J16),"n.d.") -> 0 | G7: ='Razões AgV'!I5 -> 1
A8: Ca | B8: =COUNT('Razões AgV'!K7:K16) -> 10 | C8: =IF(COUNT('Razões AgV'!K7:K16)>0,AVERAGE('Razões AgV'!K7:K16),"n.d.") -> 1 | D8: =IF(COUNT('Razões AgV'!K7:K16)>1,STDEV('Razões AgV'!K7:K16),"n.d.") -> 0 | E8: =IF(COUNT('Razões AgV'!L7:L16)>0,AVERAGE('Razões AgV'!L7:L16),"n.d.") -> 1 | F8: =IF(COUNT('Razões AgV'!L7:L16)>1,STDEV('Razões AgV'!L7:L16),"n.d.") -> 7.4014868e-17 | G8: ='Razões AgV'!K5 -> 1
A9: Cr | B9: =COUNT('Razões AgV'!M7:M16) -> 10 | C9: =IF(COUNT('Razões AgV'!M7:M16)>0,AVERAGE('Razões AgV'!M7:M16),"n.d.") -> 1 | D9: =IF(COUNT('Razões AgV'!M7:M16)>1,STDEV('Razões AgV'!M7:M16),"n.d.") -> 0 | E9: =IF(COUNT('Razões AgV'!N7:N16)>0,AVERAGE('Razões AgV'!N7:N16),"n.d.") -> 1 | F9: =IF(COUNT('Razões AgV'!N7:N16)>1,STDEV('Razões AgV'!N7:N16),"n.d.") -> 0 | G9: ='Razões AgV'!M5 -> 1
A10: Mn | B10: =COUNT('Razões AgV'!O7:O16) -> 10 | C10: =IF(COUNT('Razões AgV'!O7:O16)>0,AVERAGE('Razões AgV'!O7:O16),"n.d.") -> 1 | D10: =IF(COUNT('Razões AgV'!O7:O16)>1,STDEV('Razões AgV'!O7:O16),"n.d.") -> 0 | E10: =IF(COUNT('Razões AgV'!P7:P16)>0,AVERAGE('Razões AgV'!P7:P16),"n.d.") -> 1 | F10: =IF(COUNT('Razões AgV'!P7:P16)>1,STDEV('Razões AgV'!P7:P16),"n.d.") -> 0 | G10: ='Razões AgV'!O5 -> 1
A11: Fe | B11: =COUNT('Razões AgV'!Q7:Q16) -> 10 | C11: =IF(COUNT('Razões AgV'!Q7:Q16)>0,AVERAGE('Razões AgV'!Q7:Q16),"n.d.") -> 1 | D11: =IF(COUNT('Razões AgV'!Q7:Q16)>1,STDEV('Razões AgV'!Q7:Q16),"n.d.") -> 0 | E11: =IF(COUNT('Razões AgV'!R7:R16)>0,AVERAGE('Razões AgV'!R7:R16),"n.d.") -> 1 | F11: =IF(COUNT('Razões AgV'!R7:R16)>1,STDEV('Razões AgV'!R7:R16),"n.d.") -> 7.4014868e-17 | G11: ='Razões AgV'!Q5 -> 1
A12: Ni | B12: =COUNT('Razões AgV'!S7:S16) -> 10 | C12: =IF(COUNT('Razões AgV'!S7:S16)>0,AVERAGE('Razões AgV'!S7:S16),"n.d.") -> 1 | D12: =IF(COUNT('Razões AgV'!S7:S16)>1,STDEV('Razões AgV'!S7:S16),"n.d.") -> 0 | E12: =IF(COUNT('Razões AgV'!T7:T16)>0,AVERAGE('Razões AgV'!T7:T16),"n.d.") -> 1 | F12: =IF(COUNT('Razões AgV'!T7:T16)>1,STDEV('Razões AgV'!T7:T16),"n.d.") -> 0 | G12: ='Razões AgV'!S5 -> 1
A13: Cu | B13: =COUNT('Razões AgV'!U7:U16) -> 10 | C13: =IF(COUNT('Razões AgV'!U7:U16)>0,AVERAGE('Razões AgV'!U7:U16),"n.d.") -> 1 | D13: =IF(COUNT('Razões AgV'!U7:U16)>1,STDEV('Razões AgV'!U7:U16),"n.d.") -> 0 | E13: =IF(COUNT('Razões AgV'!V7:V16)>0,AVERAGE('Razões AgV'!V7:V16),"n.d.") -> 1 | F13: =IF(COUNT('Razões AgV'!V7:V16)>1,STDEV('Razões AgV'!V7:V16),"n.d.") -> 0 | G13: ='Razões AgV'!U5 -> 1
A14: Zn | B14: =COUNT('Razões AgV'!W7:W16) -> 10 | C14: =IF(COUNT('Razões AgV'!W7:W16)>0,AVERAGE('Razões AgV'!W7:W16),"n.d.") -> 1 | D14: =IF(COUNT('Razões AgV'!W7:W16)>1,STDEV('Razões AgV'!W7:W16),"n.d.") -> 0 | E14: =IF(COUNT('Razões AgV'!X7:X16)>0,AVERAGE('Razões AgV'!X7:X16),"n.d.") -> 1 | F14: =IF(COUNT('Razões AgV'!X7:X16)>1,STDEV('Razões AgV'!X7:X16),"n.d.") -> 7.4014868e-17 | G14: ='Razões AgV'!W5 -> 1
A15: Br | B15: =COUNT('Razões AgV'!Y7:Y16) -> 9 | C15: =IF(COUNT('Razões AgV'!Y7:Y16)>0,AVERAGE('Razões AgV'!Y7:Y16),"n.d.") -> 1 | D15: =IF(COUNT('Razões AgV'!Y7:Y16)>1,STDEV('Razões AgV'!Y7:Y16),"n.d.") -> 0 | E15: =IF(COUNT('Razões AgV'!Z7:Z16)>0,AVERAGE('Razões AgV'!Z7:Z16),"n.d.") -> 1 | F15: =IF(COUNT('Razões AgV'!Z7:Z16)>1,STDEV('Razões AgV'!Z7:Z16),"n.d.") -> 0 | G15: ='Razões AgV'!Y5 -> 1
A16: Razão = valor da ferramenta / valor da planilha. Média e DP sobre as amostras R2–R11; n < 10 quando o elemento ficou abaixo do LD em alguma amostra. LD calculado a partir do padrão (Tomato Leaves, NIST SRM 1573a).

Sheet Tabela AuV
A1: Tabela — Razão entre os resultados da ferramenta computacional e da planilha eletrônica convencional (alvo Au), amostras de raiz de cana-de-açúcar (n = 10).
A3: Elemento | B3: n | C3: Concentração média | D3: Concentração DP | E3: Incerteza média | F3: Incerteza DP | G3: LD
A4: S | B4: =COUNT('Razões AuV'!C7:C16) -> 10 | C4: =IF(COUNT('Razões AuV'!C7:C16)>0,AVERAGE('Razões AuV'!C7:C16),"n.d.") -> 1 | D4: =IF(COUNT('Razões AuV'!C7:C16)>1,STDEV('Razões AuV'!C7:C16),"n.d.") -> 0 | E4: =IF(COUNT('Razões AuV'!D7:D16)>0,AVERAGE('Razões AuV'!D7:D16),"n.d.") -> 1 | F4: =IF(COUNT('Razões AuV'!D7:D16)>1,STDEV('Razões AuV'!D7:D16),"n.d.") -> 0 | G4: ='Razões AuV'!C5 -> 1
A5: Cl | B5: =COUNT('Razões AuV'!E7:E16) -> 10 | C5: =IF(COUNT('Razões AuV'!E7:E16)>0,AVERAGE('Razões AuV'!E7:E16),"n.d.") -> 1 | D5: =IF(COUNT('Razões AuV'!E7:E16)>1,STDEV('Razões AuV'!E7:E16),"n.d.") -> 0 | E5: =IF(COUNT('Razões AuV'!F7:F16)>0,AVERAGE('Razões AuV'!F7:F16),"n.d.") -> 1 | F5: =IF(COUNT('Razões AuV'!F7:F16)>1,STDEV('Razões AuV'!F7:F16),"n.d.") -> 0 | G5: ='Razões AuV'!E5 -> 1
A6: K | B6: =COUNT('Razões AuV'!G7:G16) -> 10 | C6: =IF(COUNT('Razões AuV'!G7:G16)>0,AVERAGE('Razões AuV'!G7:G16),"n.d.") -> 1 | D6: =IF(COUNT('Razões AuV'!G7:G16)>1,STDEV('Razões AuV'!G7:G16),"n.d.") -> 0 | E6: =IF(COUNT('Razões AuV'!H7:H16)>0,AVERAGE('Razões AuV'!H7:H16),"n.d.") -> 1 | F6: =IF(COUNT('Razões AuV'!H7:H16)>1,STDEV('Razões AuV'!H7:H16),"n.d.") -> 0 | G6: ='Razões AuV'!G5 -> 1
A7: Ca | B7: =COUNT('Razões AuV'!I7:I16) -> 10 | C7: =IF(COUNT('Razões AuV'!I7:I16)>0,AVERAGE('Razões AuV'!I7:I16),"n.d.") -> 1 | D7: =IF(COUNT('Razões AuV'!I7:I16)>1,STDEV('Razões AuV'!I7:I16),"n.d.") -> 0 | E7: =IF(COUNT('Razões AuV'!J7:J16)>0,AVERAGE('Razões AuV'!J7:J16),"n.d.") -> 1 | F7: =IF(COUNT('Razões AuV'!J7:J16)>1,STDEV('Razões AuV'!J7:J16),"n.d.") -> 8.2751138e-17 | G7: ='Razões AuV'!I5 -> 1
A8: Cr | B8: =COUNT('Razões AuV'!K7:K16) -> 10 | C8: =IF(COUNT('Razões AuV'!K7:K16)>0,AVERAGE('Razões AuV'!K7:K16),"n.d.") -> 1 | D8: =IF(COUNT('Razões AuV'!K7:K16)>1,STDEV('Razões AuV'!K7:K16),"n.d.") -> 0 | E8: =IF(COUNT('Razões AuV'!L7:L16)>0,AVERAGE('Razões AuV'!L7:L16),"n.d.") -> 1 | F8: =IF(COUNT('Razões AuV'!L7:L16)>1,STDEV('Razões AuV'!L7:L16),"n.d.") -> 0 | G8: ='Razões AuV'!K5 -> 1
A9: Mn | B9: =COUNT('Razões AuV'!M7:M16) -> 10 | C9: =IF(COUNT('Razões AuV'!M7:M16)>0,AVERAGE('Razões AuV'!M7:M16),"n.d.") -> 1 | D9: =IF(COUNT('Razões AuV'!M7:M16)>1,STDEV('Razões AuV'!M7:M16),"n.d.") -> 0 | E9: =IF(COUNT('Razões AuV'!N7:N16)>0,AVERAGE('Razões AuV'!N7:N16),"n.d.") -> 1 | F9: =IF(COUNT('Razões AuV'!N7:N16)>1,STDEV('Razões AuV'!N7:N16),"n.d.") -> 0 | G9: ='Razões AuV'!M5 -> 1
A10: Fe | B10: =COUNT('Razões AuV'!O7:O16) -> 10 | C10: =IF(COUNT('Razões AuV'!O7:O16)>0,AVERAGE('Razões AuV'!O7:O16),"n.d.") -> 1 | D10: =IF(COUNT('Razões AuV'!O7:O16)>1,STDEV('Razões AuV'!O7:O16),"n.d.") -> 0 | E10: =IF(COUNT('Razões AuV'!P7:P16)>0,AVERAGE('Razões AuV'!P7:P16),"n.d.") -> 1 | F10: =IF(COUNT('Razões AuV'!P7:P16)>1,STDEV('Razões AuV'!P7:P16),"n.d.") -> 0 | G10: ='Razões AuV'!O5 -> 1
A11: Ni | B11: =COUNT('Razões AuV'!Q7:Q16) -> 10 | C11: =IF(COUNT('Razões AuV'!Q7:Q16)>0,AVERAGE('Razões AuV'!Q7:Q16),"n.d.") -> 1 | D11: =IF(COUNT('Razões AuV'!Q7:Q16)>1,STDEV('Razões AuV'!Q7:Q16),"n.d.") -> 0 | E11: =IF(COUNT('Razões AuV'!R7:R16)>0,AVERAGE('Razões AuV'!R7:R16),"n.d.") -> 1 | F11: =IF(COUNT('Razões AuV'!R7:R16)>1,STDEV('Razões AuV'!R7:R16),"n.d.") -> 0 | G11: ='Razões AuV'!Q5 -> 1
A12: Cu | B12: =COUNT('Razões AuV'!S7:S16) -> 10 | C12: =IF(COUNT('Razões AuV'!S7:S16)>0,AVERAGE('Razões AuV'!S7:S16),"n.d.") -> 1 | D12: =IF(COUNT('Razões AuV'!S7:S16)>1,STDEV('Razões AuV'!S7:S16),"n.d.") -> 0 | E12: =IF(COUNT('Razões AuV'!T7:T16)>0,AVERAGE('Razões AuV'!T7:T16),"n.d.") -> 1 | F12: =IF(COUNT('Razões AuV'!T7:T16)>1,STDEV('Razões AuV'!T7:T16),"n.d.") -> 1.4802974e-16 | G12: ='Razões AuV'!S5 -> 1
A13: Zn | B13: =COUNT('Razões AuV'!U7:U16) -> 10 | C13: =IF(COUNT('Razões AuV'!U7:U16)>0,AVERAGE('Razões AuV'!U7:U16),"n.d.") -> 1 | D13: =IF(COUNT('Razões AuV'!U7:U16)>1,STDEV('Razões AuV'!U7:U16),"n.d.") -> 0 | E13: =IF(COUNT('Razões AuV'!V7:V16)>0,AVERAGE('Razões AuV'!V7:V16),"n.d.") -> 1 | F13: =IF(COUNT('Razões AuV'!V7:V16)>1,STDEV('Razões AuV'!V7:V16),"n.d.") -> 0 | G13: ='Razões AuV'!U5 -> 1
A14: Se | B14: =COUNT('Razões AuV'!W7:W16) -> 10 | C14: =IF(COUNT('Razões AuV'!W7:W16)>0,AVERAGE('Razões AuV'!W7:W16),"n.d.") -> 1 | D14: =IF(COUNT('Razões AuV'!W7:W16)>1,STDEV('Razões AuV'!W7:W16),"n.d.") -> 0 | E14: =IF(COUNT('Razões AuV'!X7:X16)>0,AVERAGE('Razões AuV'!X7:X16),"n.d.") -> 1 | F14: =IF(COUNT('Razões AuV'!X7:X16)>1,STDEV('Razões AuV'!X7:X16),"n.d.") -> 0 | G14: ='Razões AuV'!W5 -> 1
A15: Razão = valor da ferramenta / valor da planilha. Média e DP sobre as amostras R2–R11; n < 10 quando o elemento ficou abaixo do LD em alguma amostra. LD calculado a partir do padrão (Tomato Leaves, NIST SRM 1573a).

Sheet Tabela RhV
A1: Tabela — Razão entre os resultados da ferramenta computacional e da planilha eletrônica convencional (alvo Rh), amostras de raiz de cana-de-açúcar (n = 10).
A3: Elemento | B3: n | C3: Concentração média | D3: Concentração DP | E3: Incerteza média | F3: Incerteza DP | G3: LD
A4: P | B4: =COUNT('Razões RhV'!C7:C16) -> 10 | C4: =IF(COUNT('Razões RhV'!C7:C16)>0,AVERAGE('Razões RhV'!C7:C16),"n.d.") -> 1 | D4: =IF(COUNT('Razões RhV'!C7:C16)>1,STDEV('Razões RhV'!C7:C16),"n.d.") -> 0 | E4: =IF(COUNT('Razões RhV'!D7:D16)>0,AVERAGE('Razões RhV'!D7:D16),"n.d.") -> 1 | F4: =IF(COUNT('Razões RhV'!D7:D16)>1,STDEV('Razões RhV'!D7:D16),"n.d.") -> 0 | G4: ='Razões RhV'!C5 -> 1
A5: S | B5: =COUNT('Razões RhV'!E7:E16) -> 10 | C5: =IF(COUNT('Razões RhV'!E7:E16)>0,AVERAGE('Razões RhV'!E7:E16),"n.d.") -> 1 | D5: =IF(COUNT('Razões RhV'!E7:E16)>1,STDEV('Razões RhV'!E7:E16),"n.d.") -> 0 | E5: =IF(COUNT('Razões RhV'!F7:F16)>0,AVERAGE('Razões RhV'!F7:F16),"n.d.") -> 1 | F5: =IF(COUNT('Razões RhV'!F7:F16)>1,STDEV('Razões RhV'!F7:F16),"n.d.") -> 0 | G5: ='Razões RhV'!E5 -> 1
A6: Cl | B6: =COUNT('Razões RhV'!G7:G16) -> 10 | C6: =IF(COUNT('Razões RhV'!G7:G16)>0,AVERAGE('Razões RhV'!G7:G16),"n.d.") -> 1 | D6: =IF(COUNT('Razões RhV'!G7:G16)>1,STDEV('Razões RhV'!G7:G16),"n.d.") -> 0 | E6: =IF(COUNT('Razões RhV'!H7:H16)>0,AVERAGE('Razões RhV'!H7:H16),"n.d.") -> 1 | F6: =IF(COUNT('Razões RhV'!H7:H16)>1,STDEV('Razões RhV'!H7:H16),"n.d.") -> 0 | G6: ='Razões RhV'!G5 -> 1
A7: K | B7: =COUNT('Razões RhV'!I7:I16) -> 10 | C7: =IF(COUNT('Razões RhV'!I7:I16)>0,AVERAGE('Razões RhV'!I7:I16),"n.d.") -> 1 | D7: =IF(COUNT('Razões RhV'!I7:I16)>1,STDEV('Razões RhV'!I7:I16),"n.d.") -> 0 | E7: =IF(COUNT('Razões RhV'!J7:J16)>0,AVERAGE('Razões RhV'!J7:J16),"n.d.") -> 1 | F7: =IF(COUNT('Razões RhV'!J7:J16)>1,STDEV('Razões RhV'!J7:J16),"n.d.") -> 0 | G7: ='Razões RhV'!I5 -> 1
A8: Ca | B8: =COUNT('Razões RhV'!K7:K16) -> 10 | C8: =IF(COUNT('Razões RhV'!K7:K16)>0,AVERAGE('Razões RhV'!K7:K16),"n.d.") -> 1 | D8: =IF(COUNT('Razões RhV'!K7:K16)>1,STDEV('Razões RhV'!K7:K16),"n.d.") -> 0 | E8: =IF(COUNT('Razões RhV'!L7:L16)>0,AVERAGE('Razões RhV'!L7:L16),"n.d.") -> 1 | F8: =IF(COUNT('Razões RhV'!L7:L16)>1,STDEV('Razões RhV'!L7:L16),"n.d.") -> 0 | G8: ='Razões RhV'!K5 -> 1
A9: Cr | B9: =COUNT('Razões RhV'!M7:M16) -> 10 | C9: =IF(COUNT('Razões RhV'!M7:M16)>0,AVERAGE('Razões RhV'!M7:M16),"n.d.") -> 1 | D9: =IF(COUNT('Razões RhV'!M7:M16)>1,STDEV('Razões RhV'!M7:M16),"n.d.") -> 0 | E9: =IF(COUNT('Razões RhV'!N7:N16)>0,AVERAGE('Razões RhV'!N7:N16),"n.d.") -> 1 | F9: =IF(COUNT('Razões RhV'!N7:N16)>1,STDEV('Razões RhV'!N7:N16),"n.d.") -> 0 | G9: ='Razões RhV'!M5 -> 1
A10: Mn | B10: =COUNT('Razões RhV'!O7:O16) -> 10 | C10: =IF(COUNT('Razões RhV'!O7:O16)>0,AVERAGE('Razões RhV'!O7:O16),"n.d.") -> 1 | D10: =IF(COUNT('Razões RhV'!O7:O16)>1,STDEV('Razões RhV'!O7:O16),"n.d.") -> 0 | E10: =IF(COUNT('Razões RhV'!P7:P16)>0,AVERAGE('Razões RhV'!P7:P16),"n.d.") -> 1 | F10: =IF(COUNT('Razões RhV'!P7:P16)>1,STDEV('Razões RhV'!P7:P16),"n.d.") -> 0 | G10: ='Razões RhV'!O5 -> 1
A11: Fe | B11: =COUNT('Razões RhV'!Q7:Q16) -> 10 | C11: =IF(COUNT('Razões RhV'!Q7:Q16)>0,AVERAGE('Razões RhV'!Q7:Q16),"n.d.") -> 1 | D11: =IF(COUNT('Razões RhV'!Q7:Q16)>1,STDEV('Razões RhV'!Q7:Q16),"n.d.") -> 0 | E11: =IF(COUNT('Razões RhV'!R7:R16)>0,AVERAGE('Razões RhV'!R7:R16),"n.d.") -> 1 | F11: =IF(COUNT('Razões RhV'!R7:R16)>1,STDEV('Razões RhV'!R7:R16),"n.d.") -> 0 | G11: ='Razões RhV'!Q5 -> 1
A12: Ni | B12: =COUNT('Razões RhV'!S7:S16) -> 10 | C12: =IF(COUNT('Razões RhV'!S7:S16)>0,AVERAGE('Razões RhV'!S7:S16),"n.d.") -> 1 | D12: =IF(COUNT('Razões RhV'!S7:S16)>1,STDEV('Razões RhV'!S7:S16),"n.d.") -> 0 | E12: =IF(COUNT('Razões RhV'!T7:T16)>0,AVERAGE('Razões RhV'!T7:T16),"n.d.") -> 1 | F12: =IF(COUNT('Razões RhV'!T7:T16)>1,STDEV('Razões RhV'!T7:T16),"n.d.") -> 0 | G12: ='Razões RhV'!S5 -> 1
A13: Cu | B13: =COUNT('Razões RhV'!U7:U16) -> 7 | C13: =IF(COUNT('Razões RhV'!U7:U16)>0,AVERAGE('Razões RhV'!U7:U16),"n.d.") -> 1 | D13: =IF(COUNT('Razões RhV'!U7:U16)>1,STDEV('Razões RhV'!U7:U16),"n.d.") -> 0 | E13: =IF(COUNT('Razões RhV'!V7:V16)>0,AVERAGE('Razões RhV'!V7:V16),"n.d.") -> 1 | F13: =IF(COUNT('Razões RhV'!V7:V16)>1,STDEV('Razões RhV'!V7:V16),"n.d.") -> 0 | G13: ='Razões RhV'!U5 -> 1
A14: Zn | B14: =COUNT('Razões RhV'!W7:W16) -> 10 | C14: =IF(COUNT('Razões RhV'!W7:W16)>0,AVERAGE('Razões RhV'!W7:W16),"n.d.") -> 1 | D14: =IF(COUNT('Razões RhV'!W7:W16)>1,STDEV('Razões RhV'!W7:W16),"n.d.") -> 0 | E14: =IF(COUNT('Razões RhV'!X7:X16)>0,AVERAGE('Razões RhV'!X7:X16),"n.d.") -> 1 | F14: =IF(COUNT('Razões RhV'!X7:X16)>1,STDEV('Razões RhV'!X7:X16),"n.d.") -> 5.2336415e-17 | G14: ='Razões RhV'!W5 -> 1
A15: Razão = valor da ferramenta / valor da planilha. Média e DP sobre as amostras R2–R11; n < 10 quando o elemento ficou abaixo do LD em alguma amostra. LD calculado a partir do padrão (Tomato Leaves, NIST SRM 1573a).

Sheet Razões AgV
A1: Alvo AgV — razão Calculadora / Planilha convencional, por amostra
C3: P | E3: S | G3: Cl | I3: K | K3: Ca | M3: Cr | O3: Mn | Q3: Fe | S3: Ni | U3: Cu | W3: Zn | Y3: Br
A4: Medida | B4: Amostra | C4: C | D4: u | E4: C | F4: u | G4: C | H4: u | I4: C | J4: u | K4: C | L4: u | M4: C | N4: u | O4: C | P4: u | Q4: C | R4: u | S4: C | T4: u | U4: C | V4: u | W4: C | X4: u | Y4: C | Z4: u
A5: LD | C5: =IF(AND(ISNUMBER(Calc_AgV!C5),ISNUMBER(Conv_AgV!C5)),Calc_AgV!C5/Conv_AgV!C5,"n.d.") -> 1 | E5: =IF(AND(ISNUMBER(Calc_AgV!E5),ISNUMBER(Conv_AgV!E5)),Calc_AgV!E5/Conv_AgV!E5,"n.d.") -> 1 | G5: =IF(AND(ISNUMBER(Calc_AgV!G5),ISNUMBER(Conv_AgV!G5)),Calc_AgV!G5/Conv_AgV!G5,"n.d.") -> 1 | I5: =IF(AND(ISNUMBER(Calc_AgV!I5),ISNUMBER(Conv_AgV!I5)),Calc_AgV!I5/Conv_AgV!I5,"n.d.") -> 1 | K5: =IF(AND(ISNUMBER(Calc_AgV!K5),ISNUMBER(Conv_AgV!K5)),Calc_AgV!K5/Conv_AgV!K5,"n.d.") -> 1 | M5: =IF(AND(ISNUMBER(Calc_AgV!M5),ISNUMBER(Conv_AgV!M5)),Calc_AgV!M5/Conv_AgV!M5,"n.d.") -> 1 | O5: =IF(AND(ISNUMBER(Calc_AgV!O5),ISNUMBER(Conv_AgV!O5)),Calc_AgV!O5/Conv_AgV!O5,"n.d.") -> 1 | Q5: =IF(AND(ISNUMBER(Calc_AgV!Q5),ISNUMBER(Conv_AgV!Q5)),Calc_AgV!Q5/Conv_AgV!Q5,"n.d.") -> 1 | S5: =IF(AND(ISNUMBER(Calc_AgV!S5),ISNUMBER(Conv_AgV!S5)),Calc_AgV!S5/Conv_AgV!S5,"n.d.") -> 1 | U5: =IF(AND(ISNUMBER(Calc_AgV!U5),ISNUMBER(Conv_AgV!U5)),Calc_AgV!U5/Conv_AgV!U5,"n.d.") -> 1 | W5: =IF(AND(ISNUMBER(Calc_AgV!W5),ISNUMBER(Conv_AgV!W5)),Calc_AgV!W5/Conv_AgV!W5,"n.d.") -> 1 | Y5: =IF(AND(ISNUMBER(Calc_AgV!Y5),ISNUMBER(Conv_AgV!Y5)),Calc_AgV!Y5/Conv_AgV!Y5,"n.d.") -> 1
A6: =Calc_AgV!A6 -> ab | B6: =Calc_AgV!B6 -> Padrão (1573a) | C6: =IF(AND(ISNUMBER(Calc_AgV!C6),ISNUMBER(Conv_AgV!C6)),Calc_AgV!C6/Conv_AgV!C6,"n.d.") -> 1 | D6: =IF(AND(ISNUMBER(Calc_AgV!D6),ISNUMBER(Conv_AgV!D6)),Calc_AgV!D6/Conv_AgV!D6,"n.d.") -> 1 | E6: =IF(AND(ISNUMBER(Calc_AgV!E6),ISNUMBER(Conv_AgV!E6)),Calc_AgV!E6/Conv_AgV!E6,"n.d.") -> 1 | F6: =IF(AND(ISNUMBER(Calc_AgV!F6),ISNUMBER(Conv_AgV!F6)),Calc_AgV!F6/Conv_AgV!F6,"n.d.") -> 1 | G6: =IF(AND(ISNUMBER(Calc_AgV!G6),ISNUMBER(Conv_AgV!G6)),Calc_AgV!G6/Conv_AgV!G6,"n.d.") -> 1 | H6: =IF(AND(ISNUMBER(Calc_AgV!H6),ISNUMBER(Conv_AgV!H6)),Calc_AgV!H6/Conv_AgV!H6,"n.d.") -> 1 | I6: =IF(AND(ISNUMBER(Calc_AgV!I6),ISNUMBER(Conv_AgV!I6)),Calc_AgV!I6/Conv_AgV!I6,"n.d.") -> 1 | J6: =IF(AND(ISNUMBER(Calc_AgV!J6),ISNUMBER(Conv_AgV!J6)),Calc_AgV!J6/Conv_AgV!J6,"n.d.") -> 1 | ... Z6: =IF(AND(ISNUMBER(Calc_AgV!Z6),ISNUMBER(Conv_AgV!Z6)),Calc_AgV!Z6/Conv_AgV!Z6,"n.d.") -> 1
A7: =Calc_AgV!A7 -> ac | B7: =Calc_AgV!B7 -> R2 | C7: =IF(AND(ISNUMBER(Calc_AgV!C7),ISNUMBER(Conv_AgV!C7)),Calc_AgV!C7/Conv_AgV!C7,"n.d.") -> 1 | D7: =IF(AND(ISNUMBER(Calc_AgV!D7),ISNUMBER(Conv_AgV!D7)),Calc_AgV!D7/Conv_AgV!D7,"n.d.") -> 1 | E7: =IF(AND(ISNUMBER(Calc_AgV!E7),ISNUMBER(Conv_AgV!E7)),Calc_AgV!E7/Conv_AgV!E7,"n.d.") -> 1 | F7: =IF(AND(ISNUMBER(Calc_AgV!F7),ISNUMBER(Conv_AgV!F7)),Calc_AgV!F7/Conv_AgV!F7,"n.d.") -> 1 | G7: =IF(AND(ISNUMBER(Calc_AgV!G7),ISNUMBER(Conv_AgV!G7)),Calc_AgV!G7/Conv_AgV!G7,"n.d.") -> 1 | H7: =IF(AND(ISNUMBER(Calc_AgV!H7),ISNUMBER(Conv_AgV!H7)),Calc_AgV!H7/Conv_AgV!H7,"n.d.") -> 1 | I7: =IF(AND(ISNUMBER(Calc_AgV!I7),ISNUMBER(Conv_AgV!I7)),Calc_AgV!I7/Conv_AgV!I7,"n.d.") -> 1 | J7: =IF(AND(ISNUMBER(Calc_AgV!J7),ISNUMBER(Conv_AgV!J7)),Calc_AgV!J7/Conv_AgV!J7,"n.d.") -> 1 | ... Z7: =IF(AND(ISNUMBER(Calc_AgV!Z7),ISNUMBER(Conv_AgV!Z7)),Calc_AgV!Z7/Conv_AgV!Z7,"n.d.") -> 1
A8: =Calc_AgV!A8 -> ad | B8: =Calc_AgV!B8 -> R3 | C8: =IF(AND(ISNUMBER(Calc_AgV!C8),ISNUMBER(Conv_AgV!C8)),Calc_AgV!C8/Conv_AgV!C8,"n.d.") -> 1 | D8: =IF(AND(ISNUMBER(Calc_AgV!D8),ISNUMBER(Conv_AgV!D8)),Calc_AgV!D8/Conv_AgV!D8,"n.d.") -> 1 | E8: =IF(AND(ISNUMBER(Calc_AgV!E8),ISNUMBER(Conv_AgV!E8)),Calc_AgV!E8/Conv_AgV!E8,"n.d.") -> 1 | F8: =IF(AND(ISNUMBER(Calc_AgV!F8),ISNUMBER(Conv_AgV!F8)),Calc_AgV!F8/Conv_AgV!F8,"n.d.") -> 1 | G8: =IF(AND(ISNUMBER(Calc_AgV!G8),ISNUMBER(Conv_AgV!G8)),Calc_AgV!G8/Conv_AgV!G8,"n.d.") -> 1 | H8: =IF(AND(ISNUMBER(Calc_AgV!H8),ISNUMBER(Conv_AgV!H8)),Calc_AgV!H8/Conv_AgV!H8,"n.d.") -> 1 | I8: =IF(AND(ISNUMBER(Calc_AgV!I8),ISNUMBER(Conv_AgV!I8)),Calc_AgV!I8/Conv_AgV!I8,"n.d.") -> 1 | J8: =IF(AND(ISNUMBER(Calc_AgV!J8),ISNUMBER(Conv_AgV!J8)),Calc_AgV!J8/Conv_AgV!J8,"n.d.") -> 1 | ... Z8: =IF(AND(ISNUMBER(Calc_AgV!Z8),ISNUMBER(Conv_AgV!Z8)),Calc_AgV!Z8/Conv_AgV!Z8,"n.d.") -> n.d.
A9: =Calc_AgV!A9 -> ae | B9: =Calc_AgV!B9 -> R4 | C9: =IF(AND(ISNUMBER(Calc_AgV!C9),ISNUMBER(Conv_AgV!C9)),Calc_AgV!C9/Conv_AgV!C9,"n.d.") -> 1 | D9: =IF(AND(ISNUMBER(Calc_AgV!D9),ISNUMBER(Conv_AgV!D9)),Calc_AgV!D9/Conv_AgV!D9,"n.d.") -> 1 | E9: =IF(AND(ISNUMBER(Calc_AgV!E9),ISNUMBER(Conv_AgV!E9)),Calc_AgV!E9/Conv_AgV!E9,"n.d.") -> 1 | F9: =IF(AND(ISNUMBER(Calc_AgV!F9),ISNUMBER(Conv_AgV!F9)),Calc_AgV!F9/Conv_AgV!F9,"n.d.") -> 1 | G9: =IF(AND(ISNUMBER(Calc_AgV!G9),ISNUMBER(Conv_AgV!G9)),Calc_AgV!G9/Conv_AgV!G9,"n.d.") -> 1 | H9: =IF(AND(ISNUMBER(Calc_AgV!H9),ISNUMBER(Conv_AgV!H9)),Calc_AgV!H9/Conv_AgV!H9,"n.d.") -> 1 | I9: =IF(AND(ISNUMBER(Calc_AgV!I9),ISNUMBER(Conv_AgV!I9)),Calc_AgV!I9/Conv_AgV!I9,"n.d.") -> 1 | J9: =IF(AND(ISNUMBER(Calc_AgV!J9),ISNUMBER(Conv_AgV!J9)),Calc_AgV!J9/Conv_AgV!J9,"n.d.") -> 1 | ... Z9: =IF(AND(ISNUMBER(Calc_AgV!Z9),ISNUMBER(Conv_AgV!Z9)),Calc_AgV!Z9/Conv_AgV!Z9,"n.d.") -> 1
A10: =Calc_AgV!A10 -> af | B10: =Calc_AgV!B10 -> R5 | C10: =IF(AND(ISNUMBER(Calc_AgV!C10),ISNUMBER(Conv_AgV!C10)),Calc_AgV!C10/Conv_AgV!C10,"n.d.") -> 1 | D10: =IF(AND(ISNUMBER(Calc_AgV!D10),ISNUMBER(Conv_AgV!D10)),Calc_AgV!D10/Conv_AgV!D10,"n.d.") -> 1 | E10: =IF(AND(ISNUMBER(Calc_AgV!E10),ISNUMBER(Conv_AgV!E10)),Calc_AgV!E10/Conv_AgV!E10,"n.d.") -> 1 | F10: =IF(AND(ISNUMBER(Calc_AgV!F10),ISNUMBER(Conv_AgV!F10)),Calc_AgV!F10/Conv_AgV!F10,"n.d.") -> 1 | G10: =IF(AND(ISNUMBER(Calc_AgV!G10),ISNUMBER(Conv_AgV!G10)),Calc_AgV!G10/Conv_AgV!G10,"n.d.") -> 1 | H10: =IF(AND(ISNUMBER(Calc_AgV!H10),ISNUMBER(Conv_AgV!H10)),Calc_AgV!H10/Conv_AgV!H10,"n.d.") -> 1 | I10: =IF(AND(ISNUMBER(Calc_AgV!I10),ISNUMBER(Conv_AgV!I10)),Calc_AgV!I10/Conv_AgV!I10,"n.d.") -> 1 | J10: =IF(AND(ISNUMBER(Calc_AgV!J10),ISNUMBER(Conv_AgV!J10)),Calc_AgV!J10/Conv_AgV!J10,"n.d.") -> 1 | ... Z10: =IF(AND(ISNUMBER(Calc_AgV!Z10),ISNUMBER(Conv_AgV!Z10)),Calc_AgV!Z10/Conv_AgV!Z10,"n.d.") -> 1
A11: =Calc_AgV!A11 -> ag | B11: =Calc_AgV!B11 -> R6 | C11: =IF(AND(ISNUMBER(Calc_AgV!C11),ISNUMBER(Conv_AgV!C11)),Calc_AgV!C11/Conv_AgV!C11,"n.d.") -> 1 | D11: =IF(AND(ISNUMBER(Calc_AgV!D11),ISNUMBER(Conv_AgV!D11)),Calc_AgV!D11/Conv_AgV!D11,"n.d.") -> 1 | E11: =IF(AND(ISNUMBER(Calc_AgV!E11),ISNUMBER(Conv_AgV!E11)),Calc_AgV!E11/Conv_AgV!E11,"n.d.") -> 1 | F11: =IF(AND(ISNUMBER(Calc_AgV!F11),ISNUMBER(Conv_AgV!F11)),Calc_AgV!F11/Conv_AgV!F11,"n.d.") -> 1 | G11: =IF(AND(ISNUMBER(Calc_AgV!G11),ISNUMBER(Conv_AgV!G11)),Calc_AgV!G11/Conv_AgV!G11,"n.d.") -> 1 | H11: =IF(AND(ISNUMBER(Calc_AgV!H11),ISNUMBER(Conv_AgV!H11)),Calc_AgV!H11/Conv_AgV!H11,"n.d.") -> 1 | I11: =IF(AND(ISNUMBER(Calc_AgV!I11),ISNUMBER(Conv_AgV!I11)),Calc_AgV!I11/Conv_AgV!I11,"n.d.") -> 1 | J11: =IF(AND(ISNUMBER(Calc_AgV!J11),ISNUMBER(Conv_AgV!J11)),Calc_AgV!J11/Conv_AgV!J11,"n.d.") -> 1 | ... Z11: =IF(AND(ISNUMBER(Calc_AgV!Z11),ISNUMBER(Conv_AgV!Z11)),Calc_AgV!Z11/Conv_AgV!Z11,"n.d.") -> 1
A12: =Calc_AgV!A12 -> ah | B12: =Calc_AgV!B12 -> R7 | C12: =IF(AND(ISNUMBER(Calc_AgV!C12),ISNUMBER(Conv_AgV!C12)),Calc_AgV!C12/Conv_AgV!C12,"n.d.") -> 1 | D12: =IF(AND(ISNUMBER(Calc_AgV!D12),ISNUMBER(Conv_AgV!D12)),Calc_AgV!D12/Conv_AgV!D12,"n.d.") -> 1 | E12: =IF(AND(ISNUMBER(Calc_AgV!E12),ISNUMBER(Conv_AgV!E12)),Calc_AgV!E12/Conv_AgV!E12,"n.d.") -> 1 | F12: =IF(AND(ISNUMBER(Calc_AgV!F12),ISNUMBER(Conv_AgV!F12)),Calc_AgV!F12/Conv_AgV!F12,"n.d.") -> 1 | G12: =IF(AND(ISNUMBER(Calc_AgV!G12),ISNUMBER(Conv_AgV!G12)),Calc_AgV!G12/Conv_AgV!G12,"n.d.") -> 1 | H12: =IF(AND(ISNUMBER(Calc_AgV!H12),ISNUMBER(Conv_AgV!H12)),Calc_AgV!H12/Conv_AgV!H12,"n.d.") -> 1 | I12: =IF(AND(ISNUMBER(Calc_AgV!I12),ISNUMBER(Conv_AgV!I12)),Calc_AgV!I12/Conv_AgV!I12,"n.d.") -> 1 | J12: =IF(AND(ISNUMBER(Calc_AgV!J12),ISNUMBER(Conv_AgV!J12)),Calc_AgV!J12/Conv_AgV!J12,"n.d.") -> 1 | ... Z12: =IF(AND(ISNUMBER(Calc_AgV!Z12),ISNUMBER(Conv_AgV!Z12)),Calc_AgV!Z12/Conv_AgV!Z12,"n.d.") -> 1
A13: =Calc_AgV!A13 -> ai | B13: =Calc_AgV!B13 -> R8 | C13: =IF(AND(ISNUMBER(Calc_AgV!C13),ISNUMBER(Conv_AgV!C13)),Calc_AgV!C13/Conv_AgV!C13,"n.d.") -> 1 | D13: =IF(AND(ISNUMBER(Calc_AgV!D13),ISNUMBER(Conv_AgV!D13)),Calc_AgV!D13/Conv_AgV!D13,"n.d.") -> 1 | E13: =IF(AND(ISNUMBER(Calc_AgV!E13),ISNUMBER(Conv_AgV!E13)),Calc_AgV!E13/Conv_AgV!E13,"n.d.") -> 1 | F13: =IF(AND(ISNUMBER(Calc_AgV!F13),ISNUMBER(Conv_AgV!F13)),Calc_AgV!F13/Conv_AgV!F13,"n.d.") -> 1 | G13: =IF(AND(ISNUMBER(Calc_AgV!G13),ISNUMBER(Conv_AgV!G13)),Calc_AgV!G13/Conv_AgV!G13,"n.d.") -> 1 | H13: =IF(AND(ISNUMBER(Calc_AgV!H13),ISNUMBER(Conv_AgV!H13)),Calc_AgV!H13/Conv_AgV!H13,"n.d.") -> 1 | I13: =IF(AND(ISNUMBER(Calc_AgV!I13),ISNUMBER(Conv_AgV!I13)),Calc_AgV!I13/Conv_AgV!I13,"n.d.") -> 1 | J13: =IF(AND(ISNUMBER(Calc_AgV!J13),ISNUMBER(Conv_AgV!J13)),Calc_AgV!J13/Conv_AgV!J13,"n.d.") -> 1 | ... Z13: =IF(AND(ISNUMBER(Calc_AgV!Z13),ISNUMBER(Conv_AgV!Z13)),Calc_AgV!Z13/Conv_AgV!Z13,"n.d.") -> 1
A14: =Calc_AgV!A14 -> aj | B14: =Calc_AgV!B14 -> R9 | C14: =IF(AND(ISNUMBER(Calc_AgV!C14),ISNUMBER(Conv_AgV!C14)),Calc_AgV!C14/Conv_AgV!C14,"n.d.") -> 1 | D14: =IF(AND(ISNUMBER(Calc_AgV!D14),ISNUMBER(Conv_AgV!D14)),Calc_AgV!D14/Conv_AgV!D14,"n.d.") -> 1 | E14: =IF(AND(ISNUMBER(Calc_AgV!E14),ISNUMBER(Conv_AgV!E14)),Calc_AgV!E14/Conv_AgV!E14,"n.d.") -> 1 | F14: =IF(AND(ISNUMBER(Calc_AgV!F14),ISNUMBER(Conv_AgV!F14)),Calc_AgV!F14/Conv_AgV!F14,"n.d.") -> 1 | G14: =IF(AND(ISNUMBER(Calc_AgV!G14),ISNUMBER(Conv_AgV!G14)),Calc_AgV!G14/Conv_AgV!G14,"n.d.") -> 1 | H14: =IF(AND(ISNUMBER(Calc_AgV!H14),ISNUMBER(Conv_AgV!H14)),Calc_AgV!H14/Conv_AgV!H14,"n.d.") -> 1 | I14: =IF(AND(ISNUMBER(Calc_AgV!I14),ISNUMBER(Conv_AgV!I14)),Calc_AgV!I14/Conv_AgV!I14,"n.d.") -> 1 | J14: =IF(AND(ISNUMBER(Calc_AgV!J14),ISNUMBER(Conv_AgV!J14)),Calc_AgV!J14/Conv_AgV!J14,"n.d.") -> 1 | ... Z14: =IF(AND(ISNUMBER(Calc_AgV!Z14),ISNUMBER(Conv_AgV!Z14)),Calc_AgV!Z14/Conv_AgV!Z14,"n.d.") -> 1
A15: =Calc_AgV!A15 -> ak | B15: =Calc_AgV!B15 -> R10 | C15: =IF(AND(ISNUMBER(Calc_AgV!C15),ISNUMBER(Conv_AgV!C15)),Calc_AgV!C15/Conv_AgV!C15,"n.d.") -> 1 | D15: =IF(AND(ISNUMBER(Calc_AgV!D15),ISNUMBER(Conv_AgV!D15)),Calc_AgV!D15/Conv_AgV!D15,"n.d.") -> 1 | E15: =IF(AND(ISNUMBER(Calc_AgV!E15),ISNUMBER(Conv_AgV!E15)),Calc_AgV!E15/Conv_AgV!E15,"n.d.") -> 1 | F15: =IF(AND(ISNUMBER(Calc_AgV!F15),ISNUMBER(Conv_AgV!F15)),Calc_AgV!F15/Conv_AgV!F15,"n.d.") -> 1 | G15: =IF(AND(ISNUMBER(Calc_AgV!G15),ISNUMBER(Conv_AgV!G15)),Calc_AgV!G15/Conv_AgV!G15,"n.d.") -> 1 | H15: =IF(AND(ISNUMBER(Calc_AgV!H15),ISNUMBER(Conv_AgV!H15)),Calc_AgV!H15/Conv_AgV!H15,"n.d.") -> 1 | I15: =IF(AND(ISNUMBER(Calc_AgV!I15),ISNUMBER(Conv_AgV!I15)),Calc_AgV!I15/Conv_AgV!I15,"n.d.") -> 1 | J15: =IF(AND(ISNUMBER(Calc_AgV!J15),ISNUMBER(Conv_AgV!J15)),Calc_AgV!J15/Conv_AgV!J15,"n.d.") -> 1 | ... Z15: =IF(AND(ISNUMBER(Calc_AgV!Z15),ISNUMBER(Conv_AgV!Z15)),Calc_AgV!Z15/Conv_AgV!Z15,"n.d.") -> 1
A16: =Calc_AgV!A16 -> al | B16: =Calc_AgV!B16 -> R11 | C16: =IF(AND(ISNUMBER(Calc_AgV!C16),ISNUMBER(Conv_AgV!C16)),Calc_AgV!C16/Conv_AgV!C16,"n.d.") -> 1 | D16: =IF(AND(ISNUMBER(Calc_AgV!D16),ISNUMBER(Conv_AgV!D16)),Calc_AgV!D16/Conv_AgV!D16,"n.d.") -> 1 | E16: =IF(AND(ISNUMBER(Calc_AgV!E16),ISNUMBER(Conv_AgV!E16)),Calc_AgV!E16/Conv_AgV!E16,"n.d.") -> 1 | F16: =IF(AND(ISNUMBER(Calc_AgV!F16),ISNUMBER(Conv_AgV!F16)),Calc_AgV!F16/Conv_AgV!F16,"n.d.") -> 1 | G16: =IF(AND(ISNUMBER(Calc_AgV!G16),ISNUMBER(Conv_AgV!G16)),Calc_AgV!G16/Conv_AgV!G16,"n.d.") -> 1 | H16: =IF(AND(ISNUMBER(Calc_AgV!H16),ISNUMBER(Conv_AgV!H16)),Calc_AgV!H16/Conv_AgV!H16,"n.d.") -> 1 | I16: =IF(AND(ISNUMBER(Calc_AgV!I16),ISNUMBER(Conv_AgV!I16)),Calc_AgV!I16/Conv_AgV!I16,"n.d.") -> 1 | J16: =IF(AND(ISNUMBER(Calc_AgV!J16),ISNUMBER(Conv_AgV!J16)),Calc_AgV!J16/Conv_AgV!J16,"n.d.") -> 1 | ... Z16: =IF(AND(ISNUMBER(Calc_AgV!Z16),ISNUMBER(Conv_AgV!Z16)),Calc_AgV!Z16/Conv_AgV!Z16,"n.d.") -> 1

Sheet Razões AuV
A1: Alvo AuV — razão Calculadora / Planilha convencional, por amostra
C3: S | E3: Cl | G3: K | I3: Ca | K3: Cr | M3: Mn | O3: Fe | Q3: Ni | S3: Cu | U3: Zn | W3: Se
A4: Medida | B4: Amostra | C4: C | D4: u | E4: C | F4: u | G4: C | H4: u | I4: C | J4: u | K4: C | L4: u | M4: C | N4: u | O4: C | P4: u | Q4: C | R4: u | S4: C | T4: u | U4: C | V4: u | W4: C | X4: u
A5: LD | C5: =IF(AND(ISNUMBER(Calc_AuV!C5),ISNUMBER(Conv_AuV!C5)),Calc_AuV!C5/Conv_AuV!C5,"n.d.") -> 1 | E5: =IF(AND(ISNUMBER(Calc_AuV!E5),ISNUMBER(Conv_AuV!E5)),Calc_AuV!E5/Conv_AuV!E5,"n.d.") -> 1 | G5: =IF(AND(ISNUMBER(Calc_AuV!G5),ISNUMBER(Conv_AuV!G5)),Calc_AuV!G5/Conv_AuV!G5,"n.d.") -> 1 | I5: =IF(AND(ISNUMBER(Calc_AuV!I5),ISNUMBER(Conv_AuV!I5)),Calc_AuV!I5/Conv_AuV!I5,"n.d.") -> 1 | K5: =IF(AND(ISNUMBER(Calc_AuV!K5),ISNUMBER(Conv_AuV!K5)),Calc_AuV!K5/Conv_AuV!K5,"n.d.") -> 1 | M5: =IF(AND(ISNUMBER(Calc_AuV!M5),ISNUMBER(Conv_AuV!M5)),Calc_AuV!M5/Conv_AuV!M5,"n.d.") -> 1 | O5: =IF(AND(ISNUMBER(Calc_AuV!O5),ISNUMBER(Conv_AuV!O5)),Calc_AuV!O5/Conv_AuV!O5,"n.d.") -> 1 | Q5: =IF(AND(ISNUMBER(Calc_AuV!Q5),ISNUMBER(Conv_AuV!Q5)),Calc_AuV!Q5/Conv_AuV!Q5,"n.d.") -> 1 | S5: =IF(AND(ISNUMBER(Calc_AuV!S5),ISNUMBER(Conv_AuV!S5)),Calc_AuV!S5/Conv_AuV!S5,"n.d.") -> 1 | U5: =IF(AND(ISNUMBER(Calc_AuV!U5),ISNUMBER(Conv_AuV!U5)),Calc_AuV!U5/Conv_AuV!U5,"n.d.") -> 1 | W5: =IF(AND(ISNUMBER(Calc_AuV!W5),ISNUMBER(Conv_AuV!W5)),Calc_AuV!W5/Conv_AuV!W5,"n.d.") -> 1
A6: =Calc_AuV!A6 -> ab | B6: =Calc_AuV!B6 -> Padrão (1573a) | C6: =IF(AND(ISNUMBER(Calc_AuV!C6),ISNUMBER(Conv_AuV!C6)),Calc_AuV!C6/Conv_AuV!C6,"n.d.") -> 1 | D6: =IF(AND(ISNUMBER(Calc_AuV!D6),ISNUMBER(Conv_AuV!D6)),Calc_AuV!D6/Conv_AuV!D6,"n.d.") -> 1 | E6: =IF(AND(ISNUMBER(Calc_AuV!E6),ISNUMBER(Conv_AuV!E6)),Calc_AuV!E6/Conv_AuV!E6,"n.d.") -> 1 | F6: =IF(AND(ISNUMBER(Calc_AuV!F6),ISNUMBER(Conv_AuV!F6)),Calc_AuV!F6/Conv_AuV!F6,"n.d.") -> 1 | G6: =IF(AND(ISNUMBER(Calc_AuV!G6),ISNUMBER(Conv_AuV!G6)),Calc_AuV!G6/Conv_AuV!G6,"n.d.") -> 1 | H6: =IF(AND(ISNUMBER(Calc_AuV!H6),ISNUMBER(Conv_AuV!H6)),Calc_AuV!H6/Conv_AuV!H6,"n.d.") -> 1 | I6: =IF(AND(ISNUMBER(Calc_AuV!I6),ISNUMBER(Conv_AuV!I6)),Calc_AuV!I6/Conv_AuV!I6,"n.d.") -> 1 | J6: =IF(AND(ISNUMBER(Calc_AuV!J6),ISNUMBER(Conv_AuV!J6)),Calc_AuV!J6/Conv_AuV!J6,"n.d.") -> 1 | ... X6: =IF(AND(ISNUMBER(Calc_AuV!X6),ISNUMBER(Conv_AuV!X6)),Calc_AuV!X6/Conv_AuV!X6,"n.d.") -> 1
A7: =Calc_AuV!A7 -> ac | B7: =Calc_AuV!B7 -> R2 | C7: =IF(AND(ISNUMBER(Calc_AuV!C7),ISNUMBER(Conv_AuV!C7)),Calc_AuV!C7/Conv_AuV!C7,"n.d.") -> 1 | D7: =IF(AND(ISNUMBER(Calc_AuV!D7),ISNUMBER(Conv_AuV!D7)),Calc_AuV!D7/Conv_AuV!D7,"n.d.") -> 1 | E7: =IF(AND(ISNUMBER(Calc_AuV!E7),ISNUMBER(Conv_AuV!E7)),Calc_AuV!E7/Conv_AuV!E7,"n.d.") -> 1 | F7: =IF(AND(ISNUMBER(Calc_AuV!F7),ISNUMBER(Conv_AuV!F7)),Calc_AuV!F7/Conv_AuV!F7,"n.d.") -> 1 | G7: =IF(AND(ISNUMBER(Calc_AuV!G7),ISNUMBER(Conv_AuV!G7)),Calc_AuV!G7/Conv_AuV!G7,"n.d.") -> 1 | H7: =IF(AND(ISNUMBER(Calc_AuV!H7),ISNUMBER(Conv_AuV!H7)),Calc_AuV!H7/Conv_AuV!H7,"n.d.") -> 1 | I7: =IF(AND(ISNUMBER(Calc_AuV!I7),ISNUMBER(Conv_AuV!I7)),Calc_AuV!I7/Conv_AuV!I7,"n.d.") -> 1 | J7: =IF(AND(ISNUMBER(Calc_AuV!J7),ISNUMBER(Conv_AuV!J7)),Calc_AuV!J7/Conv_AuV!J7,"n.d.") -> 1 | ... X7: =IF(AND(ISNUMBER(Calc_AuV!X7),ISNUMBER(Conv_AuV!X7)),Calc_AuV!X7/Conv_AuV!X7,"n.d.") -> 1
A8: =Calc_AuV!A8 -> ad | B8: =Calc_AuV!B8 -> R3 | C8: =IF(AND(ISNUMBER(Calc_AuV!C8),ISNUMBER(Conv_AuV!C8)),Calc_AuV!C8/Conv_AuV!C8,"n.d.") -> 1 | D8: =IF(AND(ISNUMBER(Calc_AuV!D8),ISNUMBER(Conv_AuV!D8)),Calc_AuV!D8/Conv_AuV!D8,"n.d.") -> 1 | E8: =IF(AND(ISNUMBER(Calc_AuV!E8),ISNUMBER(Conv_AuV!E8)),Calc_AuV!E8/Conv_AuV!E8,"n.d.") -> 1 | F8: =IF(AND(ISNUMBER(Calc_AuV!F8),ISNUMBER(Conv_AuV!F8)),Calc_AuV!F8/Conv_AuV!F8,"n.d.") -> 1 | G8: =IF(AND(ISNUMBER(Calc_AuV!G8),ISNUMBER(Conv_AuV!G8)),Calc_AuV!G8/Conv_AuV!G8,"n.d.") -> 1 | H8: =IF(AND(ISNUMBER(Calc_AuV!H8),ISNUMBER(Conv_AuV!H8)),Calc_AuV!H8/Conv_AuV!H8,"n.d.") -> 1 | I8: =IF(AND(ISNUMBER(Calc_AuV!I8),ISNUMBER(Conv_AuV!I8)),Calc_AuV!I8/Conv_AuV!I8,"n.d.") -> 1 | J8: =IF(AND(ISNUMBER(Calc_AuV!J8),ISNUMBER(Conv_AuV!J8)),Calc_AuV!J8/Conv_AuV!J8,"n.d.") -> 1 | ... X8: =IF(AND(ISNUMBER(Calc_AuV!X8),ISNUMBER(Conv_AuV!X8)),Calc_AuV!X8/Conv_AuV!X8,"n.d.") -> 1
A9: =Calc_AuV!A9 -> ae | B9: =Calc_AuV!B9 -> R4 | C9: =IF(AND(ISNUMBER(Calc_AuV!C9),ISNUMBER(Conv_AuV!C9)),Calc_AuV!C9/Conv_AuV!C9,"n.d.") -> 1 | D9: =IF(AND(ISNUMBER(Calc_AuV!D9),ISNUMBER(Conv_AuV!D9)),Calc_AuV!D9/Conv_AuV!D9,"n.d.") -> 1 | E9: =IF(AND(ISNUMBER(Calc_AuV!E9),ISNUMBER(Conv_AuV!E9)),Calc_AuV!E9/Conv_AuV!E9,"n.d.") -> 1 | F9: =IF(AND(ISNUMBER(Calc_AuV!F9),ISNUMBER(Conv_AuV!F9)),Calc_AuV!F9/Conv_AuV!F9,"n.d.") -> 1 | G9: =IF(AND(ISNUMBER(Calc_AuV!G9),ISNUMBER(Conv_AuV!G9)),Calc_AuV!G9/Conv_AuV!G9,"n.d.") -> 1 | H9: =IF(AND(ISNUMBER(Calc_AuV!H9),ISNUMBER(Conv_AuV!H9)),Calc_AuV!H9/Conv_AuV!H9,"n.d.") -> 1 | I9: =IF(AND(ISNUMBER(Calc_AuV!I9),ISNUMBER(Conv_AuV!I9)),Calc_AuV!I9/Conv_AuV!I9,"n.d.") -> 1 | J9: =IF(AND(ISNUMBER(Calc_AuV!J9),ISNUMBER(Conv_AuV!J9)),Calc_AuV!J9/Conv_AuV!J9,"n.d.") -> 1 | ... X9: =IF(AND(ISNUMBER(Calc_AuV!X9),ISNUMBER(Conv_AuV!X9)),Calc_AuV!X9/Conv_AuV!X9,"n.d.") -> 1
A10: =Calc_AuV!A10 -> af | B10: =Calc_AuV!B10 -> R5 | C10: =IF(AND(ISNUMBER(Calc_AuV!C10),ISNUMBER(Conv_AuV!C10)),Calc_AuV!C10/Conv_AuV!C10,"n.d.") -> 1 | D10: =IF(AND(ISNUMBER(Calc_AuV!D10),ISNUMBER(Conv_AuV!D10)),Calc_AuV!D10/Conv_AuV!D10,"n.d.") -> 1 | E10: =IF(AND(ISNUMBER(Calc_AuV!E10),ISNUMBER(Conv_AuV!E10)),Calc_AuV!E10/Conv_AuV!E10,"n.d.") -> 1 | F10: =IF(AND(ISNUMBER(Calc_AuV!F10),ISNUMBER(Conv_AuV!F10)),Calc_AuV!F10/Conv_AuV!F10,"n.d.") -> 1 | G10: =IF(AND(ISNUMBER(Calc_AuV!G10),ISNUMBER(Conv_AuV!G10)),Calc_AuV!G10/Conv_AuV!G10,"n.d.") -> 1 | H10: =IF(AND(ISNUMBER(Calc_AuV!H10),ISNUMBER(Conv_AuV!H10)),Calc_AuV!H10/Conv_AuV!H10,"n.d.") -> 1 | I10: =IF(AND(ISNUMBER(Calc_AuV!I10),ISNUMBER(Conv_AuV!I10)),Calc_AuV!I10/Conv_AuV!I10,"n.d.") -> 1 | J10: =IF(AND(ISNUMBER(Calc_AuV!J10),ISNUMBER(Conv_AuV!J10)),Calc_AuV!J10/Conv_AuV!J10,"n.d.") -> 1 | ... X10: =IF(AND(ISNUMBER(Calc_AuV!X10),ISNUMBER(Conv_AuV!X10)),Calc_AuV!X10/Conv_AuV!X10,"n.d.") -> 1
A11: =Calc_AuV!A11 -> ag | B11: =Calc_AuV!B11 -> R6 | C11: =IF(AND(ISNUMBER(Calc_AuV!C11),ISNUMBER(Conv_AuV!C11)),Calc_AuV!C11/Conv_AuV!C11,"n.d.") -> 1 | D11: =IF(AND(ISNUMBER(Calc_AuV!D11),ISNUMBER(Conv_AuV!D11)),Calc_AuV!D11/Conv_AuV!D11,"n.d.") -> 1 | E11: =IF(AND(ISNUMBER(Calc_AuV!E11),ISNUMBER(Conv_AuV!E11)),Calc_AuV!E11/Conv_AuV!E11,"n.d.") -> 1 | F11: =IF(AND(ISNUMBER(Calc_AuV!F11),ISNUMBER(Conv_AuV!F11)),Calc_AuV!F11/Conv_AuV!F11,"n.d.") -> 1 | G11: =IF(AND(ISNUMBER(Calc_AuV!G11),ISNUMBER(Conv_AuV!G11)),Calc_AuV!G11/Conv_AuV!G11,"n.d.") -> 1 | H11: =IF(AND(ISNUMBER(Calc_AuV!H11),ISNUMBER(Conv_AuV!H11)),Calc_AuV!H11/Conv_AuV!H11,"n.d.") -> 1 | I11: =IF(AND(ISNUMBER(Calc_AuV!I11),ISNUMBER(Conv_AuV!I11)),Calc_AuV!I11/Conv_AuV!I11,"n.d.") -> 1 | J11: =IF(AND(ISNUMBER(Calc_AuV!J11),ISNUMBER(Conv_AuV!J11)),Calc_AuV!J11/Conv_AuV!J11,"n.d.") -> 1 | ... X11: =IF(AND(ISNUMBER(Calc_AuV!X11),ISNUMBER(Conv_AuV!X11)),Calc_AuV!X11/Conv_AuV!X11,"n.d.") -> 1
A12: =Calc_AuV!A12 -> ah | B12: =Calc_AuV!B12 -> R7 | C12: =IF(AND(ISNUMBER(Calc_AuV!C12),ISNUMBER(Conv_AuV!C12)),Calc_AuV!C12/Conv_AuV!C12,"n.d.") -> 1 | D12: =IF(AND(ISNUMBER(Calc_AuV!D12),ISNUMBER(Conv_AuV!D12)),Calc_AuV!D12/Conv_AuV!D12,"n.d.") -> 1 | E12: =IF(AND(ISNUMBER(Calc_AuV!E12),ISNUMBER(Conv_AuV!E12)),Calc_AuV!E12/Conv_AuV!E12,"n.d.") -> 1 | F12: =IF(AND(ISNUMBER(Calc_AuV!F12),ISNUMBER(Conv_AuV!F12)),Calc_AuV!F12/Conv_AuV!F12,"n.d.") -> 1 | G12: =IF(AND(ISNUMBER(Calc_AuV!G12),ISNUMBER(Conv_AuV!G12)),Calc_AuV!G12/Conv_AuV!G12,"n.d.") -> 1 | H12: =IF(AND(ISNUMBER(Calc_AuV!H12),ISNUMBER(Conv_AuV!H12)),Calc_AuV!H12/Conv_AuV!H12,"n.d.") -> 1 | I12: =IF(AND(ISNUMBER(Calc_AuV!I12),ISNUMBER(Conv_AuV!I12)),Calc_AuV!I12/Conv_AuV!I12,"n.d.") -> 1 | J12: =IF(AND(ISNUMBER(Calc_AuV!J12),ISNUMBER(Conv_AuV!J12)),Calc_AuV!J12/Conv_AuV!J12,"n.d.") -> 1 | ... X12: =IF(AND(ISNUMBER(Calc_AuV!X12),ISNUMBER(Conv_AuV!X12)),Calc_AuV!X12/Conv_AuV!X12,"n.d.") -> 1
A13: =Calc_AuV!A13 -> ai | B13: =Calc_AuV!B13 -> R8 | C13: =IF(AND(ISNUMBER(Calc_AuV!C13),ISNUMBER(Conv_AuV!C13)),Calc_AuV!C13/Conv_AuV!C13,"n.d.") -> 1 | D13: =IF(AND(ISNUMBER(Calc_AuV!D13),ISNUMBER(Conv_AuV!D13)),Calc_AuV!D13/Conv_AuV!D13,"n.d.") -> 1 | E13: =IF(AND(ISNUMBER(Calc_AuV!E13),ISNUMBER(Conv_AuV!E13)),Calc_AuV!E13/Conv_AuV!E13,"n.d.") -> 1 | F13: =IF(AND(ISNUMBER(Calc_AuV!F13),ISNUMBER(Conv_AuV!F13)),Calc_AuV!F13/Conv_AuV!F13,"n.d.") -> 1 | G13: =IF(AND(ISNUMBER(Calc_AuV!G13),ISNUMBER(Conv_AuV!G13)),Calc_AuV!G13/Conv_AuV!G13,"n.d.") -> 1 | H13: =IF(AND(ISNUMBER(Calc_AuV!H13),ISNUMBER(Conv_AuV!H13)),Calc_AuV!H13/Conv_AuV!H13,"n.d.") -> 1 | I13: =IF(AND(ISNUMBER(Calc_AuV!I13),ISNUMBER(Conv_AuV!I13)),Calc_AuV!I13/Conv_AuV!I13,"n.d.") -> 1 | J13: =IF(AND(ISNUMBER(Calc_AuV!J13),ISNUMBER(Conv_AuV!J13)),Calc_AuV!J13/Conv_AuV!J13,"n.d.") -> 1 | ... X13: =IF(AND(ISNUMBER(Calc_AuV!X13),ISNUMBER(Conv_AuV!X13)),Calc_AuV!X13/Conv_AuV!X13,"n.d.") -> 1
A14: =Calc_AuV!A14 -> aj | B14: =Calc_AuV!B14 -> R9 | C14: =IF(AND(ISNUMBER(Calc_AuV!C14),ISNUMBER(Conv_AuV!C14)),Calc_AuV!C14/Conv_AuV!C14,"n.d.") -> 1 | D14: =IF(AND(ISNUMBER(Calc_AuV!D14),ISNUMBER(Conv_AuV!D14)),Calc_AuV!D14/Conv_AuV!D14,"n.d.") -> 1 | E14: =IF(AND(ISNUMBER(Calc_AuV!E14),ISNUMBER(Conv_AuV!E14)),Calc_AuV!E14/Conv_AuV!E14,"n.d.") -> 1 | F14: =IF(AND(ISNUMBER(Calc_AuV!F14),ISNUMBER(Conv_AuV!F14)),Calc_AuV!F14/Conv_AuV!F14,"n.d.") -> 1 | G14: =IF(AND(ISNUMBER(Calc_AuV!G14),ISNUMBER(Conv_AuV!G14)),Calc_AuV!G14/Conv_AuV!G14,"n.d.") -> 1 | H14: =IF(AND(ISNUMBER(Calc_AuV!H14),ISNUMBER(Conv_AuV!H14)),Calc_AuV!H14/Conv_AuV!H14,"n.d.") -> 1 | I14: =IF(AND(ISNUMBER(Calc_AuV!I14),ISNUMBER(Conv_AuV!I14)),Calc_AuV!I14/Conv_AuV!I14,"n.d.") -> 1 | J14: =IF(AND(ISNUMBER(Calc_AuV!J14),ISNUMBER(Conv_AuV!J14)),Calc_AuV!J14/Conv_AuV!J14,"n.d.") -> 1 | ... X14: =IF(AND(ISNUMBER(Calc_AuV!X14),ISNUMBER(Conv_AuV!X14)),Calc_AuV!X14/Conv_AuV!X14,"n.d.") -> 1
A15: =Calc_AuV!A15 -> ak | B15: =Calc_AuV!B15 -> R10 | C15: =IF(AND(ISNUMBER(Calc_AuV!C15),ISNUMBER(Conv_AuV!C15)),Calc_AuV!C15/Conv_AuV!C15,"n.d.") -> 1 | D15: =IF(AND(ISNUMBER(Calc_AuV!D15),ISNUMBER(Conv_AuV!D15)),Calc_AuV!D15/Conv_AuV!D15,"n.d.") -> 1 | E15: =IF(AND(ISNUMBER(Calc_AuV!E15),ISNUMBER(Conv_AuV!E15)),Calc_AuV!E15/Conv_AuV!E15,"n.d.") -> 1 | F15: =IF(AND(ISNUMBER(Calc_AuV!F15),ISNUMBER(Conv_AuV!F15)),Calc_AuV!F15/Conv_AuV!F15,"n.d.") -> 1 | G15: =IF(AND(ISNUMBER(Calc_AuV!G15),ISNUMBER(Conv_AuV!G15)),Calc_AuV!G15/Conv_AuV!G15,"n.d.") -> 1 | H15: =IF(AND(ISNUMBER(Calc_AuV!H15),ISNUMBER(Conv_AuV!H15)),Calc_AuV!H15/Conv_AuV!H15,"n.d.") -> 1 | I15: =IF(AND(ISNUMBER(Calc_AuV!I15),ISNUMBER(Conv_AuV!I15)),Calc_AuV!I15/Conv_AuV!I15,"n.d.") -> 1 | J15: =IF(AND(ISNUMBER(Calc_AuV!J15),ISNUMBER(Conv_AuV!J15)),Calc_AuV!J15/Conv_AuV!J15,"n.d.") -> 1 | ... X15: =IF(AND(ISNUMBER(Calc_AuV!X15),ISNUMBER(Conv_AuV!X15)),Calc_AuV!X15/Conv_AuV!X15,"n.d.") -> 1
A16: =Calc_AuV!A16 -> al | B16: =Calc_AuV!B16 -> R11 | C16: =IF(AND(ISNUMBER(Calc_AuV!C16),ISNUMBER(Conv_AuV!C16)),Calc_AuV!C16/Conv_AuV!C16,"n.d.") -> 1 | D16: =IF(AND(ISNUMBER(Calc_AuV!D16),ISNUMBER(Conv_AuV!D16)),Calc_AuV!D16/Conv_AuV!D16,"n.d.") -> 1 | E16: =IF(AND(ISNUMBER(Calc_AuV!E16),ISNUMBER(Conv_AuV!E16)),Calc_AuV!E16/Conv_AuV!E16,"n.d.") -> 1 | F16: =IF(AND(ISNUMBER(Calc_AuV!F16),ISNUMBER(Conv_AuV!F16)),Calc_AuV!F16/Conv_AuV!F16,"n.d.") -> 1 | G16: =IF(AND(ISNUMBER(Calc_AuV!G16),ISNUMBER(Conv_AuV!G16)),Calc_AuV!G16/Conv_AuV!G16,"n.d.") -> 1 | H16: =IF(AND(ISNUMBER(Calc_AuV!H16),ISNUMBER(Conv_AuV!H16)),Calc_AuV!H16/Conv_AuV!H16,"n.d.") -> 1 | I16: =IF(AND(ISNUMBER(Calc_AuV!I16),ISNUMBER(Conv_AuV!I16)),Calc_AuV!I16/Conv_AuV!I16,"n.d.") -> 1 | J16: =IF(AND(ISNUMBER(Calc_AuV!J16),ISNUMBER(Conv_AuV!J16)),Calc_AuV!J16/Conv_AuV!J16,"n.d.") -> 1 | ... X16: =IF(AND(ISNUMBER(Calc_AuV!X16),ISNUMBER(Conv_AuV!X16)),Calc_AuV!X16/Conv_AuV!X16,"n.d.") -> 1

Sheet Razões RhV
A1: Alvo RhV — razão Calculadora / Planilha convencional, por amostra
C3: P | E3: S | G3: Cl | I3: K | K3: Ca | M3: Cr | O3: Mn | Q3: Fe | S3: Ni | U3: Cu | W3: Zn
A4: Medida | B4: Amostra | C4: C | D4: u | E4: C | F4: u | G4: C | H4: u | I4: C | J4: u | K4: C | L4: u | M4: C | N4: u | O4: C | P4: u | Q4: C | R4: u | S4: C | T4: u | U4: C | V4: u | W4: C | X4: u
A5: LD | C5: =IF(AND(ISNUMBER(Calc_RhV!C5),ISNUMBER(Conv_RhV!C5)),Calc_RhV!C5/Conv_RhV!C5,"n.d.") -> 1 | E5: =IF(AND(ISNUMBER(Calc_RhV!E5),ISNUMBER(Conv_RhV!E5)),Calc_RhV!E5/Conv_RhV!E5,"n.d.") -> 1 | G5: =IF(AND(ISNUMBER(Calc_RhV!G5),ISNUMBER(Conv_RhV!G5)),Calc_RhV!G5/Conv_RhV!G5,"n.d.") -> 1 | I5: =IF(AND(ISNUMBER(Calc_RhV!I5),ISNUMBER(Conv_RhV!I5)),Calc_RhV!I5/Conv_RhV!I5,"n.d.") -> 1 | K5: =IF(AND(ISNUMBER(Calc_RhV!K5),ISNUMBER(Conv_RhV!K5)),Calc_RhV!K5/Conv_RhV!K5,"n.d.") -> 1 | M5: =IF(AND(ISNUMBER(Calc_RhV!M5),ISNUMBER(Conv_RhV!M5)),Calc_RhV!M5/Conv_RhV!M5,"n.d.") -> 1 | O5: =IF(AND(ISNUMBER(Calc_RhV!O5),ISNUMBER(Conv_RhV!O5)),Calc_RhV!O5/Conv_RhV!O5,"n.d.") -> 1 | Q5: =IF(AND(ISNUMBER(Calc_RhV!Q5),ISNUMBER(Conv_RhV!Q5)),Calc_RhV!Q5/Conv_RhV!Q5,"n.d.") -> 1 | S5: =IF(AND(ISNUMBER(Calc_RhV!S5),ISNUMBER(Conv_RhV!S5)),Calc_RhV!S5/Conv_RhV!S5,"n.d.") -> 1 | U5: =IF(AND(ISNUMBER(Calc_RhV!U5),ISNUMBER(Conv_RhV!U5)),Calc_RhV!U5/Conv_RhV!U5,"n.d.") -> 1 | W5: =IF(AND(ISNUMBER(Calc_RhV!W5),ISNUMBER(Conv_RhV!W5)),Calc_RhV!W5/Conv_RhV!W5,"n.d.") -> 1
A6: =Calc_RhV!A6 -> ab | B6: =Calc_RhV!B6 -> Padrão (1573a) | C6: =IF(AND(ISNUMBER(Calc_RhV!C6),ISNUMBER(Conv_RhV!C6)),Calc_RhV!C6/Conv_RhV!C6,"n.d.") -> 1 | D6: =IF(AND(ISNUMBER(Calc_RhV!D6),ISNUMBER(Conv_RhV!D6)),Calc_RhV!D6/Conv_RhV!D6,"n.d.") -> 1 | E6: =IF(AND(ISNUMBER(Calc_RhV!E6),ISNUMBER(Conv_RhV!E6)),Calc_RhV!E6/Conv_RhV!E6,"n.d.") -> 1 | F6: =IF(AND(ISNUMBER(Calc_RhV!F6),ISNUMBER(Conv_RhV!F6)),Calc_RhV!F6/Conv_RhV!F6,"n.d.") -> 1 | G6: =IF(AND(ISNUMBER(Calc_RhV!G6),ISNUMBER(Conv_RhV!G6)),Calc_RhV!G6/Conv_RhV!G6,"n.d.") -> 1 | H6: =IF(AND(ISNUMBER(Calc_RhV!H6),ISNUMBER(Conv_RhV!H6)),Calc_RhV!H6/Conv_RhV!H6,"n.d.") -> 1 | I6: =IF(AND(ISNUMBER(Calc_RhV!I6),ISNUMBER(Conv_RhV!I6)),Calc_RhV!I6/Conv_RhV!I6,"n.d.") -> 1 | J6: =IF(AND(ISNUMBER(Calc_RhV!J6),ISNUMBER(Conv_RhV!J6)),Calc_RhV!J6/Conv_RhV!J6,"n.d.") -> 1 | ... X6: =IF(AND(ISNUMBER(Calc_RhV!X6),ISNUMBER(Conv_RhV!X6)),Calc_RhV!X6/Conv_RhV!X6,"n.d.") -> 1
A7: =Calc_RhV!A7 -> ac | B7: =Calc_RhV!B7 -> R2 | C7: =IF(AND(ISNUMBER(Calc_RhV!C7),ISNUMBER(Conv_RhV!C7)),Calc_RhV!C7/Conv_RhV!C7,"n.d.") -> 1 | D7: =IF(AND(ISNUMBER(Calc_RhV!D7),ISNUMBER(Conv_RhV!D7)),Calc_RhV!D7/Conv_RhV!D7,"n.d.") -> 1 | E7: =IF(AND(ISNUMBER(Calc_RhV!E7),ISNUMBER(Conv_RhV!E7)),Calc_RhV!E7/Conv_RhV!E7,"n.d.") -> 1 | F7: =IF(AND(ISNUMBER(Calc_RhV!F7),ISNUMBER(Conv_RhV!F7)),Calc_RhV!F7/Conv_RhV!F7,"n.d.") -> 1 | G7: =IF(AND(ISNUMBER(Calc_RhV!G7),ISNUMBER(Conv_RhV!G7)),Calc_RhV!G7/Conv_RhV!G7,"n.d.") -> 1 | H7: =IF(AND(ISNUMBER(Calc_RhV!H7),ISNUMBER(Conv_RhV!H7)),Calc_RhV!H7/Conv_RhV!H7,"n.d.") -> 1 | I7: =IF(AND(ISNUMBER(Calc_RhV!I7),ISNUMBER(Conv_RhV!I7)),Calc_RhV!I7/Conv_RhV!I7,"n.d.") -> 1 | J7: =IF(AND(ISNUMBER(Calc_RhV!J7),ISNUMBER(Conv_RhV!J7)),Calc_RhV!J7/Conv_RhV!J7,"n.d.") -> 1 | ... X7: =IF(AND(ISNUMBER(Calc_RhV!X7),ISNUMBER(Conv_RhV!X7)),Calc_RhV!X7/Conv_RhV!X7,"n.d.") -> 1
A8: =Calc_RhV!A8 -> ad | B8: =Calc_RhV!B8 -> R3 | C8: =IF(AND(ISNUMBER(Calc_RhV!C8),ISNUMBER(Conv_RhV!C8)),Calc_RhV!C8/Conv_RhV!C8,"n.d.") -> 1 | D8: =IF(AND(ISNUMBER(Calc_RhV!D8),ISNUMBER(Conv_RhV!D8)),Calc_RhV!D8/Conv_RhV!D8,"n.d.") -> 1 | E8: =IF(AND(ISNUMBER(Calc_RhV!E8),ISNUMBER(Conv_RhV!E8)),Calc_RhV!E8/Conv_RhV!E8,"n.d.") -> 1 | F8: =IF(AND(ISNUMBER(Calc_RhV!F8),ISNUMBER(Conv_RhV!F8)),Calc_RhV!F8/Conv_RhV!F8,"n.d.") -> 1 | G8: =IF(AND(ISNUMBER(Calc_RhV!G8),ISNUMBER(Conv_RhV!G8)),Calc_RhV!G8/Conv_RhV!G8,"n.d.") -> 1 | H8: =IF(AND(ISNUMBER(Calc_RhV!H8),ISNUMBER(Conv_RhV!H8)),Calc_RhV!H8/Conv_RhV!H8,"n.d.") -> 1 | I8: =IF(AND(ISNUMBER(Calc_RhV!I8),ISNUMBER(Conv_RhV!I8)),Calc_RhV!I8/Conv_RhV!I8,"n.d.") -> 1 | J8: =IF(AND(ISNUMBER(Calc_RhV!J8),ISNUMBER(Conv_RhV!J8)),Calc_RhV!J8/Conv_RhV!J8,"n.d.") -> 1 | ... X8: =IF(AND(ISNUMBER(Calc_RhV!X8),ISNUMBER(Conv_RhV!X8)),Calc_RhV!X8/Conv_RhV!X8,"n.d.") -> 1
A9: =Calc_RhV!A9 -> ae | B9: =Calc_RhV!B9 -> R4 | C9: =IF(AND(ISNUMBER(Calc_RhV!C9),ISNUMBER(Conv_RhV!C9)),Calc_RhV!C9/Conv_RhV!C9,"n.d.") -> 1 | D9: =IF(AND(ISNUMBER(Calc_RhV!D9),ISNUMBER(Conv_RhV!D9)),Calc_RhV!D9/Conv_RhV!D9,"n.d.") -> 1 | E9: =IF(AND(ISNUMBER(Calc_RhV!E9),ISNUMBER(Conv_RhV!E9)),Calc_RhV!E9/Conv_RhV!E9,"n.d.") -> 1 | F9: =IF(AND(ISNUMBER(Calc_RhV!F9),ISNUMBER(Conv_RhV!F9)),Calc_RhV!F9/Conv_RhV!F9,"n.d.") -> 1 | G9: =IF(AND(ISNUMBER(Calc_RhV!G9),ISNUMBER(Conv_RhV!G9)),Calc_RhV!G9/Conv_RhV!G9,"n.d.") -> 1 | H9: =IF(AND(ISNUMBER(Calc_RhV!H9),ISNUMBER(Conv_RhV!H9)),Calc_RhV!H9/Conv_RhV!H9,"n.d.") -> 1 | I9: =IF(AND(ISNUMBER(Calc_RhV!I9),ISNUMBER(Conv_RhV!I9)),Calc_RhV!I9/Conv_RhV!I9,"n.d.") -> 1 | J9: =IF(AND(ISNUMBER(Calc_RhV!J9),ISNUMBER(Conv_RhV!J9)),Calc_RhV!J9/Conv_RhV!J9,"n.d.") -> 1 | ... X9: =IF(AND(ISNUMBER(Calc_RhV!X9),ISNUMBER(Conv_RhV!X9)),Calc_RhV!X9/Conv_RhV!X9,"n.d.") -> 1
A10: =Calc_RhV!A10 -> af | B10: =Calc_RhV!B10 -> R5 | C10: =IF(AND(ISNUMBER(Calc_RhV!C10),ISNUMBER(Conv_RhV!C10)),Calc_RhV!C10/Conv_RhV!C10,"n.d.") -> 1 | D10: =IF(AND(ISNUMBER(Calc_RhV!D10),ISNUMBER(Conv_RhV!D10)),Calc_RhV!D10/Conv_RhV!D10,"n.d.") -> 1 | E10: =IF(AND(ISNUMBER(Calc_RhV!E10),ISNUMBER(Conv_RhV!E10)),Calc_RhV!E10/Conv_RhV!E10,"n.d.") -> 1 | F10: =IF(AND(ISNUMBER(Calc_RhV!F10),ISNUMBER(Conv_RhV!F10)),Calc_RhV!F10/Conv_RhV!F10,"n.d.") -> 1 | G10: =IF(AND(ISNUMBER(Calc_RhV!G10),ISNUMBER(Conv_RhV!G10)),Calc_RhV!G10/Conv_RhV!G10,"n.d.") -> 1 | H10: =IF(AND(ISNUMBER(Calc_RhV!H10),ISNUMBER(Conv_RhV!H10)),Calc_RhV!H10/Conv_RhV!H10,"n.d.") -> 1 | I10: =IF(AND(ISNUMBER(Calc_RhV!I10),ISNUMBER(Conv_RhV!I10)),Calc_RhV!I10/Conv_RhV!I10,"n.d.") -> 1 | J10: =IF(AND(ISNUMBER(Calc_RhV!J10),ISNUMBER(Conv_RhV!J10)),Calc_RhV!J10/Conv_RhV!J10,"n.d.") -> 1 | ... X10: =IF(AND(ISNUMBER(Calc_RhV!X10),ISNUMBER(Conv_RhV!X10)),Calc_RhV!X10/Conv_RhV!X10,"n.d.") -> 1
A11: =Calc_RhV!A11 -> ag | B11: =Calc_RhV!B11 -> R6 | C11: =IF(AND(ISNUMBER(Calc_RhV!C11),ISNUMBER(Conv_RhV!C11)),Calc_RhV!C11/Conv_RhV!C11,"n.d.") -> 1 | D11: =IF(AND(ISNUMBER(Calc_RhV!D11),ISNUMBER(Conv_RhV!D11)),Calc_RhV!D11/Conv_RhV!D11,"n.d.") -> 1 | E11: =IF(AND(ISNUMBER(Calc_RhV!E11),ISNUMBER(Conv_RhV!E11)),Calc_RhV!E11/Conv_RhV!E11,"n.d.") -> 1 | F11: =IF(AND(ISNUMBER(Calc_RhV!F11),ISNUMBER(Conv_RhV!F11)),Calc_RhV!F11/Conv_RhV!F11,"n.d.") -> 1 | G11: =IF(AND(ISNUMBER(Calc_RhV!G11),ISNUMBER(Conv_RhV!G11)),Calc_RhV!G11/Conv_RhV!G11,"n.d.") -> 1 | H11: =IF(AND(ISNUMBER(Calc_RhV!H11),ISNUMBER(Conv_RhV!H11)),Calc_RhV!H11/Conv_RhV!H11,"n.d.") -> 1 | I11: =IF(AND(ISNUMBER(Calc_RhV!I11),ISNUMBER(Conv_RhV!I11)),Calc_RhV!I11/Conv_RhV!I11,"n.d.") -> 1 | J11: =IF(AND(ISNUMBER(Calc_RhV!J11),ISNUMBER(Conv_RhV!J11)),Calc_RhV!J11/Conv_RhV!J11,"n.d.") -> 1 | ... X11: =IF(AND(ISNUMBER(Calc_RhV!X11),ISNUMBER(Conv_RhV!X11)),Calc_RhV!X11/Conv_RhV!X11,"n.d.") -> 1
A12: =Calc_RhV!A12 -> ah | B12: =Calc_RhV!B12 -> R7 | C12: =IF(AND(ISNUMBER(Calc_RhV!C12),ISNUMBER(Conv_RhV!C12)),Calc_RhV!C12/Conv_RhV!C12,"n.d.") -> 1 | D12: =IF(AND(ISNUMBER(Calc_RhV!D12),ISNUMBER(Conv_RhV!D12)),Calc_RhV!D12/Conv_RhV!D12,"n.d.") -> 1 | E12: =IF(AND(ISNUMBER(Calc_RhV!E12),ISNUMBER(Conv_RhV!E12)),Calc_RhV!E12/Conv_RhV!E12,"n.d.") -> 1 | F12: =IF(AND(ISNUMBER(Calc_RhV!F12),ISNUMBER(Conv_RhV!F12)),Calc_RhV!F12/Conv_RhV!F12,"n.d.") -> 1 | G12: =IF(AND(ISNUMBER(Calc_RhV!G12),ISNUMBER(Conv_RhV!G12)),Calc_RhV!G12/Conv_RhV!G12,"n.d.") -> 1 | H12: =IF(AND(ISNUMBER(Calc_RhV!H12),ISNUMBER(Conv_RhV!H12)),Calc_RhV!H12/Conv_RhV!H12,"n.d.") -> 1 | I12: =IF(AND(ISNUMBER(Calc_RhV!I12),ISNUMBER(Conv_RhV!I12)),Calc_RhV!I12/Conv_RhV!I12,"n.d.") -> 1 | J12: =IF(AND(ISNUMBER(Calc_RhV!J12),ISNUMBER(Conv_RhV!J12)),Calc_RhV!J12/Conv_RhV!J12,"n.d.") -> 1 | ... X12: =IF(AND(ISNUMBER(Calc_RhV!X12),ISNUMBER(Conv_RhV!X12)),Calc_RhV!X12/Conv_RhV!X12,"n.d.") -> 1
A13: =Calc_RhV!A13 -> ai | B13: =Calc_RhV!B13 -> R8 | C13: =IF(AND(ISNUMBER(Calc_RhV!C13),ISNUMBER(Conv_RhV!C13)),Calc_RhV!C13/Conv_RhV!C13,"n.d.") -> 1 | D13: =IF(AND(ISNUMBER(Calc_RhV!D13),ISNUMBER(Conv_RhV!D13)),Calc_RhV!D13/Conv_RhV!D13,"n.d.") -> 1 | E13: =IF(AND(ISNUMBER(Calc_RhV!E13),ISNUMBER(Conv_RhV!E13)),Calc_RhV!E13/Conv_RhV!E13,"n.d.") -> 1 | F13: =IF(AND(ISNUMBER(Calc_RhV!F13),ISNUMBER(Conv_RhV!F13)),Calc_RhV!F13/Conv_RhV!F13,"n.d.") -> 1 | G13: =IF(AND(ISNUMBER(Calc_RhV!G13),ISNUMBER(Conv_RhV!G13)),Calc_RhV!G13/Conv_RhV!G13,"n.d.") -> 1 | H13: =IF(AND(ISNUMBER(Calc_RhV!H13),ISNUMBER(Conv_RhV!H13)),Calc_RhV!H13/Conv_RhV!H13,"n.d.") -> 1 | I13: =IF(AND(ISNUMBER(Calc_RhV!I13),ISNUMBER(Conv_RhV!I13)),Calc_RhV!I13/Conv_RhV!I13,"n.d.") -> 1 | J13: =IF(AND(ISNUMBER(Calc_RhV!J13),ISNUMBER(Conv_RhV!J13)),Calc_RhV!J13/Conv_RhV!J13,"n.d.") -> 1 | ... X13: =IF(AND(ISNUMBER(Calc_RhV!X13),ISNUMBER(Conv_RhV!X13)),Calc_RhV!X13/Conv_RhV!X13,"n.d.") -> 1
A14: =Calc_RhV!A14 -> aj | B14: =Calc_RhV!B14 -> R9 | C14: =IF(AND(ISNUMBER(Calc_RhV!C14),ISNUMBER(Conv_RhV!C14)),Calc_RhV!C14/Conv_RhV!C14,"n.d.") -> 1 | D14: =IF(AND(ISNUMBER(Calc_RhV!D14),ISNUMBER(Conv_RhV!D14)),Calc_RhV!D14/Conv_RhV!D14,"n.d.") -> 1 | E14: =IF(AND(ISNUMBER(Calc_RhV!E14),ISNUMBER(Conv_RhV!E14)),Calc_RhV!E14/Conv_RhV!E14,"n.d.") -> 1 | F14: =IF(AND(ISNUMBER(Calc_RhV!F14),ISNUMBER(Conv_RhV!F14)),Calc_RhV!F14/Conv_RhV!F14,"n.d.") -> 1 | G14: =IF(AND(ISNUMBER(Calc_RhV!G14),ISNUMBER(Conv_RhV!G14)),Calc_RhV!G14/Conv_RhV!G14,"n.d.") -> 1 | H14: =IF(AND(ISNUMBER(Calc_RhV!H14),ISNUMBER(Conv_RhV!H14)),Calc_RhV!H14/Conv_RhV!H14,"n.d.") -> 1 | I14: =IF(AND(ISNUMBER(Calc_RhV!I14),ISNUMBER(Conv_RhV!I14)),Calc_RhV!I14/Conv_RhV!I14,"n.d.") -> 1 | J14: =IF(AND(ISNUMBER(Calc_RhV!J14),ISNUMBER(Conv_RhV!J14)),Calc_RhV!J14/Conv_RhV!J14,"n.d.") -> 1 | ... X14: =IF(AND(ISNUMBER(Calc_RhV!X14),ISNUMBER(Conv_RhV!X14)),Calc_RhV!X14/Conv_RhV!X14,"n.d.") -> 1
A15: =Calc_RhV!A15 -> ak | B15: =Calc_RhV!B15 -> R10 | C15: =IF(AND(ISNUMBER(Calc_RhV!C15),ISNUMBER(Conv_RhV!C15)),Calc_RhV!C15/Conv_RhV!C15,"n.d.") -> 1 | D15: =IF(AND(ISNUMBER(Calc_RhV!D15),ISNUMBER(Conv_RhV!D15)),Calc_RhV!D15/Conv_RhV!D15,"n.d.") -> 1 | E15: =IF(AND(ISNUMBER(Calc_RhV!E15),ISNUMBER(Conv_RhV!E15)),Calc_RhV!E15/Conv_RhV!E15,"n.d.") -> 1 | F15: =IF(AND(ISNUMBER(Calc_RhV!F15),ISNUMBER(Conv_RhV!F15)),Calc_RhV!F15/Conv_RhV!F15,"n.d.") -> 1 | G15: =IF(AND(ISNUMBER(Calc_RhV!G15),ISNUMBER(Conv_RhV!G15)),Calc_RhV!G15/Conv_RhV!G15,"n.d.") -> 1 | H15: =IF(AND(ISNUMBER(Calc_RhV!H15),ISNUMBER(Conv_RhV!H15)),Calc_RhV!H15/Conv_RhV!H15,"n.d.") -> 1 | I15: =IF(AND(ISNUMBER(Calc_RhV!I15),ISNUMBER(Conv_RhV!I15)),Calc_RhV!I15/Conv_RhV!I15,"n.d.") -> 1 | J15: =IF(AND(ISNUMBER(Calc_RhV!J15),ISNUMBER(Conv_RhV!J15)),Calc_RhV!J15/Conv_RhV!J15,"n.d.") -> 1 | ... X15: =IF(AND(ISNUMBER(Calc_RhV!X15),ISNUMBER(Conv_RhV!X15)),Calc_RhV!X15/Conv_RhV!X15,"n.d.") -> 1
A16: =Calc_RhV!A16 -> al | B16: =Calc_RhV!B16 -> R11 | C16: =IF(AND(ISNUMBER(Calc_RhV!C16),ISNUMBER(Conv_RhV!C16)),Calc_RhV!C16/Conv_RhV!C16,"n.d.") -> 1 | D16: =IF(AND(ISNUMBER(Calc_RhV!D16),ISNUMBER(Conv_RhV!D16)),Calc_RhV!D16/Conv_RhV!D16,"n.d.") -> 1 | E16: =IF(AND(ISNUMBER(Calc_RhV!E16),ISNUMBER(Conv_RhV!E16)),Calc_RhV!E16/Conv_RhV!E16,"n.d.") -> 1 | F16: =IF(AND(ISNUMBER(Calc_RhV!F16),ISNUMBER(Conv_RhV!F16)),Calc_RhV!F16/Conv_RhV!F16,"n.d.") -> 1 | G16: =IF(AND(ISNUMBER(Calc_RhV!G16),ISNUMBER(Conv_RhV!G16)),Calc_RhV!G16/Conv_RhV!G16,"n.d.") -> 1 | H16: =IF(AND(ISNUMBER(Calc_RhV!H16),ISNUMBER(Conv_RhV!H16)),Calc_RhV!H16/Conv_RhV!H16,"n.d.") -> 1 | I16: =IF(AND(ISNUMBER(Calc_RhV!I16),ISNUMBER(Conv_RhV!I16)),Calc_RhV!I16/Conv_RhV!I16,"n.d.") -> 1 | J16: =IF(AND(ISNUMBER(Calc_RhV!J16),ISNUMBER(Conv_RhV!J16)),Calc_RhV!J16/Conv_RhV!J16,"n.d.") -> 1 | ... X16: =IF(AND(ISNUMBER(Calc_RhV!X16),ISNUMBER(Conv_RhV!X16)),Calc_RhV!X16/Conv_RhV!X16,"n.d.") -> 1

Sheet Calc_AgV
A1: Calculadora — alvo AgV (mg/kg)
C3: P | E3: S | G3: Cl | I3: K | K3: Ca | M3: Cr | O3: Mn | Q3: Fe | S3: Ni | U3: Cu | W3: Zn | Y3: Br
A4: Medida | B4: Amostra | C4: C | D4: u | E4: C | F4: u | G4: C | H4: u | I4: C | J4: u | K4: C | L4: u | M4: C | N4: u | O4: C | P4: u | Q4: C | R4: u | S4: C | T4: u | U4: C | V4: u | W4: C | X4: u | Y4: C | Z4: u
A5: LD | C5: 266.1867 | E5: 111.10928 | G5: 41.823184 | I5: 48.904277 | K5: 37.096076 | M5: 0.72856499 | O5: 10.670178 | Q5: 7.842995 | S5: 0.22720268 | U5: 1.1772661 | W5: 5.4637812 | Y5: 12.82203
A6: ab | B6: Padrão (1573a) | C6: 2161 | D6: 218.19243 | E6: 9600 | F6: 136.51808 | G6: 6600 | H6: 60.878899 | I6: 26760 | J6: 500.3816 | K6: 50450 | L6: 569.59317 | M6: 1.988 | N6: 0.48160588 | O6: 246.3 | P6: 11.244381 | Q6: 367.5 | R6: 8.548843 | S6: 1.582 | T6: 0.24829873 | U6: 4.7 | V6: 1.2661716 | W6: 30.94 | X6: 5.912336 | Y6: 1300 | Z6: 17.503293
A7: ac | B7: R2 | C7: 732.10138 | D7: 88.644167 | E7: 1604.1957 | F7: 41.054099 | G7: 1016.3212 | H7: 17.786541 | I7: 5574.5666 | J7: 110.92721 | K7: 1299.8493 | L7: 26.159915 | M7: 7.9393398 | N7: 1.3979896 | O7: 118.61706 | P7: 6.4241072 | Q7: 3636.6028 | R7: 67.670831 | S7: 1.3408464 | T7: 0.19912993 | U7: 3.111894 | V7: 0.88009171 | W7: 23.714166 | X7: 4.3752966 | Y7: 24.216682 | Z7: 6.0190179
A8: ad | B8: R3 | C8: 927.64968 | D8: 100.70228 | E8: 1537.7493 | F8: 42.055569 | G8: 1777.3281 | H8: 23.34048 | I8: 5164.9554 | J8: 104.35048 | K8: 1698.1001 | L8: 30.473339 | M8: 8.4061529 | N8: 1.4780327 | O8: 110.98422 | P8: 6.1992961 | Q8: 2666.4788 | R8: 49.856914 | S8: 1.3144623 | T8: 0.19407617 | U8: 2.7721842 | V8: 0.81525811 | W8: 35.181051 | X8: 5.6011701
A9: ae | B9: R4 | C9: 676.48551 | D9: 87.760843 | E9: 1596.4897 | F9: 42.663491 | G9: 1384.6777 | H9: 20.462494 | I9: 7462.6706 | J9: 144.97885 | K9: 1439.3974 | L9: 28.030139 | M9: 4.2946724 | N9: 0.79280541 | O9: 109.83986 | P9: 6.1208289 | Q9: 2299.6092 | R9: 43.096841 | S9: 1.0711163 | T9: 0.17465752 | U9: 3.5195476 | V9: 0.92244584 | W9: 15.268475 | X9: 3.5502219 | Y9: 18.422965 | Z9: 5.5931678
A10: af | B10: R5 | C10: 842.61186 | D10: 103.5242 | E10: 2124.7925 | F10: 51.663457 | G10: 1285.681 | H10: 21.937262 | I10: 9087.0391 | J10: 176.21696 | K10: 1832.7068 | L10: 34.282027 | M10: 8.5316367 | N10: 1.5077585 | O10: 156.505 | P10: 7.9993339 | Q10: 4283.873 | R10: 79.740034 | S10: 1.3044998 | T10: 0.20567888 | U10: 2.6523081 | V10: 0.87189344 | W10: 17.512469 | X10: 3.9799976 | Y10: 22.783062 | Z10: 6.2244118
A11: ag | B11: R6 | C11: 842.47121 | D11: 103.11324 | E11: 2135.8147 | F11: 50.564107 | G11: 1353.7749 | H11: 21.811906 | I11: 9218.8268 | J11: 178.02556 | K11: 1780.4587 | L11: 33.050643 | M11: 5.4570972 | N11: 0.99640203 | O11: 185.83871 | P11: 8.9130778 | Q11: 4828.3016 | R11: 89.703559 | S11: 1.2410194 | T11: 0.20362972 | U11: 4.3198502 | V11: 1.1141643 | W11: 23.48544 | X11: 4.6455983 | Y11: 20.535023 | Z11: 6.7510898
A12: ah | B12: R7 | C12: 933.08128 | D12: 101.04474 | E12: 1612.6803 | F12: 43.211033 | G12: 1711.875 | H12: 22.802871 | I12: 5664.0534 | J12: 112.80172 | K12: 1273.4423 | L12: 26.30671 | M12: 4.2071014 | N12: 0.77514119 | O12: 138.40494 | P12: 6.902602 | Q12: 2399.4857 | R12: 44.928933 | S12: 0.80468218 | T12: 0.1476099 | U12: 2.4241144 | V12: 0.74282429 | W12: 17.61955 | X12: 3.541158 | Y12: 16.092736 | Z12: 5.0232708
A13: ai | B13: R8 | C13: 952.81927 | D13: 105.87829 | E13: 1494.6304 | F13: 42.959558 | G13: 1403.4625 | H13: 21.71632 | I13: 6484.5358 | J13: 128.4179 | K13: 1325.5144 | L13: 28.118672 | M13: 9.5073993 | N13: 1.6684316 | O13: 202.79417 | P13: 9.3736193 | Q13: 4631.6507 | R13: 86.067284 | S13: 1.5203556 | T13: 0.22075125 | U13: 3.7036488 | V13: 0.99036718 | W13: 20.487935 | X13: 4.1871396 | Y13: 24.932487 | Z13: 6.2376399
A14: aj | B14: R9 | C14: 1333.5514 | D14: 137.73853 | E14: 2296.9465 | F14: 54.9635 | G14: 2325.3444 | H14: 29.596377 | I14: 10857.113 | J14: 208.28111 | K14: 1457.8448 | L14: 31.205333 | M14: 8.8199255 | N14: 1.5601051 | O14: 220.66205 | P14: 10.279988 | Q14: 7220.1114 | R14: 133.77657 | S14: 1.7552113 | T14: 0.25371238 | U14: 4.5314935 | V14: 1.1761327 | W14: 27.789138 | X14: 5.2362812 | Y14: 33.886826 | Z14: 7.6109042
A15: ak | B15: R10 | C15: 1220.4912 | D15: 122.32016 | E15: 1707.0095 | F15: 45.929302 | G15: 1373.9906 | H15: 21.370956 | I15: 7210.1272 | J15: 141.30596 | K15: 1879.9649 | L15: 33.100788 | M15: 9.2956228 | N15: 1.6333892 | O15: 151.48732 | P15: 7.7315495 | Q15: 6106.3323 | R15: 113.1719 | S15: 1.5971197 | T15: 0.23037184 | U15: 4.1993505 | V15: 1.0761524 | W15: 16.192587 | X15: 3.9000511 | Y15: 23.449874 | Z15: 6.5423885
A16: al | B16: R11 | C16: 1361.9127 | D16: 129.0076 | E16: 1267.4416 | F16: 40.964652 | G16: 939.18195 | H16: 18.28032 | I16: 6092.5221 | J16: 121.48735 | K16: 1658.3691 | L16: 30.907655 | M16: 11.935576 | N16: 2.0812852 | O16: 265.98882 | P16: 11.62421 | Q16: 6779.3238 | R16: 125.58937 | S16: 1.7802597 | T16: 0.24877171 | U16: 3.4958069 | V16: 0.99436341 | W16: 17.598516 | X16: 4.1125027 | Y16: 30.855523 | Z16: 7.0496205

Sheet Conv_AgV
A1: Planilha convencional (corrigida) — alvo AgV (mg/kg)
C3: P | E3: S | G3: Cl | I3: K | K3: Ca | M3: Cr | O3: Mn | Q3: Fe | S3: Ni | U3: Cu | W3: Zn | Y3: Br
A4: Medida | B4: Amostra | C4: C | D4: u | E4: C | F4: u | G4: C | H4: u | I4: C | J4: u | K4: C | L4: u | M4: C | N4: u | O4: C | P4: u | Q4: C | R4: u | S4: C | T4: u | U4: C | V4: u | W4: C | X4: u | Y4: C | Z4: u
A5: LD | C5: 266.1867 | E5: 111.10928 | G5: 41.823184 | I5: 48.904277 | K5: 37.096076 | M5: 0.72856499 | O5: 10.670178 | Q5: 7.842995 | S5: 0.22720268 | U5: 1.1772661 | W5: 5.4637812 | Y5: 12.82203
A6: ab | B6: Padrão (1573a) | C6: 2161 | D6: 218.19243 | E6: 9600 | F6: 136.51808 | G6: 6600 | H6: 60.878899 | I6: 26760 | J6: 500.3816 | K6: 50450 | L6: 569.59317 | M6: 1.988 | N6: 0.48160588 | O6: 246.3 | P6: 11.244381 | Q6: 367.5 | R6: 8.548843 | S6: 1.582 | T6: 0.24829873 | U6: 4.7 | V6: 1.2661716 | W6: 30.94 | X6: 5.912336 | Y6: 1300 | Z6: 17.503293
A7: ac | B7: R2 | C7: 732.10138 | D7: 88.644167 | E7: 1604.1957 | F7: 41.054099 | G7: 1016.3212 | H7: 17.786541 | I7: 5574.5666 | J7: 110.92721 | K7: 1299.8493 | L7: 26.159915 | M7: 7.9393398 | N7: 1.3979896 | O7: 118.61706 | P7: 6.4241072 | Q7: 3636.6028 | R7: 67.670831 | S7: 1.3408464 | T7: 0.19912993 | U7: 3.111894 | V7: 0.88009171 | W7: 23.714166 | X7: 4.3752966 | Y7: 24.216682 | Z7: 6.0190179
A8: ad | B8: R3 | C8: 927.64968 | D8: 100.70228 | E8: 1537.7493 | F8: 42.055569 | G8: 1777.3281 | H8: 23.34048 | I8: 5164.9554 | J8: 104.35048 | K8: 1698.1001 | L8: 30.473339 | M8: 8.4061529 | N8: 1.4780327 | O8: 110.98422 | P8: 6.1992961 | Q8: 2666.4788 | R8: 49.856914 | S8: 1.3144623 | T8: 0.19407617 | U8: 2.7721842 | V8: 0.81525811 | W8: 35.181051 | X8: 5.6011701
A9: ae | B9: R4 | C9: 676.48551 | D9: 87.760843 | E9: 1596.4897 | F9: 42.663491 | G9: 1384.6777 | H9: 20.462494 | I9: 7462.6706 | J9: 144.97885 | K9: 1439.3974 | L9: 28.030139 | M9: 4.2946724 | N9: 0.79280541 | O9: 109.83986 | P9: 6.1208289 | Q9: 2299.6092 | R9: 43.096841 | S9: 1.0711163 | T9: 0.17465752 | U9: 3.5195476 | V9: 0.92244584 | W9: 15.268475 | X9: 3.5502219 | Y9: 18.422965 | Z9: 5.5931678
