Workbook

Sheet Padrões
B1: Adicionar Slots | E1: Banco de Dados para Padrões | N1: Informações | O1: Acrescente seu padrão substituindo-o em alguma coluna, preferencialmente nas últimas colunas de nome "Pd", basta trocar o nome do padrão e colocar os valores em mg/kg!!
B3: Padrões | C3: Indices | E3: Padrões adicionados
C4: Concentração | D4: erro | E4: Farinha de Soja | H4: Folha de Tomate | K4: Farinha de Trigo | N4: Cinza de Madeira (MAD811) | Q4: Solo Buffalo 8704 | T4: Solo Montana 2710 | W4: Pd3 | Z4: pd4 | AC4: pd5 | AF4: p6 | AI4: Pd | AL4: Pd 1 | AO4: Pd 2
B5: =E4 -> Farinha de Soja | C5: 2 | D5: =C5+1 -> 3 | E5: Elemento | F5: C (mg/kg) | G5: erro | H5: Elemento | I5: C (mg/kg) | J5: erro | K5: Elemento | L5: C (mg/kg) | M5: erro | N5: Elemento | O5: C (mg/kg) | P5: erro | Q5: Elemento | R5: C (mg/kg) | S5: erro | T5: Elemento | U5: C (mg/kg) | V5: erro | W5: Elemento | X5: C (mg/kg) | Y5: erro | Z5: Elemento | AA5: C (mg/kg) | AB5: erro | AC5: Elemento | AD5: C (mg/kg) | AE5: erro | AF5: Elemento | AG5: C (mg/kg) | AH5: erro | AI5: Elemento | AJ5: C (mg/kg) | AK5: erro | AL5: Elemento | AM5: C (mg/kg) | AN5: erro | AO5: Elemento | AP5: C (mg/kg) | AQ5: erro
B6: =H4 -> Folha de Tomate | C6: =C5+3 -> 5 | D6: =C6+1 -> 6 | E6: Al | H6: Al | I6: 598.4 | J6: 7.1 | K6: Al | N6: Al | Q6: Al | R6: =61*1000 -> 61000 | S6: =0.18*10*1000 -> 1800 | T6: Al | U6: =64.4*1000 -> 64400 | W6: Al | Z6: Al | AC6: Al | AF6: Al | AI6: Al | AL6: Al | AO6: Al
B7: =K4 -> Farinha de Trigo | C7: =C6+3 -> 8 | D7: =C7+1 -> 9 | E7: Si | H7: Si | K7: Si | N7: Si | Q7: Si | T7: Si | U7: =289.7*1000 -> 289700 | W7: Si | Z7: Si | AC7: Si | AF7: Si | AI7: Si | AL7: Si | AO7: Si
B8: =N4 -> Cinza de Madeira (MAD811) | C8: =C7+3 -> 11 | D8: =C8+1 -> 12 | E8: P | F8: 5250 | G8: 431 | H8: P | I8: 2161 | J8: 28 | K8: P | L8: 1333 | M8: 36 | N8: P | Q8: P | T8: P | U8: =10.06*1000 -> 10060 | W8: P | Z8: P | AC8: P | AF8: P | AI8: P | AL8: P | AO8: P
B9: =Q4 -> Solo Buffalo 8704 | C9: =C8+3 -> 14 | D9: =C9+1 -> 15 | E9: S | F9: 258 | G9: 2 | H9: S | I9: 9600 | K9: S | L9: 1645 | M9: 25 | N9: S | Q9: S | T9: S | U9: =2.4*1000 -> 2400 | W9: S | Z9: S | AC9: S | AF9: S | AI9: S | AL9: S | AO9: S
B10: =T4 -> Solo Montana 2710 | C10: =C9+3 -> 17 | D10: =C10+1 -> 18 | E10: Cl | H10: Cl | I10: 6600 | K10: Cl | L10: 565.3 | M10: 8.6 | N10: Cl | Q10: Cl | T10: Cl | W10: Cl | Z10: Cl | AC10: Cl | AF10: Cl | AI10: Cl | AL10: Cl | AO10: Cl
B11: =W4 -> Pd3 | C11: =C10+3 -> 20 | D11: =C11+1 -> 21 | E11: Ar | H11: Ar | K11: Ar | N11: Ar | Q11: Ar | T11: Ar | W11: Ar | Z11: Ar | AC11: Ar | AF11: Ar | AI11: Ar | AL11: Ar | AO11: Ar
B12: =Z4 -> pd4 | C12: =C11+3 -> 23 | D12: =C12+1 -> 24 | E12: K | F12: 17762 | G12: 1068 | H12: K | I12: 26760 | J12: 480 | K12: K | L12: 1325 | M12: 20 | N12: K | O12: =123*1000 -> 123000 | Q12: K | R12: =20.01*1000 -> 20010 | S12: 410 | T12: K | U12: =21.1*1000 -> 21100 | W12: K | Z12: K | AC12: K | AF12: K | AI12: K | AL12: K | AO12: K
B13: =AC4 -> pd5 | C13: =C12+3 -> 26 | D13: =C13+1 -> 27 | E13: Ca | F13: 2022 | G13: 199 | H13: Ca | I13: 50450 | J13: 550 | K13: Ca | L13: 191.4 | M13: 3.3 | N13: Ca | O13: =103*1000 -> 103000 | Q13: Ca | R13: =26.41*1000 -> 26410 | S13: =0.083*10*1000 -> 830 | T13: Ca | U13: =12.5*1000 -> 12500 | W13: Ca | Z13: Ca | AC13: Ca | AF13: Ca | AI13: Ca | AL13: Ca | AO13: Ca
B14: =AF4 -> p6 | C14: =C13+3 -> 29 | D14: =C14+1 -> 30 | E14: Sc | H14: Sc | I14: 0.1 | K14: Sc | N14: Sc | Q14: Sc | R14: 11.26 | S14: 0.19 | T14: Sc | U14: 8.7 | W14: Sc | Z14: Sc | AC14: Sc | AF14: Sc | AI14: Sc | AL14: Sc | AO14: Sc
B15: =AI4 -> Pd | C15: =C14+3 -> 32 | D15: =C15+1 -> 33 | E15: Ti | H15: Ti | K15: Ti | N15: Ti | Q15: Ti | R15: =4.57*1000 -> 4570 | S15: =0.02*10*1000 -> 200 | T15: Ti | U15: =2.83*1000 -> 2830 | W15: Ti | Z15: Ti | AC15: Ti | AF15: Ti | AI15: Ti | AL15: Ti | AO15: Ti
B16: =AL4 -> Pd 1 | C16: =C15+3 -> 35 | D16: =C16+1 -> 36 | E16: V | H16: V | I16: 0.835 | J16: 0.034 | K16: V | N16: V | Q16: V | R16: 94.6 | S16: 4 | T16: V | U16: 76.6 | V16: 2.3 | W16: V | Z16: V | AC16: V | AF16: V | AI16: V | AL16: V | AO16: V
B17: =AO4 -> Pd 2 | C17: =C16+3 -> 38 | D17: =C17+1 -> 39 | E17: Cr | H17: Cr | I17: 1.988 | J17: 0.034 | K17: Cr | N17: Cr | Q17: Cr | R17: 121.9 | S17: 3.8 | T17: Cr | U17: 39 | W17: Cr | Z17: Cr | AC17: Cr | AF17: Cr | AI17: Cr | AL17: Cr | AO17: Cr
C18: =C17+3 -> 41 | D18: =C18+1 -> 42 | E18: Mn | F18: 32.6 | G18: 3.7 | H18: Mn | I18: 246.3 | J18: 7.1 | K18: Mn | L18: 9 | M18: 0.78 | N18: Mn | Q18: Mn | R18: 544 | S18: 21 | T18: Mn | U18: =10.1*1000 -> 10100 | W18: Mn | Z18: Mn | AC18: Mn | AF18: Mn | AI18: Mn | AL18: Mn | AO18: Mn
C19: =C18+3 -> 44 | D19: =C19+1 -> 45 | E19: Fe | F19: 137 | G19: 17 | H19: Fe | I19: 367.5 | J19: 4.3 | K19: Fe | L19: 14.11 | M19: 0.33 | N19: Fe | O19: 115 | Q19: Fe | R19: =39.7*1000 -> 39700 | S19: =0.1*10*1000 -> 1000 | T19: Fe | U19: =33.8*1000 -> 33800 | W19: Fe | Z19: Fe | AC19: Fe | AF19: Fe | AI19: Fe | AL19: Fe | AO19: Fe
C20: =C19+3 -> 47 | D20: =C20+1 -> 48 | E20: Co | H20: Co | I20: 0.5773 | J20: 0.0071 | K20: Co | N20: Co | O20: 1.22 | Q20: Co | R20: 13.57 | S20: 0.43 | T20: Co | U20: 10 | W20: Co | Z20: Co | AC20: Co | AF20: Co | AI20: Co | AL20: Co | AO20: Co
C21: =C20+3 -> 50 | D21: =C21+1 -> 51 | E21: Ni | H21: Ni | I21: 1.582 | J21: 0.041 | K21: Ni | N21: Ni | Q21: Ni | R21: 42.9 | S21: 3.7 | T21: Ni | U21: 14.3 | V21: 1 | W21: Ni | Z21: Ni | AC21: Ni | AF21: Ni | AI21: Ni | AL21: Ni | AO21: Ni
C22: =C21+3 -> 53 | D22: =C22+1 -> 54 | E22: Cu | F22: 12.8 | G22: 2.8 | H22: Cu | I22: 4.7 | J22: 0.14 | K22: Cu | L22: 2.03 | M22: 0.14 | N22: Cu | Q22: Cu | T22: Cu | U22: 2950 | V22: 130 | W22: Cu | Z22: Cu | AC22: Cu | AF22: Cu | AI22: Cu | AL22: Cu | AO22: Cu
C23: =C22+3 -> 56 | D23: =C23+1 -> 57 | E23: Zn | F23: 35.9 | G23: 5.8 | H23: Zn | I23: 30.94 | J23: 0.55 | K23: Zn | L23: 11.61 | M23: 0.26 | N23: Zn | O23: 103 | Q23: Zn | R23: 408 | S23: 15 | T23: Zn | U23: 6952 | V23: 91 | W23: Zn | Z23: Zn | AC23: Zn | AF23: Zn | AI23: Zn | AL23: Zn | AO23: Zn
E24: Ga | H24: Ga | K24: Ga | N24: Ga | Q24: Ga | T24: Ga | U24: 34 | W24: Ga | Z24: Ga | AC24: Ga | AF24: Ga | AI24: Ga | AL24: Ga | AO24: Ga
E25: Ge | H25: Ge | K25: Ge | N25: Ge | Q25: Ge | T25: Ge | W25: Ge | Z25: Ge | AC25: Ge | AF25: Ge | AI25: Ge | AL25: Ge | AO25: Ge
E26: As | H26: As | I26: 0.1126 | J26: 0.0024 | K26: As | N26: As | Q26: As | R26: 17 | T26: As | U26: 626 | V26: 38 | W26: As | Z26: As | AC26: As | AF26: As | AI26: As | AL26: As | AO26: As
E27: Se | H27: Se | I27: 0.0543 | J27: 0.002 | K27: Se | L27: 1.14 | M27: 0.1 | N27: Se | Q27: Se | T27: Se | W27: Se | Z27: Se | AC27: Se | AF27: Se | AI27: Se | AL27: Se | AO27: Se
E28: Br | H28: Br | I28: 1300 | K28: Br | N28: Br | Q28: Br | T28: Br | U28: 6 | W28: Br | Z28: Br | AC28: Br | AF28: Br | AI28: Br | AL28: Br | AO28: Br
E29: Kr | H29: Kr | K29: Kr | N29: Kr | Q29: Kr | T29: Kr | W29: Kr | Z29: Kr | AC29: Kr | AF29: Kr | AI29: Kr | AL29: Kr | AO29: Kr
E30: Rb | H30: Rb | I30: 14.83 | J30: 0.31 | K30: Rb | L30: 0.671 | M30: 0.012 | N30: Rb | O30: 578 | Q30: Rb | T30: Rb | U30: 120 | W30: Rb | Z30: Rb | AC30: Rb | AF30: Rb | AI30: Rb | AL30: Rb | AO30: Rb
E31: Sr | H31: Sr | I31: 85 | K31: Sr | N31: Sr | Q31: Sr | T31: Sr | U31: 330 | W31: Sr | Z31: Sr | AC31: Sr | AF31: Sr | AI31: Sr | AL31: Sr | AO31: Sr
E32: Y | H32: Y | K32: Y | N32: Y | Q32: Y | T32: Y | U32: 23 | W32: Y | Z32: Y | AC32: Y | AF32: Y | AI32: Y | AL32: Y | AO32: Y
E33: Zr | H33: Zr | K33: Zr | N33: Zr | Q33: Zr | T33: Zr | W33: Zr | Z33: Zr | AC33: Zr | AF33: Zr | AI33: Zr | AL33: Zr | AO33: Zr
E34: Nb | H34: Nb | K34: Nb | N34: Nb | Q34: Nb | T34: Nb | W34: Nb | Z34: Nb | AC34: Nb | AF34: Nb | AI34: Nb | AL34: Nb | AO34: Nb
E35: Mo | H35: Mo | I35: 0.46 | K35: Mo | L35: 0.464 | M35: 0.034 | N35: Mo | Q35: Mo | T35: Mo | U35: 19 | W35: Mo | Z35: Mo | AC35: Mo | AF35: Mo | AI35: Mo | AL35: Mo | AO35: Mo
E36: Tc | H36: Tc | K36: Tc | N36: Tc | Q36: Tc | T36: Tc | W36: Tc | Z36: Tc | AC36: Tc | AF36: Tc | AI36: Tc | AL36: Tc | AO36: Tc
E37: Ru | H37: Ru | K37: Ru | N37: Ru | Q37: Ru | T37: Ru | W37: Ru | Z37: Ru | AC37: Ru | AF37: Ru | AI37: Ru | AL37: Ru | AO37: Ru
E38: Rh | H38: Rh | K38: Rh | N38: Rh | Q38: Rh | T38: Rh | W38: Rh | Z38: Rh | AC38: Rh | AF38: Rh | AI38: Rh | AL38: Rh | AO38: Rh
E39: Pd | H39: Pd | K39: Pd | N39: Pd | Q39: Pd | T39: Pd | W39: Pd | Z39: Pd | AC39: Pd | AF39: Pd | AI39: Pd | AL39: Pd | AO39: Pd
E40: Ag | H40: Ag | I40: 0.017 | K40: Ag | N40: Ag | Q40: Ag | T40: Ag | U40: 35.3 | V40: 1.5 | W40: Ag | Z40: Ag | AC40: Ag | AF40: Ag | AI40: Ag | AL40: Ag | AO40: Ag
E41: Cd | H41: Cd | I41: 1.517 | J41: 0.027 | K41: Cd | L41: 0.0254 | M41: 0.0009 | N41: Cd | Q41: Cd | R41: 2.94 | S41: 2.29 | T41: Cd | U41: 21.8 | V41: 0.2 | W41: Cd | Z41: Cd | AC41: Cd | AF41: Cd | AI41: Cd | AL41: Cd | AO41: Cd
...

Sheet Banco de Dados
B1: aa | D1: Calibração | J1: ab | L1: Padrão | R1: ac | S1: Amostra | Y1: ad | Z1: Amostra | AF1: ae | AG1: Amostra | AM1: af | AN1: Amostra | AT1: ag | AU1: Amostra | BA1: ah | BB1: Amostra | BH1: ai | BI1: Amostra | BO1: aj | BP1: Amostra | BV1: ak | BW1: Amostra | CC1: al | CD1: Amostra | CJ1: am | CK1: Amostra | CQ1: an | CR1: Amostra | CX1: ao | CY1: Amostra | DE1: ap | DF1: Amostra | DL1: aq | DM1: Amostra | DS1: ar | DT1: Amostra | DZ1: as | EA1: Amostra | EG1: at | EH1: Amostra | EN1: au | EO1: Amostra | EU1: av | EV1: Amostra | FB1: aw | FC1: Amostra | FI1: ax | FJ1: Amostra | FP1: ay | FQ1: Amostra | FW1: az | FX1: Amostra
A2: Condição uso de virgula ou ponto | B2: Correção | C2: Elemento | D2: Z | E2: Energia (KeV) | F2: Níveis | G2: Área (CPS) | H2: Erro (CPS) | J2: Correção | K2: Elemento | L2: Z | M2: Energia (KeV) | N2: Níveis | O2: Área (CPS) | P2: Erro (CPS) | R2: Elemento | S2: Z | T2: Energia (KeV) | U2: Níveis | V2: Área (CPS) | W2: Erro (CPS) | Y2: Elemento | Z2: Z | AA2: Energia (KeV) | AB2: Níveis | AC2: Área (CPS) | AD2: Erro (CPS) | AF2: Elemento | AG2: Z | AH2: Energia (KeV) | AI2: Níveis | AJ2: Área (CPS) | AK2: Erro (CPS) | AM2: Elemento | AN2: Z | AO2: Energia (KeV) | AP2: Níveis | AQ2: Área (CPS) | AR2: Erro (CPS) | AT2: Elemento | AU2: Z | AV2: Energia (KeV) | AW2: Níveis | AX2: Área (CPS) | AY2: Erro (CPS) | BA2: Elemento | BB2: Z | BC2: Energia (KeV) | BD2: Níveis | BE2: Área (CPS) | BF2: Erro (CPS) | BH2: Elemento | BI2: Z | BJ2: Energia (KeV) | BK2: Níveis | BL2: Área (CPS) | BM2: Erro (CPS) | BO2: Elemento | BP2: Z | BQ2: Energia (KeV) | BR2: Níveis | BS2: Área (CPS) | BT2: Erro (CPS) | BV2: Elemento | BW2: Z | BX2: Energia (KeV) | BY2: Níveis | BZ2: Área (CPS) | CA2: Erro (CPS) | CC2: Elemento | CD2: Z | CE2: Energia (KeV) | CF2: Níveis | CG2: Área (CPS) | CH2: Erro (CPS) | CJ2: Elemento | CK2: Z | CL2: Energia (KeV) | CM2: Níveis | CN2: Área (CPS) | CO2: Erro (CPS) | CQ2: Elemento | CR2: Z | CS2: Energia (KeV) | CT2: Níveis | CU2: Área (CPS) | CV2: Erro (CPS) | CX2: Elemento | CY2: Z | CZ2: Energia (KeV) | DA2: Níveis | DB2: Área (CPS) | DC2: Erro (CPS) | DE2: Elemento | DF2: Z | DG2: Energia (KeV) | DH2: Níveis | DI2: Área (CPS) | DJ2: Erro (CPS) | DL2: Elemento | DM2: Z | DN2: Energia (KeV) | DO2: Níveis | DP2: Área (CPS) | DQ2: Erro (CPS) | DS2: Elemento | DT2: Z | DU2: Energia (KeV) | DV2: Níveis | DW2: Área (CPS) | DX2: Erro (CPS) | DZ2: Elemento | EA2: Z | EB2: Energia (KeV) | EC2: Níveis | ED2: Área (CPS) | EE2: Erro (CPS) | EG2: Elemento | EH2: Z | EI2: Energia (KeV) | EJ2: Níveis | EK2: Área (CPS) | EL2: Erro (CPS) | EN2: Elemento | EO2: Z | EP2: Energia (KeV) | EQ2: Níveis | ER2: Área (CPS) | ES2: Erro (CPS) | EU2: Elemento | EV2: Z | EW2: Energia (KeV) | EX2: Níveis | EY2: Área (CPS) | EZ2: Erro (CPS) | FB2: Elemento | FC2: Z | FD2: Energia (KeV) | FE2: Níveis | FF2: Área (CPS) | FG2: Erro (CPS) | FI2: Elemento | FJ2: Z | FK2: Energia (KeV) | FL2: Níveis | FM2: Área (CPS) | FN2: Erro (CPS) | FP2: Elemento | FQ2: Z | FR2: Energia (KeV) | FS2: Níveis | FT2: Área (CPS) | FU2: Erro (CPS) | FW2: Elemento | FX2: Z | FY2: Energia (KeV) | FZ2: Níveis | GA2: Área (CPS) | GB2: Erro (CPS)
A3: =Dados!C2 -> Ponto | B3: =IF($A$3=$A$26,E3,E3*1000) -> 1487 | C3: Al | D3: =VLOOKUP(C3,$C$284:$D$377,2,FALSE) -> 13 | E3: 1.487 | F3: Kα | G3: {=_xlfn.XLOOKUP($B$3:$B$274,Dados!E5:E1048576,Dados!F5:F1048576,"")} | H3: {=_xlfn.XLOOKUP(_xlfn.ANCHORARRAY(G3),Dados!F5:F1048576,Dados!G5:G1048576,"")} | J3: =M3*1000 -> 1487 | K3: Al | L3: =VLOOKUP(K3,$C$284:$D$377,2,FALSE) -> 13 | M3: 1.487 | N3: Kα | O3: {=_xlfn.XLOOKUP($B$3:$B$274,Dados!L5:L1048576,Dados!M5:M1048576,"")} | P3: {=_xlfn.XLOOKUP(_xlfn.ANCHORARRAY(O3),Dados!M5:M1048576,Dados!N5:N1048576,"")} | R3: Al | S3: =VLOOKUP(R3,$C$284:$D$377,2,FALSE) -> 13 | T3: 1.487 | U3: Kα | V3: {=_xlfn.XLOOKUP($B$3:$B$274,Dados!S5:S1048576,Dados!T5:T1048576,"")} | W3: {=_xlfn.XLOOKUP(_xlfn.ANCHORARRAY(V3),Dados!T5:T1048576,Dados!U5:U1048576,"")} | Y3: Al | Z3: =VLOOKUP(Y3,$C$284:$D$377,2,FALSE) -> 13 | AA3: 1.487 | AB3: Kα | AC3: {=_xlfn.XLOOKUP($B$3:$B$274,Dados!Z5:Z1048576,Dados!AA5:AA1048576,"")} | AD3: {=_xlfn.XLOOKUP(_xlfn.ANCHORARRAY(AC3),Dados!AA5:AA1048576,Dados!AB5:AB1048576,"")} | AF3: Al | AG3: =VLOOKUP(AF3,$C$284:$D$377,2,FALSE) -> 13 | AH3: 1.487 | AI3: Kα | AJ3: {=_xlfn.XLOOKUP($B$3:$B$274,Dados!AG5:AG1048576,Dados!AH5:AH1048576,"")} | AK3: {=_xlfn.XLOOKUP(_xlfn.ANCHORARRAY(AJ3),Dados!AH5:AH1048576,Dados!AI5:AI1048576,"")} | AM3: Al | AN3: =VLOOKUP(AM3,$C$284:$D$377,2,FALSE) -> 13 | AO3: 1.487 | AP3: Kα | AQ3: {=_xlfn.XLOOKUP($B$3:$B$274,Dados!AN5:AN1048576,Dados!AO5:AO1048576,"")} | AR3: {=_xlfn.XLOOKUP(_xlfn.ANCHORARRAY(AQ3),Dados!AO5:AO1048576,Dados!AP5:AP1048576,"")} | AT3: Al | AU3: =VLOOKUP(AT3,$C$284:$D$377,2,FALSE) -> 13 | AV3: 1.487 | AW3: Kα | AX3: {=_xlfn.XLOOKUP($B$3:$B$274,Dados!AU5:AU1048576,Dados!AV5:AV1048576,"")} | AY3: {=_xlfn.XLOOKUP(_xlfn.ANCHORARRAY(AX3),Dados!AV5:AV1048576,Dados!AW5:AW1048576,"")} | BA3: Al | BB3: =VLOOKUP(BA3,$C$284:$D$377,2,FALSE) -> 13 | BC3: 1.487 | BD3: Kα | BE3: {=_xlfn.XLOOKUP($B$3:$B$274,Dados!BB5:BB1048576,Dados!BC5:BC1048576,"")} | BF3: {=_xlfn.XLOOKUP(_xlfn.ANCHORARRAY(BE3),Dados!BC5:BC1048576,Dados!BD5:BD1048576,"")} | BH3: Al | BI3: =VLOOKUP(BH3,$C$284:$D$377,2,FALSE) -> 13 | BJ3: 1.487 | BK3: Kα | BL3: {=_xlfn.XLOOKUP($B$3:$B$274,Dados!BI5:BI1048576,Dados!BJ5:BJ1048576,"")} | BM3: {=_xlfn.XLOOKUP(_xlfn.ANCHORARRAY(BL3),Dados!BJ5:BJ1048576,Dados!BK5:BK1048576,"")} | BO3: Al | BP3: =VLOOKUP(BO3,$C$284:$D$377,2,FALSE) -> 13 | BQ3: 1.487 | BR3: Kα | BS3: {=_xlfn.XLOOKUP($B$3:$B$274,Dados!BP5:BP1048576,Dados!BQ5:BQ1048576,"")} | BT3: {=_xlfn.XLOOKUP(_xlfn.ANCHORARRAY(BS3),Dados!BQ5:BQ1048576,Dados!BR5:BR1048576,"")} | BV3: Al | BW3: =VLOOKUP(BV3,$C$284:$D$377,2,FALSE) -> 13 | BX3: 1.487 | BY3: Kα | BZ3: {=_xlfn.XLOOKUP($B$3:$B$274,Dados!BW5:BW1048576,Dados!BX5:BX1048576,"")} | CA3: {=_xlfn.XLOOKUP(_xlfn.ANCHORARRAY(BZ3),Dados!BX5:BX1048576,Dados!BY5:BY1048576,"")} | CC3: Al | CD3: =VLOOKUP(CC3,$C$284:$D$377,2,FALSE) -> 13 | CE3: 1.487 | CF3: Kα | CG3: {=_xlfn.XLOOKUP($B$3:$B$274,Dados!CD5:CD1048576,Dados!CE5:CE1048576,"")} | CH3: {=_xlfn.XLOOKUP(_xlfn.ANCHORARRAY(CG3),Dados!CE5:CE1048576,Dados!CF5:CF1048576,"")} | CJ3: Al | CK3: =VLOOKUP(CJ3,$C$284:$D$377,2,FALSE) -> 13 | CL3: 1.487 | CM3: Kα | CN3: {=_xlfn.XLOOKUP($B$3:$B$274,Dados!CK5:CK1048576,Dados!CL5:CL1048576,"")} | CO3: {=_xlfn.XLOOKUP(_xlfn.ANCHORARRAY(CN3),Dados!CL5:CL1048576,Dados!CM5:CM1048576,"")} | CQ3: Al | CR3: =VLOOKUP(CQ3,$C$284:$D$377,2,FALSE) -> 13 | CS3: 1.487 | CT3: Kα | CU3: {=_xlfn.XLOOKUP($B$3:$B$274,Dados!CR5:CR1048576,Dados!CS5:CS1048576,"")} | CV3: {=_xlfn.XLOOKUP(_xlfn.ANCHORARRAY(CU3),Dados!CS5:CS1048576,Dados!CT5:CT1048576,"")} | CX3: Al | CY3: =VLOOKUP(CX3,$C$284:$D$377,2,FALSE) -> 13 | CZ3: 1.487 | DA3: Kα | DB3: {=_xlfn.XLOOKUP($B$3:$B$274,Dados!CY5:CY1048576,Dados!CZ5:CZ1048576,"")} | DC3: {=_xlfn.XLOOKUP(_xlfn.ANCHORARRAY(DB3),Dados!CZ5:CZ1048576,Dados!DA5:DA1048576,"")} | DE3: Al | DF3: =VLOOKUP(DE3,$C$284:$D$377,2,FALSE) -> 13 | DG3: 1.487 | DH3: Kα | DI3: {=_xlfn.XLOOKUP($B$3:$B$274,Dados!DF5:DF1048576,Dados!DG5:DG1048576,"")} | DJ3: {=_xlfn.XLOOKUP(_xlfn.ANCHORARRAY(DI3),Dados!DG5:DG1048576,Dados!DH5:DH1048576,"")} | DL3: Al | DM3: =VLOOKUP(DL3,$C$284:$D$377,2,FALSE) -> 13 | DN3: 1.487 | DO3: Kα | DP3: {=_xlfn.XLOOKUP($B$3:$B$274,Dados!DM5:DM1048576,Dados!DN5:DN1048576,"")} | DQ3: {=_xlfn.XLOOKUP(_xlfn.ANCHORARRAY(DP3),Dados!DN5:DN1048576,Dados!DO5:DO1048576,"")} | DS3: Al | DT3: =VLOOKUP(DS3,$C$284:$D$377,2,FALSE) -> 13 | DU3: 1.487 | DV3: Kα | DW3: {=_xlfn.XLOOKUP($B$3:$B$274,Dados!DT5:DT1048576,Dados!DU5:DU1048576,"")} | DX3: {=_xlfn.XLOOKUP(_xlfn.ANCHORARRAY(DW3),Dados!DU5:DU1048576,Dados!DV5:DV1048576,"")} | DZ3: Al | EA3: =VLOOKUP(DZ3,$C$284:$D$377,2,FALSE) -> 13 | EB3: 1.487 | EC3: Kα | ED3: {=_xlfn.XLOOKUP($B$3:$B$274,Dados!EA5:EA1048576,Dados!EB5:EB1048576,"")} | EE3: {=_xlfn.XLOOKUP(_xlfn.ANCHORARRAY(ED3),Dados!EB5:EB1048576,Dados!EC5:EC1048576,"")} | EG3: Al | EH3: =VLOOKUP(EG3,$C$284:$D$377,2,FALSE) -> 13 | EI3: 1.487 | EJ3: Kα | EK3: {=_xlfn.XLOOKUP($B$3:$B$274,Dados!EH5:EH1048576,Dados!EI5:EI1048576,"")} | EL3: {=_xlfn.XLOOKUP(_xlfn.ANCHORARRAY(EK3),Dados!EI5:EI1048576,Dados!EJ5:EJ1048576,"")} | EN3: Al | EO3: =VLOOKUP(EN3,$C$284:$D$377,2,FALSE) -> 13 | EP3: 1.487 | EQ3: Kα | ER3: {=_xlfn.XLOOKUP($B$3:$B$274,Dados!EO5:EO1048576,Dados!EP5:EP1048576,"")} | ES3: {=_xlfn.XLOOKUP(_xlfn.ANCHORARRAY(ER3),Dados!EP5:EP1048576,Dados!EQ5:EQ1048576,"")} | EU3: Al | EV3: =VLOOKUP(EU3,$C$284:$D$377,2,FALSE) -> 13 | EW3: 1.487 | EX3: Kα | EY3: {=_xlfn.XLOOKUP($B$3:$B$274,Dados!EV5:EV1048576,Dados!EW5:EW1048576,"")} | EZ3: {=_xlfn.XLOOKUP(_xlfn.ANCHORARRAY(EY3),Dados!EW5:EW1048576,Dados!EX5:EX1048576,"")} | FB3: Al | FC3: =VLOOKUP(FB3,$C$284:$D$377,2,FALSE) -> 13 | FD3: 1.487 | FE3: Kα | FF3: {=_xlfn.XLOOKUP($B$3:$B$274,Dados!FC5:FC1048576,Dados!FD5:FD1048576,"")} | FG3: {=_xlfn.XLOOKUP(_xlfn.ANCHORARRAY(FF3),Dados!FD5:FD1048576,Dados!FE5:FE1048576,"")} | FI3: Al | FJ3: =VLOOKUP(FI3,$C$284:$D$377,2,FALSE) -> 13 | FK3: 1.487 | FL3: Kα | FM3: {=_xlfn.XLOOKUP($B$3:$B$274,Dados!FJ5:FJ1048576,Dados!FK5:FK1048576,"")} | FN3: {=_xlfn.XLOOKUP(_xlfn.ANCHORARRAY(FM3),Dados!FK5:FK1048576,Dados!FL5:FL1048576,"")} | FP3: Al | FQ3: =VLOOKUP(FP3,$C$284:$D$377,2,FALSE) -> 13 | FR3: 1.487 | FS3: Kα | FT3: {=_xlfn.XLOOKUP($B$3:$B$274,Dados!FQ5:FQ1048576,Dados!FR5:FR1048576,"")} | FU3: {=_xlfn.XLOOKUP(_xlfn.ANCHORARRAY(FT3),Dados!FR5:FR1048576,Dados!FS5:FS1048576,"")} | FW3: Al | FX3: =VLOOKUP(FW3,$C$284:$D$377,2,FALSE) -> 13 | FY3: 1.487 | FZ3: Kα | GA3: {=_xlfn.XLOOKUP($B$3:$B$274,Dados!FX5:FX1048576,Dados!FY5:FY1048576,"")} | GB3: {=_xlfn.XLOOKUP(_xlfn.ANCHORARRAY(GA3),Dados!FY5:FY1048576,Dados!FZ5:FZ1048576,"")}
B4: =IF($A$3=$A$26,E4,E4*1000) -> 1553 | C4: Al | D4: =VLOOKUP(C4,$C$284:$D$377,2,FALSE) -> 13 | E4: 1.553 | F4: Kβ | J4: =M4*1000 -> 1553 | K4: Al | L4: =VLOOKUP(K4,$C$284:$D$377,2,FALSE) -> 13 | M4: 1.553 | N4: Kβ | R4: Al | S4: =VLOOKUP(R4,$C$284:$D$377,2,FALSE) -> 13 | T4: 1.553 | U4: Kβ | Y4: Al | Z4: =VLOOKUP(Y4,$C$284:$D$377,2,FALSE) -> 13 | AA4: 1.553 | AB4: Kβ | AF4: Al | AG4: =VLOOKUP(AF4,$C$284:$D$377,2,FALSE) -> 13 | AH4: 1.553 | AI4: Kβ | AM4: Al | AN4: =VLOOKUP(AM4,$C$284:$D$377,2,FALSE) -> 13 | AO4: 1.553 | AP4: Kβ | AT4: Al | AU4: =VLOOKUP(AT4,$C$284:$D$377,2,FALSE) -> 13 | AV4: 1.553 | AW4: Kβ | BA4: Al | BB4: =VLOOKUP(BA4,$C$284:$D$377,2,FALSE) -> 13 | BC4: 1.553 | BD4: Kβ | BH4: Al | BI4: =VLOOKUP(BH4,$C$284:$D$377,2,FALSE) -> 13 | BJ4: 1.553 | BK4: Kβ | BO4: Al | BP4: =VLOOKUP(BO4,$C$284:$D$377,2,FALSE) -> 13 | BQ4: 1.553 | BR4: Kβ | BV4: Al | BW4: =VLOOKUP(BV4,$C$284:$D$377,2,FALSE) -> 13 | BX4: 1.553 | BY4: Kβ | CC4: Al | CD4: =VLOOKUP(CC4,$C$284:$D$377,2,FALSE) -> 13 | CE4: 1.553 | CF4: Kβ | CJ4: Al | CK4: =VLOOKUP(CJ4,$C$284:$D$377,2,FALSE) -> 13 | CL4: 1.553 | CM4: Kβ | CQ4: Al | CR4: =VLOOKUP(CQ4,$C$284:$D$377,2,FALSE) -> 13 | CS4: 1.553 | CT4: Kβ | CX4: Al | CY4: =VLOOKUP(CX4,$C$284:$D$377,2,FALSE) -> 13 | CZ4: 1.553 | DA4: Kβ | DE4: Al | DF4: =VLOOKUP(DE4,$C$284:$D$377,2,FALSE) -> 13 | DG4: 1.553 | DH4: Kβ | DL4: Al | DM4: =VLOOKUP(DL4,$C$284:$D$377,2,FALSE) -> 13 | DN4: 1.553 | DO4: Kβ | DS4: Al | DT4: =VLOOKUP(DS4,$C$284:$D$377,2,FALSE) -> 13 | DU4: 1.553 | DV4: Kβ | DZ4: Al | EA4: =VLOOKUP(DZ4,$C$284:$D$377,2,FALSE) -> 13 | EB4: 1.553 | EC4: Kβ | EG4: Al | EH4: =VLOOKUP(EG4,$C$284:$D$377,2,FALSE) -> 13 | EI4: 1.553 | EJ4: Kβ | EN4: Al | EO4: =VLOOKUP(EN4,$C$284:$D$377,2,FALSE) -> 13 | EP4: 1.553 | EQ4: Kβ | EU4: Al | EV4: =VLOOKUP(EU4,$C$284:$D$377,2,FALSE) -> 13 | EW4: 1.553 | EX4: Kβ | FB4: Al | FC4: =VLOOKUP(FB4,$C$284:$D$377,2,FALSE) -> 13 | FD4: 1.553 | FE4: Kβ | FI4: Al | FJ4: =VLOOKUP(FI4,$C$284:$D$377,2,FALSE) -> 13 | FK4: 1.553 | FL4: Kβ | FP4: Al | FQ4: =VLOOKUP(FP4,$C$284:$D$377,2,FALSE) -> 13 | FR4: 1.553 | FS4: Kβ | FW4: Al | FX4: =VLOOKUP(FW4,$C$284:$D$377,2,FALSE) -> 13 | FY4: 1.553 | FZ4: Kβ
B5: =IF($A$3=$A$26,E5,E5*1000) -> 1740 | C5: Si | D5: =VLOOKUP(C5,$C$284:$D$377,2,FALSE) -> 14 | E5: 1.74 | F5: Kα | J5: =M5*1000 -> 1740 | K5: Si | L5: =VLOOKUP(K5,$C$284:$D$377,2,FALSE) -> 14 | M5: 1.74 | N5: Kα | R5: Si | S5: =VLOOKUP(R5,$C$284:$D$377,2,FALSE) -> 14 | T5: 1.74 | U5: Kα | V5: 4158 | W5: 86 | Y5: Si | Z5: =VLOOKUP(Y5,$C$284:$D$377,2,FALSE) -> 14 | AA5: 1.74 | AB5: Kα | AC5: 3391 | AD5: 79 | AF5: Si | AG5: =VLOOKUP(AF5,$C$284:$D$377,2,FALSE) -> 14 | AH5: 1.74 | AI5: Kα | AJ5: 4643 | AK5: 90 | AM5: Si | AN5: =VLOOKUP(AM5,$C$284:$D$377,2,FALSE) -> 14 | AO5: 1.74 | AP5: Kα | AQ5: 6800 | AR5: 107 | AT5: Si | AU5: =VLOOKUP(AT5,$C$284:$D$377,2,FALSE) -> 14 | AV5: 1.74 | AW5: Kα | AX5: 4273 | AY5: 70 | BA5: Si | BB5: =VLOOKUP(BA5,$C$284:$D$377,2,FALSE) -> 14 | BC5: 1.74 | BD5: Kα | BE5: 3929 | BF5: 86 | BH5: Si | BI5: =VLOOKUP(BH5,$C$284:$D$377,2,FALSE) -> 14 | BJ5: 1.74 | BK5: Kα | BL5: 5428 | BM5: 100 | BO5: Si | BP5: =VLOOKUP(BO5,$C$284:$D$377,2,FALSE) -> 14 | BQ5: 1.74 | BR5: Kα | BS5: 7268 | BT5: 113 | BV5: Si | BW5: =VLOOKUP(BV5,$C$284:$D$377,2,FALSE) -> 14 | BX5: 1.74 | BY5: Kα | BZ5: 5318 | CA5: 97 | CC5: Si | CD5: =VLOOKUP(CC5,$C$284:$D$377,2,FALSE) -> 14 | CE5: 1.74 | CF5: Kα | CG5: 11218 | CH5: 130 | CJ5: Si | CK5: =VLOOKUP(CJ5,$C$284:$D$377,2,FALSE) -> 14 | CL5: 1.74 | CM5: Kα | CQ5: Si | CR5: =VLOOKUP(CQ5,$C$284:$D$377,2,FALSE) -> 14 | CS5: 1.74 | CT5: Kα | CX5: Si | CY5: =VLOOKUP(CX5,$C$284:$D$377,2,FALSE) -> 14 | CZ5: 1.74 | DA5: Kα | DE5: Si | DF5: =VLOOKUP(DE5,$C$284:$D$377,2,FALSE) -> 14 | DG5: 1.74 | DH5: Kα | DL5: Si | DM5: =VLOOKUP(DL5,$C$284:$D$377,2,FALSE) -> 14 | DN5: 1.74 | DO5: Kα | DS5: Si | DT5: =VLOOKUP(DS5,$C$284:$D$377,2,FALSE) -> 14 | DU5: 1.74 | DV5: Kα | DZ5: Si | EA5: =VLOOKUP(DZ5,$C$284:$D$377,2,FALSE) -> 14 | EB5: 1.74 | EC5: Kα | EG5: Si | EH5: =VLOOKUP(EG5,$C$284:$D$377,2,FALSE) -> 14 | EI5: 1.74 | EJ5: Kα | EN5: Si | EO5: =VLOOKUP(EN5,$C$284:$D$377,2,FALSE) -> 14 | EP5: 1.74 | EQ5: Kα | EU5: Si | EV5: =VLOOKUP(EU5,$C$284:$D$377,2,FALSE) -> 14 | EW5: 1.74 | EX5: Kα | FB5: Si | FC5: =VLOOKUP(FB5,$C$284:$D$377,2,FALSE) -> 14 | FD5: 1.74 | FE5: Kα | FI5: Si | FJ5: =VLOOKUP(FI5,$C$284:$D$377,2,FALSE) -> 14 | FK5: 1.74 | FL5: Kα | FP5: Si | FQ5: =VLOOKUP(FP5,$C$284:$D$377,2,FALSE) -> 14 | FR5: 1.74 | FS5: Kα | FW5: Si | FX5: =VLOOKUP(FW5,$C$284:$D$377,2,FALSE) -> 14 | FY5: 1.74 | FZ5: Kα
B6: =IF($A$3=$A$26,E6,E6*1000) -> 1832 | C6: Si | D6: =VLOOKUP(C6,$C$284:$D$377,2,FALSE) -> 14 | E6: 1.832 | F6: Kβ | J6: =M6*1000 -> 1832 | K6: Si | L6: =VLOOKUP(K6,$C$284:$D$377,2,FALSE) -> 14 | M6: 1.832 | N6: Kβ | R6: Si | S6: =VLOOKUP(R6,$C$284:$D$377,2,FALSE) -> 14 | T6: 1.832 | U6: Kβ | Y6: Si | Z6: =VLOOKUP(Y6,$C$284:$D$377,2,FALSE) -> 14 | AA6: 1.832 | AB6: Kβ | AF6: Si | AG6: =VLOOKUP(AF6,$C$284:$D$377,2,FALSE) -> 14 | AH6: 1.832 | AI6: Kβ | AM6: Si | AN6: =VLOOKUP(AM6,$C$284:$D$377,2,FALSE) -> 14 | AO6: 1.832 | AP6: Kβ | AT6: Si | AU6: =VLOOKUP(AT6,$C$284:$D$377,2,FALSE) -> 14 | AV6: 1.832 | AW6: Kβ | BA6: Si | BB6: =VLOOKUP(BA6,$C$284:$D$377,2,FALSE) -> 14 | BC6: 1.832 | BD6: Kβ | BH6: Si | BI6: =VLOOKUP(BH6,$C$284:$D$377,2,FALSE) -> 14 | BJ6: 1.832 | BK6: Kβ | BO6: Si | BP6: =VLOOKUP(BO6,$C$284:$D$377,2,FALSE) -> 14 | BQ6: 1.832 | BR6: Kβ | BV6: Si | BW6: =VLOOKUP(BV6,$C$284:$D$377,2,FALSE) -> 14 | BX6: 1.832 | BY6: Kβ | CC6: Si | CD6: =VLOOKUP(CC6,$C$284:$D$377,2,FALSE) -> 14 | CE6: 1.832 | CF6: Kβ | CJ6: Si | CK6: =VLOOKUP(CJ6,$C$284:$D$377,2,FALSE) -> 14 | CL6: 1.832 | CM6: Kβ | CQ6: Si | CR6: =VLOOKUP(CQ6,$C$284:$D$377,2,FALSE) -> 14 | CS6: 1.832 | CT6: Kβ | CX6: Si | CY6: =VLOOKUP(CX6,$C$284:$D$377,2,FALSE) -> 14 | CZ6: 1.832 | DA6: Kβ | DE6: Si | DF6: =VLOOKUP(DE6,$C$284:$D$377,2,FALSE) -> 14 | DG6: 1.832 | DH6: Kβ | DL6: Si | DM6: =VLOOKUP(DL6,$C$284:$D$377,2,FALSE) -> 14 | DN6: 1.832 | DO6: Kβ | DS6: Si | DT6: =VLOOKUP(DS6,$C$284:$D$377,2,FALSE) -> 14 | DU6: 1.832 | DV6: Kβ | DZ6: Si | EA6: =VLOOKUP(DZ6,$C$284:$D$377,2,FALSE) -> 14 | EB6: 1.832 | EC6: Kβ | EG6: Si | EH6: =VLOOKUP(EG6,$C$284:$D$377,2,FALSE) -> 14 | EI6: 1.832 | EJ6: Kβ | EN6: Si | EO6: =VLOOKUP(EN6,$C$284:$D$377,2,FALSE) -> 14 | EP6: 1.832 | EQ6: Kβ | EU6: Si | EV6: =VLOOKUP(EU6,$C$284:$D$377,2,FALSE) -> 14 | EW6: 1.832 | EX6: Kβ | FB6: Si | FC6: =VLOOKUP(FB6,$C$284:$D$377,2,FALSE) -> 14 | FD6: 1.832 | FE6: Kβ | FI6: Si | FJ6: =VLOOKUP(FI6,$C$284:$D$377,2,FALSE) -> 14 | FK6: 1.832 | FL6: Kβ | FP6: Si | FQ6: =VLOOKUP(FP6,$C$284:$D$377,2,FALSE) -> 14 | FR6: 1.832 | FS6: Kβ | FW6: Si | FX6: =VLOOKUP(FW6,$C$284:$D$377,2,FALSE) -> 14 | FY6: 1.832 | FZ6: Kβ
B7: =IF($A$3=$A$26,E7,E7*1000) -> 2013 | C7: P | D7: =VLOOKUP(C7,$C$284:$D$377,2,FALSE) -> 15 | E7: 2.013 | F7: Kα | J7: =M7*1000 -> 2013 | K7: P | L7: =VLOOKUP(K7,$C$284:$D$377,2,FALSE) -> 15 | M7: 2.013 | N7: Kα | O7: 968 | P7: 104 | R7: P | S7: =VLOOKUP(R7,$C$284:$D$377,2,FALSE) -> 15 | T7: 2.013 | U7: Kα | V7: 831 | W7: 71 | Y7: P | Z7: =VLOOKUP(Y7,$C$284:$D$377,2,FALSE) -> 15 | AA7: 2.013 | AB7: Kα | AC7: 630 | AD7: 71 | AF7: P | AG7: =VLOOKUP(AF7,$C$284:$D$377,2,FALSE) -> 15 | AH7: 2.013 | AI7: Kα | AJ7: 767 | AK7: 72 | AM7: P | AN7: =VLOOKUP(AM7,$C$284:$D$377,2,FALSE) -> 15 | AO7: 2.013 | AP7: Kα | AQ7: 602 | AR7: 74 | AT7: P | AU7: =VLOOKUP(AT7,$C$284:$D$377,2,FALSE) -> 15 | AV7: 2.013 | AW7: Kα | AX7: 476 | AY7: 36 | BA7: P | BB7: =VLOOKUP(BA7,$C$284:$D$377,2,FALSE) -> 15 | BC7: 2.013 | BD7: Kα | BE7: 981 | BF7: 77 | BH7: P | BI7: =VLOOKUP(BH7,$C$284:$D$377,2,FALSE) -> 15 | BJ7: 2.013 | BK7: Kα | BL7: 731 | BM7: 76 | BO7: P | BP7: =VLOOKUP(BO7,$C$284:$D$377,2,FALSE) -> 15 | BQ7: 2.013 | BR7: Kα | BS7: 1144 | BT7: 83 | BV7: P | BW7: =VLOOKUP(BV7,$C$284:$D$377,2,FALSE) -> 15 | BX7: 2.013 | BY7: Kα | BZ7: 1154 | CA7: 80 | CC7: P | CD7: =VLOOKUP(CC7,$C$284:$D$377,2,FALSE) -> 15 | CE7: 2.013 | CF7: Kα | CG7: 1186 | CH7: 81 | CJ7: P | CK7: =VLOOKUP(CJ7,$C$284:$D$377,2,FALSE) -> 15 | CL7: 2.013 | CM7: Kα | CQ7: P | CR7: =VLOOKUP(CQ7,$C$284:$D$377,2,FALSE) -> 15 | CS7: 2.013 | CT7: Kα | CX7: P | CY7: =VLOOKUP(CX7,$C$284:$D$377,2,FALSE) -> 15 | CZ7: 2.013 | DA7: Kα | DE7: P | DF7: =VLOOKUP(DE7,$C$284:$D$377,2,FALSE) -> 15 | DG7: 2.013 | DH7: Kα | DL7: P | DM7: =VLOOKUP(DL7,$C$284:$D$377,2,FALSE) -> 15 | DN7: 2.013 | DO7: Kα | DS7: P | DT7: =VLOOKUP(DS7,$C$284:$D$377,2,FALSE) -> 15 | DU7: 2.013 | DV7: Kα | DZ7: P | EA7: =VLOOKUP(DZ7,$C$284:$D$377,2,FALSE) -> 15 | EB7: 2.013 | EC7: Kα | EG7: P | EH7: =VLOOKUP(EG7,$C$284:$D$377,2,FALSE) -> 15 | EI7: 2.013 | EJ7: Kα | EN7: P | EO7: =VLOOKUP(EN7,$C$284:$D$377,2,FALSE) -> 15 | EP7: 2.013 | EQ7: Kα | EU7: P | EV7: =VLOOKUP(EU7,$C$284:$D$377,2,FALSE) -> 15 | EW7: 2.013 | EX7: Kα | FB7: P | FC7: =VLOOKUP(FB7,$C$284:$D$377,2,FALSE) -> 15 | FD7: 2.013 | FE7: Kα | FI7: P | FJ7: =VLOOKUP(FI7,$C$284:$D$377,2,FALSE) -> 15 | FK7: 2.013 | FL7: Kα | FP7: P | FQ7: =VLOOKUP(FP7,$C$284:$D$377,2,FALSE) -> 15 | FR7: 2.013 | FS7: Kα | FW7: P | FX7: =VLOOKUP(FW7,$C$284:$D$377,2,FALSE) -> 15 | FY7: 2.013 | FZ7: Kα
B8: =IF($A$3=$A$26,E8,E8*1000) -> 2136 | C8: P | D8: =VLOOKUP(C8,$C$284:$D$377,2,FALSE) -> 15 | E8: 2.136 | F8: Kβ | J8: =M8*1000 -> 2136 | K8: P | L8: =VLOOKUP(K8,$C$284:$D$377,2,FALSE) -> 15 | M8: 2.136 | N8: Kβ | R8: P | S8: =VLOOKUP(R8,$C$284:$D$377,2,FALSE) -> 15 | T8: 2.136 | U8: Kβ | Y8: P | Z8: =VLOOKUP(Y8,$C$284:$D$377,2,FALSE) -> 15 | AA8: 2.136 | AB8: Kβ | AF8: P | AG8: =VLOOKUP(AF8,$C$284:$D$377,2,FALSE) -> 15 | AH8: 2.136 | AI8: Kβ | AM8: P | AN8: =VLOOKUP(AM8,$C$284:$D$377,2,FALSE) -> 15 | AO8: 2.136 | AP8: Kβ | AT8: P | AU8: =VLOOKUP(AT8,$C$284:$D$377,2,FALSE) -> 15 | AV8: 2.136 | AW8: Kβ | BA8: P | BB8: =VLOOKUP(BA8,$C$284:$D$377,2,FALSE) -> 15 | BC8: 2.136 | BD8: Kβ | BH8: P | BI8: =VLOOKUP(BH8,$C$284:$D$377,2,FALSE) -> 15 | BJ8: 2.136 | BK8: Kβ | BO8: P | BP8: =VLOOKUP(BO8,$C$284:$D$377,2,FALSE) -> 15 | BQ8: 2.136 | BR8: Kβ | BV8: P | BW8: =VLOOKUP(BV8,$C$284:$D$377,2,FALSE) -> 15 | BX8: 2.136 | BY8: Kβ | CC8: P | CD8: =VLOOKUP(CC8,$C$284:$D$377,2,FALSE) -> 15 | CE8: 2.136 | CF8: Kβ | CJ8: P | CK8: =VLOOKUP(CJ8,$C$284:$D$377,2,FALSE) -> 15 | CL8: 2.136 | CM8: Kβ | CQ8: P | CR8: =VLOOKUP(CQ8,$C$284:$D$377,2,FALSE) -> 15 | CS8: 2.136 | CT8: Kβ | CX8: P | CY8: =VLOOKUP(CX8,$C$284:$D$377,2,FALSE) -> 15 | CZ8: 2.136 | DA8: Kβ | DE8: P | DF8: =VLOOKUP(DE8,$C$284:$D$377,2,FALSE) -> 15 | DG8: 2.136 | DH8: Kβ | DL8: P | DM8: =VLOOKUP(DL8,$C$284:$D$377,2,FALSE) -> 15 | DN8: 2.136 | DO8: Kβ | DS8: P | DT8: =VLOOKUP(DS8,$C$284:$D$377,2,FALSE) -> 15 | DU8: 2.136 | DV8: Kβ | DZ8: P | EA8: =VLOOKUP(DZ8,$C$284:$D$377,2,FALSE) -> 15 | EB8: 2.136 | EC8: Kβ | EG8: P | EH8: =VLOOKUP(EG8,$C$284:$D$377,2,FALSE) -> 15 | EI8: 2.136 | EJ8: Kβ | EN8: P | EO8: =VLOOKUP(EN8,$C$284:$D$377,2,FALSE) -> 15 | EP8: 2.136 | EQ8: Kβ | EU8: P | EV8: =VLOOKUP(EU8,$C$284:$D$377,2,FALSE) -> 15 | EW8: 2.136 | EX8: Kβ | FB8: P | FC8: =VLOOKUP(FB8,$C$284:$D$377,2,FALSE) -> 15 | FD8: 2.136 | FE8: Kβ | FI8: P | FJ8: =VLOOKUP(FI8,$C$284:$D$377,2,FALSE) -> 15 | FK8: 2.136 | FL8: Kβ | FP8: P | FQ8: =VLOOKUP(FP8,$C$284:$D$377,2,FALSE) -> 15 | FR8: 2.136 | FS8: Kβ | FW8: P | FX8: =VLOOKUP(FW8,$C$284:$D$377,2,FALSE) -> 15 | FY8: 2.136 | FZ8: Kβ
B9: =IF($A$3=$A$26,E9,E9*1000) -> 2307 | C9: S | D9: =VLOOKUP(C9,$C$284:$D$377,2,FALSE) -> 16 | E9: 2.307 | F9: Kα | J9: =M9*1000 -> 2307 | K9: S | L9: =VLOOKUP(K9,$C$284:$D$377,2,FALSE) -> 16 | M9: 2.307 | N9: Kα | O9: 19589 | P9: 183 | R9: S | S9: =VLOOKUP(R9,$C$284:$D$377,2,FALSE) -> 16 | T9: 2.307 | U9: Kα | V9: 3751 | W9: 99 | Y9: S | Z9: =VLOOKUP(Y9,$C$284:$D$377,2,FALSE) -> 16 | AA9: 2.307 | AB9: Kα | AC9: 3279 | AD9: 99 | AF9: S | AG9: =VLOOKUP(AF9,$C$284:$D$377,2,FALSE) -> 16 | AH9: 2.307 | AI9: Kα | AJ9: 2989 | AK9: 96 | AM9: S | AN9: =VLOOKUP(AM9,$C$284:$D$377,2,FALSE) -> 16 | AO9: 2.307 | AP9: Kα | AQ9: 4373 | AR9: 106 | AT9: S | AU9: =VLOOKUP(AT9,$C$284:$D$377,2,FALSE) -> 16 | AV9: 2.307 | AW9: Kα | AX9: 2592 | AY9: 72 | BA9: S | BB9: =VLOOKUP(BA9,$C$284:$D$377,2,FALSE) -> 16 | BC9: 2.307 | BD9: Kα | BE9: 4039 | BF9: 105 | BH9: S | BI9: =VLOOKUP(BH9,$C$284:$D$377,2,FALSE) -> 16 | BJ9: 2.307 | BK9: Kα | BL9: 3350 | BM9: 101 | BO9: S | BP9: =VLOOKUP(BO9,$C$284:$D$377,2,FALSE) -> 16 | BQ9: 2.307 | BR9: Kα | BS9: 4134 | BT9: 108 | BV9: S | BW9: =VLOOKUP(BV9,$C$284:$D$377,2,FALSE) -> 16 | BX9: 2.307 | BY9: Kα | BZ9: 4221 | CA9: 106 | CC9: S | CD9: =VLOOKUP(CC9,$C$284:$D$377,2,FALSE) -> 16 | CE9: 2.307 | CF9: Kα | CG9: 2535 | CH9: 95 | CJ9: S | CK9: =VLOOKUP(CJ9,$C$284:$D$377,2,FALSE) -> 16 | CL9: 2.307 | CM9: Kα | CQ9: S | CR9: =VLOOKUP(CQ9,$C$284:$D$377,2,FALSE) -> 16 | CS9: 2.307 | CT9: Kα | CX9: S | CY9: =VLOOKUP(CX9,$C$284:$D$377,2,FALSE) -> 16 | CZ9: 2.307 | DA9: Kα | DE9: S | DF9: =VLOOKUP(DE9,$C$284:$D$377,2,FALSE) -> 16 | DG9: 2.307 | DH9: Kα | DL9: S | DM9: =VLOOKUP(DL9,$C$284:$D$377,2,FALSE) -> 16 | DN9: 2.307 | DO9: Kα | DS9: S | DT9: =VLOOKUP(DS9,$C$284:$D$377,2,FALSE) -> 16 | DU9: 2.307 | DV9: Kα | DZ9: S | EA9: =VLOOKUP(DZ9,$C$284:$D$377,2,FALSE) -> 16 | EB9: 2.307 | EC9: Kα | EG9: S | EH9: =VLOOKUP(EG9,$C$284:$D$377,2,FALSE) -> 16 | EI9: 2.307 | EJ9: Kα | EN9: S | EO9: =VLOOKUP(EN9,$C$284:$D$377,2,FALSE) -> 16 | EP9: 2.307 | EQ9: Kα | EU9: S | EV9: =VLOOKUP(EU9,$C$284:$D$377,2,FALSE) -> 16 | EW9: 2.307 | EX9: Kα | FB9: S | FC9: =VLOOKUP(FB9,$C$284:$D$377,2,FALSE) -> 16 | FD9: 2.307 | FE9: Kα | FI9: S | FJ9: =VLOOKUP(FI9,$C$284:$D$377,2,FALSE) -> 16 | FK9: 2.307 | FL9: Kα | FP9: S | FQ9: =VLOOKUP(FP9,$C$284:$D$377,2,FALSE) -> 16 | FR9: 2.307 | FS9: Kα | FW9: S | FX9: =VLOOKUP(FW9,$C$284:$D$377,2,FALSE) -> 16 | FY9: 2.307 | FZ9: Kα
B10: =IF($A$3=$A$26,E10,E10*1000) -> 2464 | C10: S | D10: =VLOOKUP(C10,$C$284:$D$377,2,FALSE) -> 16 | E10: 2.464 | F10: Kβ | J10: =M10*1000 -> 2464 | K10: S | L10: =VLOOKUP(K10,$C$284:$D$377,2,FALSE) -> 16 | M10: 2.464 | N10: Kβ | R10: S | S10: =VLOOKUP(R10,$C$284:$D$377,2,FALSE) -> 16 | T10: 2.464 | U10: Kβ | Y10: S | Z10: =VLOOKUP(Y10,$C$284:$D$377,2,FALSE) -> 16 | AA10: 2.464 | AB10: Kβ | AF10: S | AG10: =VLOOKUP(AF10,$C$284:$D$377,2,FALSE) -> 16 | AH10: 2.464 | AI10: Kβ | AM10: S | AN10: =VLOOKUP(AM10,$C$284:$D$377,2,FALSE) -> 16 | AO10: 2.464 | AP10: Kβ | AT10: S | AU10: =VLOOKUP(AT10,$C$284:$D$377,2,FALSE) -> 16 | AV10: 2.464 | AW10: Kβ | BA10: S | BB10: =VLOOKUP(BA10,$C$284:$D$377,2,FALSE) -> 16 | BC10: 2.464 | BD10: Kβ | BH10: S | BI10: =VLOOKUP(BH10,$C$284:$D$377,2,FALSE) -> 16 | BJ10: 2.464 | BK10: Kβ | BO10: S | BP10: =VLOOKUP(BO10,$C$284:$D$377,2,FALSE) -> 16 | BQ10: 2.464 | BR10: Kβ | BV10: S | BW10: =VLOOKUP(BV10,$C$284:$D$377,2,FALSE) -> 16 | BX10: 2.464 | BY10: Kβ | CC10: S | CD10: =VLOOKUP(CC10,$C$284:$D$377,2,FALSE) -> 16 | CE10: 2.464 | CF10: Kβ | CJ10: S | CK10: =VLOOKUP(CJ10,$C$284:$D$377,2,FALSE) -> 16 | CL10: 2.464 | CM10: Kβ | CQ10: S | CR10: =VLOOKUP(CQ10,$C$284:$D$377,2,FALSE) -> 16 | CS10: 2.464 | CT10: Kβ | CX10: S | CY10: =VLOOKUP(CX10,$C$284:$D$377,2,FALSE) -> 16 | CZ10: 2.464 | DA10: Kβ | DE10: S | DF10: =VLOOKUP(DE10,$C$284:$D$377,2,FALSE) -> 16 | DG10: 2.464 | DH10: Kβ | DL10: S | DM10: =VLOOKUP(DL10,$C$284:$D$377,2,FALSE) -> 16 | DN10: 2.464 | DO10: Kβ | DS10: S | DT10: =VLOOKUP(DS10,$C$284:$D$377,2,FALSE) -> 16 | DU10: 2.464 | DV10: Kβ | DZ10: S | EA10: =VLOOKUP(DZ10,$C$284:$D$377,2,FALSE) -> 16 | EB10: 2.464 | EC10: Kβ | EG10: S | EH10: =VLOOKUP(EG10,$C$284:$D$377,2,FALSE) -> 16 | EI10: 2.464 | EJ10: Kβ | EN10: S | EO10: =VLOOKUP(EN10,$C$284:$D$377,2,FALSE) -> 16 | EP10: 2.464 | EQ10: Kβ | EU10: S | EV10: =VLOOKUP(EU10,$C$284:$D$377,2,FALSE) -> 16 | EW10: 2.464 | EX10: Kβ | FB10: S | FC10: =VLOOKUP(FB10,$C$284:$D$377,2,FALSE) -> 16 | FD10: 2.464 | FE10: Kβ | FI10: S | FJ10: =VLOOKUP(FI10,$C$284:$D$377,2,FALSE) -> 16 | FK10: 2.464 | FL10: Kβ | FP10: S | FQ10: =VLOOKUP(FP10,$C$284:$D$377,2,FALSE) -> 16 | FR10: 2.464 | FS10: Kβ | FW10: S | FX10: =VLOOKUP(FW10,$C$284:$D$377,2,FALSE) -> 16 | FY10: 2.464 | FZ10: Kβ
B11: =IF($A$3=$A$26,E11,E11*1000) -> 2622 | C11: Cl | D11: =VLOOKUP(C11,$C$284:$D$377,2,FALSE) -> 17 | E11: 2.622 | F11: Kα | J11: =M11*1000 -> 2622 | K11: Cl | L11: =VLOOKUP(K11,$C$284:$D$377,2,FALSE) -> 17 | M11: 2.622 | N11: Kα | O11: 29684 | P11: 255 | R11: Cl | S11: =VLOOKUP(R11,$C$284:$D$377,2,FALSE) -> 17 | T11: 2.622 | U11: Kα | V11: 8237 | W11: 160 | Y11: Cl | Z11: =VLOOKUP(Y11,$C$284:$D$377,2,FALSE) -> 17 | AA11: 2.622 | AB11: Kα | AC11: 11608 | AD11: 176 | AF11: Cl | AG11: =VLOOKUP(AF11,$C$284:$D$377,2,FALSE) -> 17 | AH11: 2.622 | AI11: Kα | AJ11: 9237 | AK11: 164 | AM11: Cl | AN11: =VLOOKUP(AM11,$C$284:$D$377,2,FALSE) -> 17 | AO11: 2.622 | AP11: Kα | AQ11: 8287 | AR11: 161 | AT11: Cl | AU11: =VLOOKUP(AT11,$C$284:$D$377,2,FALSE) -> 17 | AV11: 2.622 | AW11: Kα | AX11: 9118 | AY11: 127 | BA11: Cl | BB11: =VLOOKUP(BA11,$C$284:$D$377,2,FALSE) -> 17 | BC11: 2.622 | BD11: Kα | BE11: 12017 | BF11: 179 | BH11: Cl | BI11: =VLOOKUP(BH11,$C$284:$D$377,2,FALSE) -> 17 | BJ11: 2.622 | BK11: Kα | BL11: 9250 | BM11: 166 | BO11: Cl | BP11: =VLOOKUP(BO11,$C$284:$D$377,2,FALSE) -> 17 | BQ11: 2.622 | BR11: Kα | BS11: 12390 | BT11: 180 | BV11: Cl | BW11: =VLOOKUP(BV11,$C$284:$D$377,2,FALSE) -> 17 | BX11: 2.622 | BY11: Kα | BZ11: 8981 | CA11: 165 | CC11: Cl | CD11: =VLOOKUP(CC11,$C$284:$D$377,2,FALSE) -> 17 | CE11: 2.622 | CF11: Kα | CG11: 6433 | CH11: 150 | CJ11: Cl | CK11: =VLOOKUP(CJ11,$C$284:$D$377,2,FALSE) -> 17 | CL11: 2.622 | CM11: Kα | CQ11: Cl | CR11: =VLOOKUP(CQ11,$C$284:$D$377,2,FALSE) -> 17 | CS11: 2.622 | CT11: Kα | CX11: Cl | CY11: =VLOOKUP(CX11,$C$284:$D$377,2,FALSE) -> 17 | CZ11: 2.622 | DA11: Kα | DE11: Cl | DF11: =VLOOKUP(DE11,$C$284:$D$377,2,FALSE) -> 17 | DG11: 2.622 | DH11: Kα | DL11: Cl | DM11: =VLOOKUP(DL11,$C$284:$D$377,2,FALSE) -> 17 | DN11: 2.622 | DO11: Kα | DS11: Cl | DT11: =VLOOKUP(DS11,$C$284:$D$377,2,FALSE) -> 17 | DU11: 2.622 | DV11: Kα | DZ11: Cl | EA11: =VLOOKUP(DZ11,$C$284:$D$377,2,FALSE) -> 17 | EB11: 2.622 | EC11: Kα | EG11: Cl | EH11: =VLOOKUP(EG11,$C$284:$D$377,2,FALSE) -> 17 | EI11: 2.622 | EJ11: Kα | EN11: Cl | EO11: =VLOOKUP(EN11,$C$284:$D$377,2,FALSE) -> 17 | EP11: 2.622 | EQ11: Kα | EU11: Cl | EV11: =VLOOKUP(EU11,$C$284:$D$377,2,FALSE) -> 17 | EW11: 2.622 | EX11: Kα | FB11: Cl | FC11: =VLOOKUP(FB11,$C$284:$D$377,2,FALSE) -> 17 | FD11: 2.622 | FE11: Kα | FI11: Cl | FJ11: =VLOOKUP(FI11,$C$284:$D$377,2,FALSE) -> 17 | FK11: 2.622 | FL11: Kα | FP11: Cl | FQ11: =VLOOKUP(FP11,$C$284:$D$377,2,FALSE) -> 17 | FR11: 2.622 | FS11: Kα | FW11: Cl | FX11: =VLOOKUP(FW11,$C$284:$D$377,2,FALSE) -> 17 | FY11: 2.622 | FZ11: Kα
B12: =IF($A$3=$A$26,E12,E12*1000) -> 2815 | C12: Cl | D12: =VLOOKUP(C12,$C$284:$D$377,2,FALSE) -> 17 | E12: 2.815 | F12: Kβ | J12: =M12*1000 -> 2815 | K12: Cl | L12: =VLOOKUP(K12,$C$284:$D$377,2,FALSE) -> 17 | M12: 2.815 | N12: Kβ | R12: Cl | S12: =VLOOKUP(R12,$C$284:$D$377,2,FALSE) -> 17 | T12: 2.815 | U12: Kβ | Y12: Cl | Z12: =VLOOKUP(Y12,$C$284:$D$377,2,FALSE) -> 17 | AA12: 2.815 | AB12: Kβ | AF12: Cl | AG12: =VLOOKUP(AF12,$C$284:$D$377,2,FALSE) -> 17 | AH12: 2.815 | AI12: Kβ | AM12: Cl | AN12: =VLOOKUP(AM12,$C$284:$D$377,2,FALSE) -> 17 | AO12: 2.815 | AP12: Kβ | AT12: Cl | AU12: =VLOOKUP(AT12,$C$284:$D$377,2,FALSE) -> 17 | AV12: 2.815 | AW12: Kβ | BA12: Cl | BB12: =VLOOKUP(BA12,$C$284:$D$377,2,FALSE) -> 17 | BC12: 2.815 | BD12: Kβ | BH12: Cl | BI12: =VLOOKUP(BH12,$C$284:$D$377,2,FALSE) -> 17 | BJ12: 2.815 | BK12: Kβ | BO12: Cl | BP12: =VLOOKUP(BO12,$C$284:$D$377,2,FALSE) -> 17 | BQ12: 2.815 | BR12: Kβ | BV12: Cl | BW12: =VLOOKUP(BV12,$C$284:$D$377,2,FALSE) -> 17 | BX12: 2.815 | BY12: Kβ | CC12: Cl | CD12: =VLOOKUP(CC12,$C$284:$D$377,2,FALSE) -> 17 | CE12: 2.815 | CF12: Kβ | CJ12: Cl | CK12: =VLOOKUP(CJ12,$C$284:$D$377,2,FALSE) -> 17 | CL12: 2.815 | CM12: Kβ | CQ12: Cl | CR12: =VLOOKUP(CQ12,$C$284:$D$377,2,FALSE) -> 17 | CS12: 2.815 | CT12: Kβ | CX12: Cl | CY12: =VLOOKUP(CX12,$C$284:$D$377,2,FALSE) -> 17 | CZ12: 2.815 | DA12: Kβ | DE12: Cl | DF12: =VLOOKUP(DE12,$C$284:$D$377,2,FALSE) -> 17 | DG12: 2.815 | DH12: Kβ | DL12: Cl | DM12: =VLOOKUP(DL12,$C$284:$D$377,2,FALSE) -> 17 | DN12: 2.815 | DO12: Kβ | DS12: Cl | DT12: =VLOOKUP(DS12,$C$284:$D$377,2,FALSE) -> 17 | DU12: 2.815 | DV12: Kβ | DZ12: Cl | EA12: =VLOOKUP(DZ12,$C$284:$D$377,2,FALSE) -> 17 | EB12: 2.815 | EC12: Kβ | EG12: Cl | EH12: =VLOOKUP(EG12,$C$284:$D$377,2,FALSE) -> 17 | EI12: 2.815 | EJ12: Kβ | EN12: Cl | EO12: =VLOOKUP(EN12,$C$284:$D$377,2,FALSE) -> 17 | EP12: 2.815 | EQ12: Kβ | EU12: Cl | EV12: =VLOOKUP(EU12,$C$284:$D$377,2,FALSE) -> 17 | EW12: 2.815 | EX12: Kβ | FB12: Cl | FC12: =VLOOKUP(FB12,$C$284:$D$377,2,FALSE) -> 17 | FD12: 2.815 | FE12: Kβ | FI12: Cl | FJ12: =VLOOKUP(FI12,$C$284:$D$377,2,FALSE) -> 17 | FK12: 2.815 | FL12: Kβ | FP12: Cl | FQ12: =VLOOKUP(FP12,$C$284:$D$377,2,FALSE) -> 17 | FR12: 2.815 | FS12: Kβ | FW12: Cl | FX12: =VLOOKUP(FW12,$C$284:$D$377,2,FALSE) -> 17 | FY12: 2.815 | FZ12: Kβ
B13: =IF($A$3=$A$26,E13,E13*1000) -> 2957 | C13: Ar | D13: =VLOOKUP(C13,$C$284:$D$377,2,FALSE) -> 18 | E13: 2.957 | F13: Kα | J13: =M13*1000 -> 2957 | K13: Ar | L13: =VLOOKUP(K13,$C$284:$D$377,2,FALSE) -> 18 | M13: 2.957 | N13: Kα | O13: 4130 | P13: 229 | R13: Ar | S13: =VLOOKUP(R13,$C$284:$D$377,2,FALSE) -> 18 | T13: 2.957 | U13: Kα | V13: 5943 | W13: 190 | Y13: Ar | Z13: =VLOOKUP(Y13,$C$284:$D$377,2,FALSE) -> 18 | AA13: 2.957 | AB13: Kα | AC13: 6238 | AD13: 192 | AF13: Ar | AG13: =VLOOKUP(AF13,$C$284:$D$377,2,FALSE) -> 18 | AH13: 2.957 | AI13: Kα | AJ13: 6081 | AK13: 191 | AM13: Ar | AN13: =VLOOKUP(AM13,$C$284:$D$377,2,FALSE) -> 18 | AO13: 2.957 | AP13: Kα | AQ13: 5556 | AR13: 193 | AT13: Ar | AU13: =VLOOKUP(AT13,$C$284:$D$377,2,FALSE) -> 18 | AV13: 2.957 | AW13: Kα | AX13: 7259 | AY13: 158 | BA13: Ar | BB13: =VLOOKUP(BA13,$C$284:$D$377,2,FALSE) -> 18 | BC13: 2.957 | BD13: Kα | BE13: 5818 | BF13: 195 | BH13: Ar | BI13: =VLOOKUP(BH13,$C$284:$D$377,2,FALSE) -> 18 | BJ13: 2.957 | BK13: Kα | BL13: 6279 | BM13: 192 | BO13: Ar | BP13: =VLOOKUP(BO13,$C$284:$D$377,2,FALSE) -> 18 | BQ13: 2.957 | BR13: Kα | BS13: 5552 | BT13: 194 | BV13: Ar | BW13: =VLOOKUP(BV13,$C$284:$D$377,2,FALSE) -> 18 | BX13: 2.957 | BY13: Kα | BZ13: 5120 | CA13: 192 | CC13: Ar | CD13: =VLOOKUP(CC13,$C$284:$D$377,2,FALSE) -> 18 | CE13: 2.957 | CF13: Kα | CG13: 5484 | CH13: 190 | CJ13: Ar | CK13: =VLOOKUP(CJ13,$C$284:$D$377,2,FALSE) -> 18 | CL13: 2.957 | CM13: Kα | CQ13: Ar | CR13: =VLOOKUP(CQ13,$C$284:$D$377,2,FALSE) -> 18 | CS13: 2.957 | CT13: Kα | CX13: Ar | CY13: =VLOOKUP(CX13,$C$284:$D$377,2,FALSE) -> 18 | CZ13: 2.957 | DA13: Kα | DE13: Ar | DF13: =VLOOKUP(DE13,$C$284:$D$377,2,FALSE) -> 18 | DG13: 2.957 | DH13: Kα | DL13: Ar | DM13: =VLOOKUP(DL13,$C$284:$D$377,2,FALSE) -> 18 | DN13: 2.957 | DO13: Kα | DS13: Ar | DT13: =VLOOKUP(DS13,$C$284:$D$377,2,FALSE) -> 18 | DU13: 2.957 | DV13: Kα | DZ13: Ar | EA13: =VLOOKUP(DZ13,$C$284:$D$377,2,FALSE) -> 18 | EB13: 2.957 | EC13: Kα | EG13: Ar | EH13: =VLOOKUP(EG13,$C$284:$D$377,2,FALSE) -> 18 | EI13: 2.957 | EJ13: Kα | EN13: Ar | EO13: =VLOOKUP(EN13,$C$284:$D$377,2,FALSE) -> 18 | EP13: 2.957 | EQ13: Kα | EU13: Ar | EV13: =VLOOKUP(EU13,$C$284:$D$377,2,FALSE) -> 18 | EW13: 2.957 | EX13: Kα | FB13: Ar | FC13: =VLOOKUP(FB13,$C$284:$D$377,2,FALSE) -> 18 | FD13: 2.957 | FE13: Kα | FI13: Ar | FJ13: =VLOOKUP(FI13,$C$284:$D$377,2,FALSE) -> 18 | FK13: 2.957 | FL13: Kα | FP13: Ar | FQ13: =VLOOKUP(FP13,$C$284:$D$377,2,FALSE) -> 18 | FR13: 2.957 | FS13: Kα | FW13: Ar | FX13: =VLOOKUP(FW13,$C$284:$D$377,2,FALSE) -> 18 | FY13: 2.957 | FZ13: Kα
B14: =IF($A$3=$A$26,E14,E14*1000) -> 3192 | C14: Ar | D14: =VLOOKUP(C14,$C$284:$D$377,2,FALSE) -> 18 | E14: 3.192 | F14: Kβ | J14: =M14*1000 -> 3192 | K14: Ar | L14: =VLOOKUP(K14,$C$284:$D$377,2,FALSE) -> 18 | M14: 3.192 | N14: Kβ | R14: Ar | S14: =VLOOKUP(R14,$C$284:$D$377,2,FALSE) -> 18 | T14: 3.192 | U14: Kβ | Y14: Ar | Z14: =VLOOKUP(Y14,$C$284:$D$377,2,FALSE) -> 18 | AA14: 3.192 | AB14: Kβ | AF14: Ar | AG14: =VLOOKUP(AF14,$C$284:$D$377,2,FALSE) -> 18 | AH14: 3.192 | AI14: Kβ | AM14: Ar | AN14: =VLOOKUP(AM14,$C$284:$D$377,2,FALSE) -> 18 | AO14: 3.192 | AP14: Kβ | AT14: Ar | AU14: =VLOOKUP(AT14,$C$284:$D$377,2,FALSE) -> 18 | AV14: 3.192 | AW14: Kβ | BA14: Ar | BB14: =VLOOKUP(BA14,$C$284:$D$377,2,FALSE) -> 18 | BC14: 3.192 | BD14: Kβ | BH14: Ar | BI14: =VLOOKUP(BH14,$C$284:$D$377,2,FALSE) -> 18 | BJ14: 3.192 | BK14: Kβ | BO14: Ar | BP14: =VLOOKUP(BO14,$C$284:$D$377,2,FALSE) -> 18 | BQ14: 3.192 | BR14: Kβ | BV14: Ar | BW14: =VLOOKUP(BV14,$C$284:$D$377,2,FALSE) -> 18 | BX14: 3.192 | BY14: Kβ | CC14: Ar | CD14: =VLOOKUP(CC14,$C$284:$D$377,2,FALSE) -> 18 | CE14: 3.192 | CF14: Kβ | CJ14: Ar | CK14: =VLOOKUP(CJ14,$C$284:$D$377,2,FALSE) -> 18 | CL14: 3.192 | CM14: Kβ | CQ14: Ar | CR14: =VLOOKUP(CQ14,$C$284:$D$377,2,FALSE) -> 18 | CS14: 3.192 | CT14: Kβ | CX14: Ar | CY14: =VLOOKUP(CX14,$C$284:$D$377,2,FALSE) -> 18 | CZ14: 3.192 | DA14: Kβ | DE14: Ar | DF14: =VLOOKUP(DE14,$C$284:$D$377,2,FALSE) -> 18 | DG14: 3.192 | DH14: Kβ | DL14: Ar | DM14: =VLOOKUP(DL14,$C$284:$D$377,2,FALSE) -> 18 | DN14: 3.192 | DO14: Kβ | DS14: Ar | DT14: =VLOOKUP(DS14,$C$284:$D$377,2,FALSE) -> 18 | DU14: 3.192 | DV14: Kβ | DZ14: Ar | EA14: =VLOOKUP(DZ14,$C$284:$D$377,2,FALSE) -> 18 | EB14: 3.192 | EC14: Kβ | EG14: Ar | EH14: =VLOOKUP(EG14,$C$284:$D$377,2,FALSE) -> 18 | EI14: 3.192 | EJ14: Kβ | EN14: Ar | EO14: =VLOOKUP(EN14,$C$284:$D$377,2,FALSE) -> 18 | EP14: 3.192 | EQ14: Kβ | EU14: Ar | EV14: =VLOOKUP(EU14,$C$284:$D$377,2,FALSE) -> 18 | EW14: 3.192 | EX14: Kβ | FB14: Ar | FC14: =VLOOKUP(FB14,$C$284:$D$377,2,FALSE) -> 18 | FD14: 3.192 | FE14: Kβ | FI14: Ar | FJ14: =VLOOKUP(FI14,$C$284:$D$377,2,FALSE) -> 18 | FK14: 3.192 | FL14: Kβ | FP14: Ar | FQ14: =VLOOKUP(FP14,$C$284:$D$377,2,FALSE) -> 18 | FR14: 3.192 | FS14: Kβ | FW14: Ar | FX14: =VLOOKUP(FW14,$C$284:$D$377,2,FALSE) -> 18 | FY14: 3.192 | FZ14: Kβ
B15: =IF($A$3=$A$26,E15,E15*1000) -> 3313 | C15: K | D15: =VLOOKUP(C15,$C$284:$D$377,2,FALSE) -> 19 | E15: 3.313 | F15: Kα | J15: =M15*1000 -> 3313 | K15: K | L15: =VLOOKUP(K15,$C$284:$D$377,2,FALSE) -> 19 | M15: 3.313 | N15: Kα | O15: 169151 | P15: 441 | R15: K | S15: =VLOOKUP(R15,$C$284:$D$377,2,FALSE) -> 19 | T15: 3.313 | U15: Kα | V15: 43735 | W15: 246 | Y15: K | Z15: =VLOOKUP(Y15,$C$284:$D$377,2,FALSE) -> 19 | AA15: 3.313 | AB15: Kα | AC15: 37860 | AD15: 236 | AF15: K | AG15: =VLOOKUP(AF15,$C$284:$D$377,2,FALSE) -> 19 | AH15: 3.313 | AI15: Kα | AJ15: 52986 | AK15: 263 | AM15: K | AN15: =VLOOKUP(AM15,$C$284:$D$377,2,FALSE) -> 19 | AO15: 3.313 | AP15: Kα | AQ15: 63702 | AR15: 282 | AT15: K | AU15: =VLOOKUP(AT15,$C$284:$D$377,2,FALSE) -> 19 | AV15: 3.313 | AW15: Kα | AX15: 61476 | AY15: 263 | BA15: K | BB15: =VLOOKUP(BA15,$C$284:$D$377,2,FALSE) -> 19 | BC15: 3.313 | BD15: Kα | BE15: 53117 | BF15: 266 | BH15: K | BI15: =VLOOKUP(BH15,$C$284:$D$377,2,FALSE) -> 19 | BJ15: 3.313 | BK15: Kα | BL15: 48230 | BM15: 255 | BO15: K | BP15: =VLOOKUP(BO15,$C$284:$D$377,2,FALSE) -> 19 | BQ15: 3.313 | BR15: Kα | BS15: 76728 | BT15: 302 | BV15: K | BW15: =VLOOKUP(BV15,$C$284:$D$377,2,FALSE) -> 19 | BX15: 3.313 | BY15: Kα | BZ15: 57180 | CA15: 273 | CC15: K | CD15: =VLOOKUP(CC15,$C$284:$D$377,2,FALSE) -> 19 | CE15: 3.313 | CF15: Kα | CG15: 44743 | CH15: 248 | CJ15: K | CK15: =VLOOKUP(CJ15,$C$284:$D$377,2,FALSE) -> 19 | CL15: 3.313 | CM15: Kα | CQ15: K | CR15: =VLOOKUP(CQ15,$C$284:$D$377,2,FALSE) -> 19 | CS15: 3.313 | CT15: Kα | CX15: K | CY15: =VLOOKUP(CX15,$C$284:$D$377,2,FALSE) -> 19 | CZ15: 3.313 | DA15: Kα | DE15: K | DF15: =VLOOKUP(DE15,$C$284:$D$377,2,FALSE) -> 19 | DG15: 3.313 | DH15: Kα | DL15: K | DM15: =VLOOKUP(DL15,$C$284:$D$377,2,FALSE) -> 19 | DN15: 3.313 | DO15: Kα | DS15: K | DT15: =VLOOKUP(DS15,$C$284:$D$377,2,FALSE) -> 19 | DU15: 3.313 | DV15: Kα | DZ15: K | EA15: =VLOOKUP(DZ15,$C$284:$D$377,2,FALSE) -> 19 | EB15: 3.313 | EC15: Kα | EG15: K | EH15: =VLOOKUP(EG15,$C$284:$D$377,2,FALSE) -> 19 | EI15: 3.313 | EJ15: Kα | EN15: K | EO15: =VLOOKUP(EN15,$C$284:$D$377,2,FALSE) -> 19 | EP15: 3.313 | EQ15: Kα | EU15: K | EV15: =VLOOKUP(EU15,$C$284:$D$377,2,FALSE) -> 19 | EW15: 3.313 | EX15: Kα | FB15: K | FC15: =VLOOKUP(FB15,$C$284:$D$377,2,FALSE) -> 19 | FD15: 3.313 | FE15: Kα | FI15: K | FJ15: =VLOOKUP(FI15,$C$284:$D$377,2,FALSE) -> 19 | FK15: 3.313 | FL15: Kα | FP15: K | FQ15: =VLOOKUP(FP15,$C$284:$D$377,2,FALSE) -> 19 | FR15: 3.313 | FS15: Kα | FW15: K | FX15: =VLOOKUP(FW15,$C$284:$D$377,2,FALSE) -> 19 | FY15: 3.313 | FZ15: Kα
B16: =IF($A$3=$A$26,E16,E16*1000) -> 3589 | C16: K | D16: =VLOOKUP(C16,$C$284:$D$377,2,FALSE) -> 19 | E16: 3.589 | F16: Kβ | J16: =M16*1000 -> 3589 | K16: K | L16: =VLOOKUP(K16,$C$284:$D$377,2,FALSE) -> 19 | M16: 3.589 | N16: Kβ | R16: K | S16: =VLOOKUP(R16,$C$284:$D$377,2,FALSE) -> 19 | T16: 3.589 | U16: Kβ | Y16: K | Z16: =VLOOKUP(Y16,$C$284:$D$377,2,FALSE) -> 19 | AA16: 3.589 | AB16: Kβ | AF16: K | AG16: =VLOOKUP(AF16,$C$284:$D$377,2,FALSE) -> 19 | AH16: 3.589 | AI16: Kβ | AM16: K | AN16: =VLOOKUP(AM16,$C$284:$D$377,2,FALSE) -> 19 | AO16: 3.589 | AP16: Kβ | AT16: K | AU16: =VLOOKUP(AT16,$C$284:$D$377,2,FALSE) -> 19 | AV16: 3.589 | AW16: Kβ | BA16: K | BB16: =VLOOKUP(BA16,$C$284:$D$377,2,FALSE) -> 19 | BC16: 3.589 | BD16: Kβ | BH16: K | BI16: =VLOOKUP(BH16,$C$284:$D$377,2,FALSE) -> 19 | BJ16: 3.589 | BK16: Kβ | BO16: K | BP16: =VLOOKUP(BO16,$C$284:$D$377,2,FALSE) -> 19 | BQ16: 3.589 | BR16: Kβ | BV16: K | BW16: =VLOOKUP(BV16,$C$284:$D$377,2,FALSE) -> 19 | BX16: 3.589 | BY16: Kβ | CC16: K | CD16: =VLOOKUP(CC16,$C$284:$D$377,2,FALSE) -> 19 | CE16: 3.589 | CF16: Kβ | CJ16: K | CK16: =VLOOKUP(CJ16,$C$284:$D$377,2,FALSE) -> 19 | CL16: 3.589 | CM16: Kβ | CQ16: K | CR16: =VLOOKUP(CQ16,$C$284:$D$377,2,FALSE) -> 19 | CS16: 3.589 | CT16: Kβ | CX16: K | CY16: =VLOOKUP(CX16,$C$284:$D$377,2,FALSE) -> 19 | CZ16: 3.589 | DA16: Kβ | DE16: K | DF16: =VLOOKUP(DE16,$C$284:$D$377,2,FALSE) -> 19 | DG16: 3.589 | DH16: Kβ | DL16: K | DM16: =VLOOKUP(DL16,$C$284:$D$377,2,FALSE) -> 19 | DN16: 3.589 | DO16: Kβ | DS16: K | DT16: =VLOOKUP(DS16,$C$284:$D$377,2,FALSE) -> 19 | DU16: 3.589 | DV16: Kβ | DZ16: K | EA16: =VLOOKUP(DZ16,$C$284:$D$377,2,FALSE) -> 19 | EB16: 3.589 | EC16: Kβ | EG16: K | EH16: =VLOOKUP(EG16,$C$284:$D$377,2,FALSE) -> 19 | EI16: 3.589 | EJ16: Kβ | EN16: K | EO16: =VLOOKUP(EN16,$C$284:$D$377,2,FALSE) -> 19 | EP16: 3.589 | EQ16: Kβ | EU16: K | EV16: =VLOOKUP(EU16,$C$284:$D$377,2,FALSE) -> 19 | EW16: 3.589 | EX16: Kβ | FB16: K | FC16: =VLOOKUP(FB16,$C$284:$D$377,2,FALSE) -> 19 | FD16: 3.589 | FE16: Kβ | FI16: K | FJ16: =VLOOKUP(FI16,$C$284:$D$377,2,FALSE) -> 19 | FK16: 3.589 | FL16: Kβ | FP16: K | FQ16: =VLOOKUP(FP16,$C$284:$D$377,2,FALSE) -> 19 | FR16: 3.589 | FS16: Kβ | FW16: K | FX16: =VLOOKUP(FW16,$C$284:$D$377,2,FALSE) -> 19 | FY16: 3.589 | FZ16: Kβ
B17: =IF($A$3=$A$26,E17,E17*1000) -> 3691 | C17: Ca | D17: =VLOOKUP(C17,$C$284:$D$377,2,FALSE) -> 20 | E17: 3.691 | F17: Kα | J17: =M17*1000 -> 3691 | K17: Ca | L17: =VLOOKUP(K17,$C$284:$D$377,2,FALSE) -> 20 | M17: 3.691 | N17: Kα | O17: 427317 | P17: 637 | R17: Ca | S17: =VLOOKUP(R17,$C$284:$D$377,2,FALSE) -> 20 | T17: 3.691 | U17: Kα | V17: 16457 | W17: 173 | Y17: Ca | Z17: =VLOOKUP(Y17,$C$284:$D$377,2,FALSE) -> 20 | AA17: 3.691 | AB17: Kα | AC17: 18873 | AD17: 180 | AF17: Ca | AG17: =VLOOKUP(AF17,$C$284:$D$377,2,FALSE) -> 20 | AH17: 3.691 | AI17: Kα | AJ17: 17823 | AK17: 178 | AM17: Ca | AN17: =VLOOKUP(AM17,$C$284:$D$377,2,FALSE) -> 20 | AO17: 3.691 | AP17: Kα | AQ17: 20379 | AR17: 188 | AT17: Ca | AU17: =VLOOKUP(AT17,$C$284:$D$377,2,FALSE) -> 20 | AV17: 3.691 | AW17: Kα | AX17: 20178 | AY17: 179 | BA17: Ca | BB17: =VLOOKUP(BA17,$C$284:$D$377,2,FALSE) -> 20 | BC17: 3.691 | BD17: Kα | BE17: 20558 | BF17: 188 | BH17: Ca | BI17: =VLOOKUP(BH17,$C$284:$D$377,2,FALSE) -> 20 | BJ17: 3.691 | BK17: Kα | BL17: 16352 | BM17: 173 | BO17: Ca | BP17: =VLOOKUP(BO17,$C$284:$D$377,2,FALSE) -> 20 | BQ17: 3.691 | BR17: Kα | BS17: 17562 | BT17: 179 | BV17: Ca | BW17: =VLOOKUP(BV17,$C$284:$D$377,2,FALSE) -> 20 | BX17: 3.691 | BY17: Kα | BZ17: 24113 | CA17: 198 | CC17: Ca | CD17: =VLOOKUP(CC17,$C$284:$D$377,2,FALSE) -> 20 | CE17: 3.691 | CF17: Kα | CG17: 19867 | CH17: 183 | CJ17: Ca | CK17: =VLOOKUP(CJ17,$C$284:$D$377,2,FALSE) -> 20 | CL17: 3.691 | CM17: Kα | CQ17: Ca | CR17: =VLOOKUP(CQ17,$C$284:$D$377,2,FALSE) -> 20 | CS17: 3.691 | CT17: Kα | CX17: Ca | CY17: =VLOOKUP(CX17,$C$284:$D$377,2,FALSE) -> 20 | CZ17: 3.691 | DA17: Kα | DE17: Ca | DF17: =VLOOKUP(DE17,$C$284:$D$377,2,FALSE) -> 20 | DG17: 3.691 | DH17: Kα | DL17: Ca | DM17: =VLOOKUP(DL17,$C$284:$D$377,2,FALSE) -> 20 | DN17: 3.691 | DO17: Kα | DS17: Ca | DT17: =VLOOKUP(DS17,$C$284:$D$377,2,FALSE) -> 20 | DU17: 3.691 | DV17: Kα | DZ17: Ca | EA17: =VLOOKUP(DZ17,$C$284:$D$377,2,FALSE) -> 20 | EB17: 3.691 | EC17: Kα | EG17: Ca | EH17: =VLOOKUP(EG17,$C$284:$D$377,2,FALSE) -> 20 | EI17: 3.691 | EJ17: Kα | EN17: Ca | EO17: =VLOOKUP(EN17,$C$284:$D$377,2,FALSE) -> 20 | EP17: 3.691 | EQ17: Kα | EU17: Ca | EV17: =VLOOKUP(EU17,$C$284:$D$377,2,FALSE) -> 20 | EW17: 3.691 | EX17: Kα | FB17: Ca | FC17: =VLOOKUP(FB17,$C$284:$D$377,2,FALSE) -> 20 | FD17: 3.691 | FE17: Kα | FI17: Ca | FJ17: =VLOOKUP(FI17,$C$284:$D$377,2,FALSE) -> 20 | FK17: 3.691 | FL17: Kα | FP17: Ca | FQ17: =VLOOKUP(FP17,$C$284:$D$377,2,FALSE) -> 20 | FR17: 3.691 | FS17: Kα | FW17: Ca | FX17: =VLOOKUP(FW17,$C$284:$D$377,2,FALSE) -> 20 | FY17: 3.691 | FZ17: Kα
B18: =IF($A$3=$A$26,E18,E18*1000) -> 4012 | C18: Ca | D18: =VLOOKUP(C18,$C$284:$D$377,2,FALSE) -> 20 | E18: 4.012 | F18: Kβ | J18: =M18*1000 -> 4012 | K18: Ca | L18: =VLOOKUP(K18,$C$284:$D$377,2,FALSE) -> 20 | M18: 4.012 | N18: Kβ | R18: Ca | S18: =VLOOKUP(R18,$C$284:$D$377,2,FALSE) -> 20 | T18: 4.012 | U18: Kβ | Y18: Ca | Z18: =VLOOKUP(Y18,$C$284:$D$377,2,FALSE) -> 20 | AA18: 4.012 | AB18: Kβ | AF18: Ca | AG18: =VLOOKUP(AF18,$C$284:$D$377,2,FALSE) -> 20 | AH18: 4.012 | AI18: Kβ | AM18: Ca | AN18: =VLOOKUP(AM18,$C$284:$D$377,2,FALSE) -> 20 | AO18: 4.012 | AP18: Kβ | AT18: Ca | AU18: =VLOOKUP(AT18,$C$284:$D$377,2,FALSE) -> 20 | AV18: 4.012 | AW18: Kβ | BA18: Ca | BB18: =VLOOKUP(BA18,$C$284:$D$377,2,FALSE) -> 20 | BC18: 4.012 | BD18: Kβ | BH18: Ca | BI18: =VLOOKUP(BH18,$C$284:$D$377,2,FALSE) -> 20 | BJ18: 4.012 | BK18: Kβ | BO18: Ca | BP18: =VLOOKUP(BO18,$C$284:$D$377,2,FALSE) -> 20 | BQ18: 4.012 | BR18: Kβ | BV18: Ca | BW18: =VLOOKUP(BV18,$C$284:$D$377,2,FALSE) -> 20 | BX18: 4.012 | BY18: Kβ | CC18: Ca | CD18: =VLOOKUP(CC18,$C$284:$D$377,2,FALSE) -> 20 | CE18: 4.012 | CF18: Kβ | CJ18: Ca | CK18: =VLOOKUP(CJ18,$C$284:$D$377,2,FALSE) -> 20 | CL18: 4.012 | CM18: Kβ | CQ18: Ca | CR18: =VLOOKUP(CQ18,$C$284:$D$377,2,FALSE) -> 20 | CS18: 4.012 | CT18: Kβ | CX18: Ca | CY18: =VLOOKUP(CX18,$C$284:$D$377,2,FALSE) -> 20 | CZ18: 4.012 | DA18: Kβ | DE18: Ca | DF18: =VLOOKUP(DE18,$C$284:$D$377,2,FALSE) -> 20 | DG18: 4.012 | DH18: Kβ | DL18: Ca | DM18: =VLOOKUP(DL18,$C$284:$D$377,2,FALSE) -> 20 | DN18: 4.012 | DO18: Kβ | DS18: Ca | DT18: =VLOOKUP(DS18,$C$284:$D$377,2,FALSE) -> 20 | DU18: 4.012 | DV18: Kβ | DZ18: Ca | EA18: =VLOOKUP(DZ18,$C$284:$D$377,2,FALSE) -> 20 | EB18: 4.012 | EC18: Kβ | EG18: Ca | EH18: =VLOOKUP(EG18,$C$284:$D$377,2,FALSE) -> 20 | EI18: 4.012 | EJ18: Kβ | EN18: Ca | EO18: =VLOOKUP(EN18,$C$284:$D$377,2,FALSE) -> 20 | EP18: 4.012 | EQ18: Kβ | EU18: Ca | EV18: =VLOOKUP(EU18,$C$284:$D$377,2,FALSE) -> 20 | EW18: 4.012 | EX18: Kβ | FB18: Ca | FC18: =VLOOKUP(FB18,$C$284:$D$377,2,FALSE) -> 20 | FD18: 4.012 | FE18: Kβ | FI18: Ca | FJ18: =VLOOKUP(FI18,$C$284:$D$377,2,FALSE) -> 20 | FK18: 4.012 | FL18: Kβ | FP18: Ca | FQ18: =VLOOKUP(FP18,$C$284:$D$377,2,FALSE) -> 20 | FR18: 4.012 | FS18: Kβ | FW18: Ca | FX18: =VLOOKUP(FW18,$C$284:$D$377,2,FALSE) -> 20 | FY18: 4.012 | FZ18: Kβ
B19: =IF($A$3=$A$26,E19,E19*1000) -> 4089 | C19: Sc | D19: =VLOOKUP(C19,$C$284:$D$377,2,FALSE) -> 21 | E19: 4.089 | F19: Kα | J19: =M19*1000 -> 4090 | K19: Sc | L19: =VLOOKUP(K19,$C$284:$D$377,2,FALSE) -> 21 | M19: 4.09 | N19: Kα | R19: Sc | S19: =VLOOKUP(R19,$C$284:$D$377,2,FALSE) -> 21 | T19: 4.09 | U19: Kα | Y19: Sc | Z19: =VLOOKUP(Y19,$C$284:$D$377,2,FALSE) -> 21 | AA19: 4.09 | AB19: Kα | AF19: Sc | AG19: =VLOOKUP(AF19,$C$284:$D$377,2,FALSE) -> 21 | AH19: 4.09 | AI19: Kα | AM19: Sc | AN19: =VLOOKUP(AM19,$C$284:$D$377,2,FALSE) -> 21 | AO19: 4.09 | AP19: Kα | AT19: Sc | AU19: =VLOOKUP(AT19,$C$284:$D$377,2,FALSE) -> 21 | AV19: 4.09 | AW19: Kα | BA19: Sc | BB19: =VLOOKUP(BA19,$C$284:$D$377,2,FALSE) -> 21 | BC19: 4.09 | BD19: Kα | BH19: Sc | BI19: =VLOOKUP(BH19,$C$284:$D$377,2,FALSE) -> 21 | BJ19: 4.09 | BK19: Kα | BO19: Sc | BP19: =VLOOKUP(BO19,$C$284:$D$377,2,FALSE) -> 21 | BQ19: 4.09 | BR19: Kα | BV19: Sc | BW19: =VLOOKUP(BV19,$C$284:$D$377,2,FALSE) -> 21 | BX19: 4.09 | BY19: Kα | CC19: Sc | CD19: =VLOOKUP(CC19,$C$284:$D$377,2,FALSE) -> 21 | CE19: 4.09 | CF19: Kα | CJ19: Sc | CK19: =VLOOKUP(CJ19,$C$284:$D$377,2,FALSE) -> 21 | CL19: 4.09 | CM19: Kα | CQ19: Sc | CR19: =VLOOKUP(CQ19,$C$284:$D$377,2,FALSE) -> 21 | CS19: 4.09 | CT19: Kα | CX19: Sc | CY19: =VLOOKUP(CX19,$C$284:$D$377,2,FALSE) -> 21 | CZ19: 4.09 | DA19: Kα | DE19: Sc | DF19: =VLOOKUP(DE19,$C$284:$D$377,2,FALSE) -> 21 | DG19: 4.09 | DH19: Kα | DL19: Sc | DM19: =VLOOKUP(DL19,$C$284:$D$377,2,FALSE) -> 21 | DN19: 4.09 | DO19: Kα | DS19: Sc | DT19: =VLOOKUP(DS19,$C$284:$D$377,2,FALSE) -> 21 | DU19: 4.09 | DV19: Kα | DZ19: Sc | EA19: =VLOOKUP(DZ19,$C$284:$D$377,2,FALSE) -> 21 | EB19: 4.09 | EC19: Kα | EG19: Sc | EH19: =VLOOKUP(EG19,$C$284:$D$377,2,FALSE) -> 21 | EI19: 4.09 | EJ19: Kα | EN19: Sc | EO19: =VLOOKUP(EN19,$C$284:$D$377,2,FALSE) -> 21 | EP19: 4.09 | EQ19: Kα | EU19: Sc | EV19: =VLOOKUP(EU19,$C$284:$D$377,2,FALSE) -> 21 | EW19: 4.09 | EX19: Kα | FB19: Sc | FC19: =VLOOKUP(FB19,$C$284:$D$377,2,FALSE) -> 21 | FD19: 4.09 | FE19: Kα | FI19: Sc | FJ19: =VLOOKUP(FI19,$C$284:$D$377,2,FALSE) -> 21 | FK19: 4.09 | FL19: Kα | FP19: Sc | FQ19: =VLOOKUP(FP19,$C$284:$D$377,2,FALSE) -> 21 | FR19: 4.09 | FS19: Kα | FW19: Sc | FX19: =VLOOKUP(FW19,$C$284:$D$377,2,FALSE) -> 21 | FY19: 4.09 | FZ19: Kα
B20: =IF($A$3=$A$26,E20,E20*1000) -> 4460 | C20: Sc | D20: =VLOOKUP(C20,$C$284:$D$377,2,FALSE) -> 21 | E20: 4.46 | F20: Kβ | J20: =M20*1000 -> 4460 | K20: Sc | L20: =VLOOKUP(K20,$C$284:$D$377,2,FALSE) -> 21 | M20: 4.46 | N20: Kβ | R20: Sc | S20: =VLOOKUP(R20,$C$284:$D$377,2,FALSE) -> 21 | T20: 4.46 | U20: Kβ | Y20: Sc | Z20: =VLOOKUP(Y20,$C$284:$D$377,2,FALSE) -> 21 | AA20: 4.46 | AB20: Kβ | AF20: Sc | AG20: =VLOOKUP(AF20,$C$284:$D$377,2,FALSE) -> 21 | AH20: 4.46 | AI20: Kβ | AM20: Sc | AN20: =VLOOKUP(AM20,$C$284:$D$377,2,FALSE) -> 21 | AO20: 4.46 | AP20: Kβ | AT20: Sc | AU20: =VLOOKUP(AT20,$C$284:$D$377,2,FALSE) -> 21 | AV20: 4.46 | AW20: Kβ | BA20: Sc | BB20: =VLOOKUP(BA20,$C$284:$D$377,2,FALSE) -> 21 | BC20: 4.46 | BD20: Kβ | BH20: Sc | BI20: =VLOOKUP(BH20,$C$284:$D$377,2,FALSE) -> 21 | BJ20: 4.46 | BK20: Kβ | BO20: Sc | BP20: =VLOOKUP(BO20,$C$284:$D$377,2,FALSE) -> 21 | BQ20: 4.46 | BR20: Kβ | BV20: Sc | BW20: =VLOOKUP(BV20,$C$284:$D$377,2,FALSE) -> 21 | BX20: 4.46 | BY20: Kβ | CC20: Sc | CD20: =VLOOKUP(CC20,$C$284:$D$377,2,FALSE) -> 21 | CE20: 4.46 | CF20: Kβ | CJ20: Sc | CK20: =VLOOKUP(CJ20,$C$284:$D$377,2,FALSE) -> 21 | CL20: 4.46 | CM20: Kβ | CQ20: Sc | CR20: =VLOOKUP(CQ20,$C$284:$D$377,2,FALSE) -> 21 | CS20: 4.46 | CT20: Kβ | CX20: Sc | CY20: =VLOOKUP(CX20,$C$284:$D$377,2,FALSE) -> 21 | CZ20: 4.46 | DA20: Kβ | DE20: Sc | DF20: =VLOOKUP(DE20,$C$284:$D$377,2,FALSE) -> 21 | DG20: 4.46 | DH20: Kβ | DL20: Sc | DM20: =VLOOKUP(DL20,$C$284:$D$377,2,FALSE) -> 21 | DN20: 4.46 | DO20: Kβ | DS20: Sc | DT20: =VLOOKUP(DS20,$C$284:$D$377,2,FALSE) -> 21 | DU20: 4.46 | DV20: Kβ | DZ20: Sc | EA20: =VLOOKUP(DZ20,$C$284:$D$377,2,FALSE) -> 21 | EB20: 4.46 | EC20: Kβ | EG20: Sc | EH20: =VLOOKUP(EG20,$C$284:$D$377,2,FALSE) -> 21 | EI20: 4.46 | EJ20: Kβ | EN20: Sc | EO20: =VLOOKUP(EN20,$C$284:$D$377,2,FALSE) -> 21 | EP20: 4.46 | EQ20: Kβ | EU20: Sc | EV20: =VLOOKUP(EU20,$C$284:$D$377,2,FALSE) -> 21 | EW20: 4.46 | EX20: Kβ | FB20: Sc | FC20: =VLOOKUP(FB20,$C$284:$D$377,2,FALSE) -> 21 | FD20: 4.46 | FE20: Kβ | FI20: Sc | FJ20: =VLOOKUP(FI20,$C$284:$D$377,2,FALSE) -> 21 | FK20: 4.46 | FL20: Kβ | FP20: Sc | FQ20: =VLOOKUP(FP20,$C$284:$D$377,2,FALSE) -> 21 | FR20: 4.46 | FS20: Kβ | FW20: Sc | FX20: =VLOOKUP(FW20,$C$284:$D$377,2,FALSE) -> 21 | FY20: 4.46 | FZ20: Kβ
